Workbook

Sheet Hoja 1
J1: =SUM(J3:J284) -> 1427935.2 | K1: =SUM(K3:K284) -> 876 | W1: =Y1/X1 -> 0.89431335 | X1: =SUM(X3:X284) -> 2023315.5 | Y1: =SUM(Y3:Y284) -> 1809478.1
A2: Articulo | B2: Nombre | C2: UXC | D2: Subfamilia | E2: SN | F2: Categoria | G2: CN | H2: CostoCIVA | I2: CostoXCaja | J2: $Pedido | K2: SumaPedido | L2: 10VentasG | M2: 10ExistenciaG | P2: PedidoLPD | Q2: 30VentasG | R2: 30ExistenciasG | S2: PedMorelia | T2: 50VentasG | U2: 50ExistenciaG | V2: PedidoZam | W2: ExCEDIS | X2: ValorVentaG | Y2: ValorExistenciaG | Z2: 10Actual15 | AA2: 10Actual30R | AB2: 10Anterior15 | AC2: 10Anterior30R | AD2: 10ExistenciaWC | AE2: 40Actual15 | AF2: 40Actual30R | AG2: 40Anterior15 | AH2: 40Anterior30R | AI2: 40ExistenciaWC | AJ2: 42Actual15 | AK2: 42Actual30R | AL2: 42Anterior15 | AM2: 42Anterior30R | AN2: 42ExistenciaWC | AO2: 44Actual15 | AP2: 44Actual30R | AQ2: 44Anterior15 | AR2: 44Anterior30R | AS2: 44ExistenciaWC | AT2: 30Actual15 | AU2: 30Actual30R | AV2: 30Anterior15 | AW2: 30Anterior30R | AX2: 30ExistenciaWC | AY2: 32Actual15 | AZ2: 32Actual30R | BA2: 32Anterior15 | BB2: 32Anterior30R | BC2: 32ExistenciaWC | BD2: 50Actual15 | BE2: 50Actual30R | BF2: 50Anterior15 | BG2: 50Anterior30R | BH2: 50ExistenciaWC | BI2: 54Actual15 | BJ2: 54Actual30R | BK2: 54Anterior15 | BL2: 54Anterior30R | BM2: 54ExistenciaWC
A3: 65124 | B3: SKWINKLES SALSAGHETI SANDIA/12 | C3: 20 | D3: 162 | E3: EFFEM MEXICO INC. Y COMPAÑÍAS EN N.C DE CV | F3: 807 | G3: MATRE MEXICO S DE RL DE CV | H3: 80.936 | I3: 1618.72 | J3: =K3*I3 -> 80936 | K3: =SUM(P3+S3+V3) -> 50 | L3: 49.98 | M3: 43.2 | N3: 42 | O3: 8 | P3: 20 | Q3: 63.85 | R3: 61.2 | S3: 20 | T3: 23.7 | U3: 16.75 | V3: 10 | W3: 0 | X3: 222614.47 | Y3: 196107.93 | Z3: 343 | AA3: 0 | AB3: 474 | AC3: 365 | AD3: 864 | AE3: 0 | AF3: 0 | AG3: 0 | AH3: 0 | AI3: 0 | AJ3: 0 | AK3: 0 | AL3: 0 | AM3: 0 | AN3: 0 | AO3: 0 | AP3: 0 | AQ3: 0 | AR3: 0 | AS3: 0 | AT3: 563 | AU3: 0 | AV3: 497 | AW3: 434 | AX3: 1224 | AY3: 0 | AZ3: 0 | BA3: 0 | BB3: 0 | BC3: 0 | BD3: 400 | BE3: 0 | BF3: 54 | BG3: 40 | BH3: 335 | BI3: 0 | BJ3: 0 | BK3: 0 | BL3: 0 | BM3: 0
A4: 65133 | B4: PANZON LUCAS SANDIA CHAMOY /10 | C4: 24 | D4: 162 | E4: EFFEM MEXICO INC. Y COMPAÑÍAS EN N.C DE CV | F4: 807 | G4: MATRE MEXICO S DE RL DE CV | H4: 76.07 | I4: 1825.68 | J4: =K4*I4 -> 63898.8 | K4: =SUM(P4+S4+V4) -> 35 | L4: 26.29 | M4: 21.58 | N4: 15 | O4: 20 | P4: 10 | Q4: 31.98 | R4: 24.46 | S4: 15 | T4: 14.9 | U4: 16.04 | V4: 10 | W4: 0 | X4: 133578.92 | Y4: 113344.3 | Z4: 228 | AA4: 0 | AB4: 253 | AC4: 300 | AD4: 518 | AE4: 0 | AF4: 0 | AG4: 0 | AH4: 0 | AI4: 0 | AJ4: 0 | AK4: 0 | AL4: 0 | AM4: 0 | AN4: 0 | AO4: 0 | AP4: 0 | AQ4: 0 | AR4: 0 | AS4: 0 | AT4: 229 | AU4: 0 | AV4: 386 | AW4: 305 | AX4: 587 | AY4: 0 | AZ4: 0 | BA4: 0 | BB4: 0 | BC4: 0 | BD4: 225 | BE4: 0 | BF4: 73 | BG4: 119 | BH4: 385 | BI4: 0 | BJ4: 0 | BK4: 0 | BL4: 0 | BM4: 0
A5: 6001 | B5: CHOC SNICKERS /6 | C5: 32 | D5: 162 | E5: EFFEM MEXICO INC. Y COMPAÑÍAS EN N.C DE CV | F5: 558 | G5: CHOCOLATES | H5: 84.1675 | I5: 2693.36 | J5: =K5*I5 -> 94267.6 | K5: =SUM(P5+S5+V5) -> 35 | L5: 15.31 | M5: 6.88 | P5: 15 | Q5: 19.09 | R5: 7.81 | S5: 15 | T5: 12.41 | U5: 8.88 | V5: 5 | W5: 0 | X5: 126082.92 | Y5: 63462.3 | Z5: 161 | AA5: 0 | AB5: 232 | AC5: 194 | AD5: 220 | AE5: 0 | AF5: 0 | AG5: 0 | AH5: 0 | AI5: 0 | AJ5: 0 | AK5: 0 | AL5: 0 | AM5: 0 | AN5: 0 | AO5: 0 | AP5: 0 | AQ5: 0 | AR5: 0 | AS5: 0 | AT5: 195 | AU5: 0 | AV5: 232 | AW5: 368 | AX5: 250 | AY5: 0 | AZ5: 0 | BA5: 0 | BB5: 0 | BC5: 0 | BD5: 205 | BE5: 0 | BF5: 135 | BG5: 114 | BH5: 284 | BI5: 0 | BJ5: 0 | BK5: 0 | BL5: 0 | BM5: 0
A6: 88124 | B6: CH ORBIT 4 S MENTA / 40 | C6: 24 | D6: 162 | E6: EFFEM MEXICO INC. Y COMPAÑÍAS EN N.C DE CV | F6: 974 | G6: CHICLES | H6: 76.9276 | I6: 1846.2624 | J6: =K6*I6 -> 64619.184 | K6: =SUM(P6+S6+V6) -> 35 | L6: 39.02 | M6: 11 | P6: 20 | Q6: 23.94 | R6: 25.75 | S6: 10 | T6: 4.54 | U6: 3.79 | V6: 5 | W6: 0 | X6: 124622.71 | Y6: 74850.55 | Z6: 328 | AA6: 0 | AB6: 451 | AC6: 315 | AD6: 264 | AE6: 0 | AF6: 0 | AG6: 0 | AH6: 0 | AI6: 0 | AJ6: 0 | AK6: 0 | AL6: 0 | AM6: 0 | AN6: 0 | AO6: 0 | AP6: 0 | AQ6: 0 | AR6: 0 | AS6: 0 | AT6: 215 | AU6: 0 | AV6: 248 | AW6: 223 | AX6: 618 | AY6: 0 | AZ6: 0 | BA6: 0 | BB6: 0 | BC6: 0 | BD6: 33 | BE6: 0 | BF6: 55 | BG6: 42 | BH6: 91 | BI6: 0 | BJ6: 0 | BK6: 0 | BL6: 0 | BM6: 0
A7: 65109 | B7: GUSANO LUCAS CHAMOY EXH /10 | C7: 30 | D7: 162 | E7: EFFEM MEXICO INC. Y COMPAÑÍAS EN N.C DE CV | F7: 807 | G7: MATRE MEXICO S DE RL DE CV | H7: 65.2744 | I7: 1958.232 | J7: =K7*I7 -> 58746.96 | K7: =SUM(P7+S7+V7) -> 30 | L7: 16.98 | M7: 16.43 | P7: 5 | Q7: 26 | R7: 15.8 | S7: 15 | T7: 18.35 | U7: 6.57 | V7: 10 | W7: 0 | X7: 120104.9 | Y7: 75979.4 | Z7: 241 | AA7: 0 | AB7: 213 | AC7: 111 | AD7: 493 | AE7: 0 | AF7: 0 | AG7: 0 | AH7: 0 | AI7: 0 | AJ7: 0 | AK7: 0 | AL7: 0 | AM7: 0 | AN7: 0 | AO7: 0 | AP7: 0 | AQ7: 0 | AR7: 0 | AS7: 0 | AT7: 185 | AU7: 0 | AV7: 473 | AW7: 244 | AX7: 474 | AY7: 0 | AZ7: 0 | BA7: 0 | BB7: 0 | BC7: 0 | BD7: 200 | BE7: 0 | BF7: 247 | BG7: 207 | BH7: 197 | BI7: 0 | BJ7: 0 | BK7: 0 | BL7: 0 | BM7: 0
A8: 6002 | B8: CHOC MILKY WAY /6 | C8: 32 | D8: 162 | E8: EFFEM MEXICO INC. Y COMPAÑÍAS EN N.C DE CV | F8: 558 | G8: CHOCOLATES | H8: 84.1675 | I8: 2693.36 | J8: =K8*I8 -> 94267.6 | K8: =SUM(P8+S8+V8) -> 35 | L8: 10.8 | M8: 3.25 | N8: 9 | O8: 26 | P8: 15 | Q8: 16.34 | R8: 7.41 | S8: 15 | T8: 10.64 | U8: 6.19 | V8: 5 | W8: 0 | X8: 101758.51 | Y8: 45366.28 | Z8: 96 | AA8: 0 | AB8: 156 | AC8: 187 | AD8: 104 | AE8: 0 | AF8: 0 | AG8: 0 | AH8: 0 | AI8: 0 | AJ8: 0 | AK8: 0 | AL8: 0 | AM8: 0 | AN8: 0 | AO8: 0 | AP8: 0 | AQ8: 0 | AR8: 0 | AS8: 0 | AT8: 121 | AU8: 0 | AV8: 228 | AW8: 348 | AX8: 237 | AY8: 0 | AZ8: 0 | BA8: 0 | BB8: 0 | BC8: 0 | BD8: 144 | BE8: 0 | BF8: 160 | BG8: 73 | BH8: 198 | BI8: 0 | BJ8: 0 | BK8: 0 | BL8: 0 | BM8: 0
A9: 88102 | B9: CH ORBIT 4 S HIERBABUENA / 40 | C9: 24 | D9: 162 | E9: EFFEM MEXICO INC. Y COMPAÑÍAS EN N.C DE CV | F9: 974 | G9: CHICLES | H9: 76.9276 | I9: 1846.2624 | J9: =K9*I9 -> 18462.624 | K9: =SUM(P9+S9+V9) -> 10 | L9: 19.44 | M9: 36.67 | P9: 0 | Q9: 18.73 | R9: 16.08 | S9: 10 | T9: 4.54 | U9: 5.83 | V9: 0 | W9: 0 | X9: 78850.79 | Y9: 108160.21 | Z9: 232 | AA9: 0 | AB9: 190 | AC9: 89 | AD9: 880 | AE9: 0 | AF9: 0 | AG9: 0 | AH9: 0 | AI9: 0 | AJ9: 0 | AK9: 0 | AL9: 0 | AM9: 0 | AN9: 0 | AO9: 0 | AP9: 0 | AQ9: 0 | AR9: 0 | AS9: 0 | AT9: 153 | AU9: 0 | AV9: 206 | AW9: 181 | AX9: 386 | AY9: 0 | AZ9: 0 | BA9: 0 | BB9: 0 | BC9: 0 | BD9: 32 | BE9: 0 | BF9: 61 | BG9: 32 | BH9: 140 | BI9: 0 | BJ9: 0 | BK9: 0 | BL9: 0 | BM9: 0
A10: 88135 | B10: CH ORBIT 4 S POLAR MINT 4 S / 40 | C10: 24 | D10: 162 | E10: EFFEM MEXICO INC. Y COMPAÑÍAS EN N.C DE CV | F10: 974 | G10: CHICLES | H10: 76.9276 | I10: 1846.2624 | J10: =K10*I10 -> 27693.936 | K10: =SUM(P10+S10+V10) -> 15 | L10: 17.29 | M10: 28.33 | P10: 0 | Q10: 19.17 | R10: 16.17 | S10: 10 | T10: 3.67 | U10: 2.92 | V10: 5 | W10: 0 | X10: 74081.28 | Y10: 87543.61 | Z10: 135 | AA10: 0 | AB10: 218 | AC10: 124 | AD10: 680 | AE10: 0 | AF10: 0 | AG10: 0 | AH10: 0 | AI10: 0 | AJ10: 0 | AK10: 0 | AL10: 0 | AM10: 0 | AN10: 0 | AO10: 0 | AP10: 0 | AQ10: 0 | AR10: 0 | AS10: 0 | AT10: 149 | AU10: 0 | AV10: 248 | AW10: 126 | AX10: 388 | AY10: 0 | AZ10: 0 | BA10: 0 | BB10: 0 | BC10: 0 | BD10: 19 | BE10: 0 | BF10: 53 | BG10: 32 | BH10: 70 | BI10: 0 | BJ10: 0 | BK10: 0 | BL10: 0 | BM10: 0
A11: 88060 | B11: SKITTLES ORIGINAL /10 | C11: 24 | D11: 162 | E11: EFFEM MEXICO INC. Y COMPAÑÍAS EN N.C DE CV | F11: 807 | G11: MATRE MEXICO S DE RL DE CV | H11: 61.51 | I11: 1476.24 | J11: =K11*I11 -> 73812 | K11: =SUM(P11+S11+V11) -> 50 | L11: 12.4 | M11: 1.54 | N11: 10 | O11: 40 | P11: 25 | Q11: 25.94 | R11: 13.21 | S11: 20 | T11: 9.15 | U11: 5.79 | V11: 5 | W11: 0 | X11: 70090.64 | Y11: 30324.43 | Z11: 132 | AA11: 0 | AB11: 103 | AC11: 125 | AD11: 37 | AE11: 0 | AF11: 0 | AG11: 0 | AH11: 0 | AI11: 0 | AJ11: 0 | AK11: 0 | AL11: 0 | AM11: 0 | AN11: 0 | AO11: 0 | AP11: 0 | AQ11: 0 | AR11: 0 | AS11: 0 | AT11: 155 | AU11: 0 | AV11: 313 | AW11: 309 | AX11: 317 | AY11: 0 | AZ11: 0 | BA11: 0 | BB11: 0 | BC11: 0 | BD11: 94 | BE11: 0 | BF11: 106 | BG11: 39 | BH11: 139 | BI11: 0 | BJ11: 0 | BK11: 0 | BL11: 0 | BM11: 0
A12: 65112 | B12: MUECAS LUCAS CHAMOY EXH /10 | C12: 24 | D12: 162 | E12: EFFEM MEXICO INC. Y COMPAÑÍAS EN N.C DE CV | F12: 807 | G12: MATRE MEXICO S DE RL DE CV | H12: 63.79 | I12: 1530.96 | J12: =K12*I12 -> 22964.4 | K12: =SUM(P12+S12+V12) -> 15 | L12: 12.1 | M12: 17.08 | N12: 5 | O12: 10 | P12: 5 | Q12: 24.92 | R12: 25.17 | S12: 5 | T12: 8.15 | U12: 9.71 | V12: 5 | W12: 0 | X12: 69148.36 | Y12: 79546.13 | Z12: 91 | AA12: 0 | AB12: 137 | AC12: 125 | AD12: 410 | AE12: 0 | AF12: 0 | AG12: 0 | AH12: 0 | AI12: 0 | AJ12: 0 | AK12: 0 | AL12: 0 | AM12: 0 | AN12: 0 | AO12: 0 | AP12: 0 | AQ12: 0 | AR12: 0 | AS12: 0 | AT12: 223 | AU12: 0 | AV12: 282 | AW12: 186 | AX12: 604 | AY12: 0 | AZ12: 0 | BA12: 0 | BB12: 0 | BC12: 0 | BD12: 89 | BE12: 0 | BF12: 83 | BG12: 47 | BH12: 233 | BI12: 0 | BJ12: 0 | BK12: 0 | BL12: 0 | BM12: 0
A13: 88158 | B13: CH ORBIT 4 S FRESA / 40 | C13: 24 | D13: 162 | E13: EFFEM MEXICO INC. Y COMPAÑÍAS EN N.C DE CV | F13: 974 | G13: CHICLES | H13: 76.9276 | I13: 1846.2624 | J13: =K13*I13 -> 18462.624 | K13: =SUM(P13+S13+V13) -> 10 | L13: 11.73 | M13: 29.29 | P13: 0 | Q13: 15.88 | R13: 14.92 | S13: 5 | T13: 2.1 | U13: 4.71 | V13: 5 | W13: 0 | X13: 54849.38 | Y13: 90313 | Z13: 109 | AA13: 0 | AB13: 114 | AC13: 117 | AD13: 703 | AE13: 0 | AF13: 0 | AG13: 0 | AH13: 0 | AI13: 0 | AJ13: 0 | AK13: 0 | AL13: 0 | AM13: 0 | AN13: 0 | AO13: 0 | AP13: 0 | AQ13: 0 | AR13: 0 | AS13: 0 | AT13: 129 | AU13: 0 | AV13: 177 | AW13: 150 | AX13: 358 | AY13: 0 | AZ13: 0 | BA13: 0 | BB13: 0 | BC13: 0 | BD13: 16 | BE13: 0 | BF13: 23 | BG13: 23 | BH13: 113 | BI13: 0 | BJ13: 0 | BK13: 0 | BL13: 0 | BM13: 0
A14: 65123 | B14: SKWINKLES CHAMOY EXH /12 | C14: 24 | D14: 162 | E14: EFFEM MEXICO INC. Y COMPAÑÍAS EN N.C DE CV | F14: 807 | G14: MATRE MEXICO S DE RL DE CV | H14: 69.9875 | I14: 1679.7 | J14: =K14*I14 -> 75586.5 | K14: =SUM(P14+S14+V14) -> 45 | L14: 8.44 | M14: 9.83 | N14: 36 | O14: 9 | P14: 10 | Q14: 16.44 | R14: 3.12 | S14: 25 | T14: 7.27 | U14: 3.5 | V14: 10 | W14: 0 | X14: 53995.36 | Y14: 27645.06 | Z14: 61 | AA14: 0 | AB14: 104 | AC14: 75 | AD14: 236 | AE14: 0 | AF14: 0 | AG14: 0 | AH14: 0 | AI14: 0 | AJ14: 0 | AK14: 0 | AL14: 0 | AM14: 0 | AN14: 0 | AO14: 0 | AP14: 0 | AQ14: 0 | AR14: 0 | AS14: 0 | AT14: 145 | AU14: 0 | AV14: 185 | AW14: 129 | AX14: 75 | AY14: 0 | AZ14: 0 | BA14: 0 | BB14: 0 | BC14: 0 | BD14: 77 | BE14: 0 | BF14: 80 | BG14: 35 | BH14: 84 | BI14: 0 | BJ14: 0 | BK14: 0 | BL14: 0 | BM14: 0
A15: 65117 | B15: MUECAS LUCAS CEREZA EXH /10 | C15: 24 | D15: 162 | E15: EFFEM MEXICO INC. Y COMPAÑÍAS EN N.C DE CV | F15: 807 | G15: MATRE MEXICO S DE RL DE CV | H15: 63.79 | I15: 1530.96 | J15: =K15*I15 -> 45928.8 | K15: =SUM(P15+S15+V15) -> 30 | L15: 9.46 | M15: 3.29 | P15: 10 | Q15: 14.79 | R15: 2.96 | S15: 20 | T15: 5.02 | U15: 5.58 | V15: 0 | W15: 0 | X15: 44812.48 | Y15: 18116.36 | Z15: 83 | AA15: 0 | AB15: 102 | AC15: 84 | AD15: 79 | AE15: 0 | AF15: 0 | AG15: 0 | AH15: 0 | AI15: 0 | AJ15: 0 | AK15: 0 | AL15: 0 | AM15: 0 | AN15: 0 | AO15: 0 | AP15: 0 | AQ15: 0 | AR15: 0 | AS15: 0 | AT15: 114 | AU15: 0 | AV15: 173 | AW15: 136 | AX15: 71 | AY15: 0 | AZ15: 0 | BA15: 0 | BB15: 0 | BC15: 0 | BD15: 9 | BE15: 0 | BF15: 68 | BG15: 87 | BH15: 134 | BI15: 0 | BJ15: 0 | BK15: 0 | BL15: 0 | BM15: 0
A16: 6004 | B16: CHOC M&M S PEANUT /6 | C16: 32 | D16: 162 | E16: EFFEM MEXICO INC. Y COMPAÑÍAS EN N.C DE CV | F16: 558 | G16: CHOCOLATES | H16: 80.55 | I16: 2577.6 | J16: =K16*I16 -> 51552 | K16: =SUM(P16+S16+V16) -> 20 | L16: 5.81 | M16: 0.12 | N16: 8 | O16: 12 | P16: 10 | Q16: 8.2 | R16: 2.5 | S16: 10 | T16: 2.28 | U16: 3.44 | V16: 0 | W16: 0 | X16: 42006.82 | Y16: 15626.7 | Z16: 60 | AA16: 0 | AB16: 93 | AC16: 66 | AD16: 4 | AE16: 0 | AF16: 0 | AG16: 0 | AH16: 0 | AI16: 0 | AJ16: 0 | AK16: 0 | AL16: 0 | AM16: 0 | AN16: 0 | AO16: 0 | AP16: 0 | AQ16: 0 | AR16: 0 | AS16: 0 | AT16: 140 | AU16: 0 | AV16: 79 | AW16: 87 | AX16: 80 | AY16: 0 | AZ16: 0 | BA16: 0 | BB16: 0 | BC16: 0 | BD16: 18 | BE16: 0 | BF16: 35 | BG16: 40 | BH16: 110 | BI16: 0 | BJ16: 0 | BK16: 0 | BL16: 0 | BM16: 0
A17: 65120 | B17: MUECAS LUCAS SANDIA EXH /10 | C17: 24 | D17: 162 | E17: EFFEM MEXICO INC. Y COMPAÑÍAS EN N.C DE CV | F17: 807 | G17: MATRE MEXICO S DE RL DE CV | H17: 63.79 | I17: 1530.96 | J17: =K17*I17 -> 45928.8 | K17: =SUM(P17+S17+V17) -> 30 | L17: 7.19 | M17: 2.75 | P17: 15 | Q17: 12.5 | R17: 8.71 | S17: 5 | T17: 6.62 | U17: 1.71 | V17: 10 | W17: 0 | X17: 40283.38 | Y17: 20157.64 | Z17: 51 | AA17: 0 | AB17: 88 | AC17: 67 | AD17: 66 | AE17: 0 | AF17: 0 | AG17: 0 | AH17: 0 | AI17: 0 | AJ17: 0 | AK17: 0 | AL17: 0 | AM17: 0 | AN17: 0 | AO17: 0 | AP17: 0 | AQ17: 0 | AR17: 0 | AS17: 0 | AT17: 55 | AU17: 0 | AV17: 177 | AW17: 136 | AX17: 209 | AY17: 0 | AZ17: 0 | BA17: 0 | BB17: 0 | BC17: 0 | BD17: 66 | BE17: 0 | BF17: 69 | BG17: 48 | BH17: 41 | BI17: 0 | BJ17: 0 | BK17: 0 | BL17: 0 | BM17: 0
A18: 88033 | B18: CH WRIGLEY S WINTERFRESH 5 S / 20 | C18: 40 | D18: 162 | E18: EFFEM MEXICO INC. Y COMPAÑÍAS EN N.C DE CV | F18: 974 | G18: CHICLES | H18: 123.2556 | I18: 4930.224 | J18: =K18*I18 -> 29581.344 | K18: =SUM(P18+S18+V18) -> 6 | L18: 3 | M18: 1.65 | P18: 3 | Q18: 2.72 | R18: 3.95 | S18: 0 | T18: 2.38 | U18: 0.72 | V18: 3 | W18: 0 | X18: 39934.81 | Y18: 31183.67 | Z18: 54 | AA18: 0 | AB18: 61 | AC18: 10 | AD18: 66 | AE18: 0 | AF18: 0 | AG18: 0 | AH18: 0 | AI18: 0 | AJ18: 0 | AK18: 0 | AL18: 0 | AM18: 0 | AN18: 0 | AO18: 0 | AP18: 0 | AQ18: 0 | AR18: 0 | AS18: 0 | AT18: 42 | AU18: 0 | AV18: 42 | AW18: 50 | AX18: 158 | AY18: 0 | AZ18: 0 | BA18: 0 | BB18: 0 | BC18: 0 | BD18: 55 | BE18: 0 | BF18: 40 | BG18: 0 | BH18: 29 | BI18: 0 | BJ18: 0 | BK18: 0 | BL18: 0 | BM18: 0
A19: 65113 | B19: MUECAS LUCAS MANGO EXH /10 | C19: 24 | D19: 162 | E19: EFFEM MEXICO INC. Y COMPAÑÍAS EN N.C DE CV | F19: 807 | G19: MATRE MEXICO S DE RL DE CV | H19: 63.79 | I19: 1530.96 | J19: =K19*I19 -> 7654.8 | K19: =SUM(P19+S19+V19) -> 5 | L19: 6.25 | M19: 17.33 | O19: 2 | P19: 0 | Q19: 12.29 | R19: 11.71 | S19: 5 | T19: 5.73 | U19: 7.33 | V19: 0 | W19: 0 | X19: 37157.67 | Y19: 55688.67 | Z19: 35 | AA19: 0 | AB19: 90 | AC19: 50 | AD19: 416 | AE19: 0 | AF19: 0 | AG19: 0 | AH19: 0 | AI19: 0 | AJ19: 0 | AK19: 0 | AL19: 0 | AM19: 0 | AN19: 0 | AO19: 0 | AP19: 0 | AQ19: 0 | AR19: 0 | AS19: 0 | AT19: 53 | AU19: 0 | AV19: 195 | AW19: 94 | AX19: 281 | AY19: 0 | AZ19: 0 | BA19: 0 | BB19: 0 | BC19: 0 | BD19: 77 | BE19: 0 | BF19: 34 | BG19: 53 | BH19: 176 | BI19: 0 | BJ19: 0 | BK19: 0 | BL19: 0 | BM19: 0
A20: 6003 | B20: CHOC M&M S PLAIN /6 | C20: 32 | D20: 162 | E20: EFFEM MEXICO INC. Y COMPAÑÍAS EN N.C DE CV | F20: 558 | G20: CHOCOLATES | H20: 80.55 | I20: 2577.6 | J20: =K20*I20 -> 25776 | K20: =SUM(P20+S20+V20) -> 10 | L20: 5 | M20: 0.59 | O20: 8 | P20: 5 | Q20: 6.48 | R20: 4.09 | S20: 5 | T20: 2.25 | U20: 2.38 | V20: 0 | W20: 0 | X20: 35401.72 | Y20: 18204.3 | Z20: 52 | AA20: 0 | AB20: 71 | AC20: 74 | AD20: 19 | AE20: 0 | AF20: 0 | AG20: 0 | AH20: 0 | AI20: 0 | AJ20: 0 | AK20: 0 | AL20: 0 | AM20: 0 | AN20: 0 | AO20: 0 | AP20: 0 | AQ20: 0 | AR20: 0 | AS20: 0 | AT20: 82 | AU20: 0 | AV20: 68 | AW20: 115 | AX20: 131 | AY20: 0 | AZ20: 0 | BA20: 0 | BB20: 0 | BC20: 0 | BD20: 20 | BE20: 0 | BF20: 34 | BG20: 36 | BH20: 76 | BI20: 0 | BJ20: 0 | BK20: 0 | BL20: 0 | BM20: 0
A21: 65152 | B21: SKWINKLOTE SANDIA (240G) /6 | C21: 24 | D21: 162 | E21: EFFEM MEXICO INC. Y COMPAÑÍAS EN N.C DE CV | F21: 807 | G21: MATRE MEXICO S DE RL DE CV | H21: 63.0306 | I21: 1512.7344 | J21: =K21*I21 -> 30254.688 | K21: =SUM(P21+S21+V21) -> 20 | L21: 9.35 | M21: 1.54 | P21: 10 | Q21: 6.83 | R21: 4.42 | S21: 10 | T21: 5.12 | U21: 5.54 | V21: 0 | W21: 0 | X21: 32240.15 | Y21: 17396.45 | Z21: 107 | AA21: 0 | AB21: 100 | AC21: 35 | AD21: 37 | AE21: 0 | AF21: 0 | AG21: 0 | AH21: 0 | AI21: 0 | AJ21: 0 | AK21: 0 | AL21: 0 | AM21: 0 | AN21: 0 | AO21: 0 | AP21: 0 | AQ21: 0 | AR21: 0 | AS21: 0 | AT21: 80 | AU21: 0 | AV21: 48 | AW21: 72 | AX21: 106 | AY21: 0 | AZ21: 0 | BA21: 0 | BB21: 0 | BC21: 0 | BD21: 40 | BE21: 0 | BF21: 49 | BG21: 68 | BH21: 133 | BI21: 0 | BJ21: 0 | BK21: 0 | BL21: 0 | BM21: 0
A22: 65165 | B22: MUECAS LUCAS PEPINO EXH /10 | C22: 24 | D22: 162 | E22: EFFEM MEXICO INC. Y COMPAÑÍAS EN N.C DE CV | F22: 807 | G22: MATRE MEXICO S DE RL DE CV | H22: 63.79 | I22: 1530.96 | J22: =K22*I22 -> 7654.8 | K22: =SUM(P22+S22+V22) -> 5 | L22: 4.75 | M22: 17.38 | P22: 0 | Q22: 8.9 | R22: 6.25 | S22: 5 | T22: 5.62 | U22: 2.92 | V22: 0 | W22: 0 | X22: 29502.88 | Y22: 40634.23 | Z22: 27 | AA22: 0 | AB22: 63 | AC22: 48 | AD22: 417 | AE22: 0 | AF22: 0 | AG22: 0 | AH22: 0 | AI22: 0 | AJ22: 0 | AK22: 0 | AL22: 0 | AM22: 0 | AN22: 0 | AO22: 0 | AP22: 0 | AQ22: 0 | AR22: 0 | AS22: 0 | AT22: 51 | AU22: 0 | AV22: 111 | AW22: 103 | AX22: 150 | AY22: 0 | AZ22: 0 | BA22: 0 | BB22: 0 | BC22: 0 | BD22: 50 | BE22: 0 | BF22: 63 | BG22: 44 | BH22: 70 | BI22: 0 | BJ22: 0 | BK22: 0 | BL22: 0 | BM22: 0
A23: 88161 | B23: SKITTLES WILDBERRIES /10 | C23: 24 | D23: 162 | E23: EFFEM MEXICO INC. Y COMPAÑÍAS EN N.C DE CV | F23: 807 | G23: MATRE MEXICO S DE RL DE CV | H23: 61.51 | I23: 1476.24 | J23: =K23*I23 -> 22143.6 | K23: =SUM(P23+S23+V23) -> 15 | L23: 5.79 | M23: 2.46 | P23: 10 | Q23: 9.35 | R23: 15.29 | S23: 0 | T23: 4.21 | U23: 0.96 | V23: 5 | W23: 0 | X23: 28571.4 | Y23: 27617.99 | Z23: 40 | AA23: 0 | AB23: 76 | AC23: 46 | AD23: 59 | AE23: 0 | AF23: 0 | AG23: 0 | AH23: 0 | AI23: 0 | AJ23: 0 | AK23: 0 | AL23: 0 | AM23: 0 | AN23: 0 | AO23: 0 | AP23: 0 | AQ23: 0 | AR23: 0 | AS23: 0 | AT23: 57 | AU23: 0 | AV23: 121 | AW23: 93 | AX23: 367 | AY23: 0 | AZ23: 0 | BA23: 0 | BB23: 0 | BC23: 0 | BD23: 31 | BE23: 0 | BF23: 69 | BG23: 2 | BH23: 23 | BI23: 0 | BJ23: 0 | BK23: 0 | BL23: 0 | BM23: 0
A24: 6041 | B24: EXHIBIDOR VARIETY PACK/14 630.6GR | C24: 10 | D24: 162 | E24: EFFEM MEXICO INC. Y COMPAÑÍAS EN N.C DE CV | F24: 558 | G24: CHOCOLATES | H24: 181.19 | I24: 1811.9 | J24: =K24*I24 -> 27178.5 | K24: =SUM(P24+S24+V24) -> 15 | L24: 0 | M24: 0 | P24: =L24*0.8-M24 -> 0 | Q24: 0 | R24: 0 | S24: 15 | T24: 0 | U24: 0 | V24: =T24*0.8-U24 -> 0 | W24: 0 | X24: 0 | Y24: 0 | Z24: 0 | AA24: 0 | AB24: 0 | AC24: 0 | AD24: 0 | AE24: 0 | AF24: 0 | AG24: 0 | AH24: 0 | AI24: 0 | AJ24: 0 | AK24: 0 | AL24: 0 | AM24: 0 | AN24: 0 | AO24: 0 | AP24: 0 | AQ24: 0 | AR24: 0 | AS24: 0 | AT24: 0 | AU24: 0 | AV24: 0 | AW24: 0 | AX24: 0 | AY24: 0 | AZ24: 0 | BA24: 0 | BB24: 0 | BC24: 0 | BD24: 0 | BE24: 0 | BF24: 0 | BG24: 0 | BH24: 0 | BI24: 0 | BJ24: 0 | BK24: 0 | BL24: 0 | BM24: 0
A25: 6020 | B25: CH HUBBA BUBBA ORIGINAL / 6 | C25: 24 | D25: 162 | E25: EFFEM MEXICO INC. Y COMPAÑÍAS EN N.C DE CV | F25: 974 | G25: CHICLES | H25: 107.6336 | I25: 2583.2064 | J25: =K25*I25 -> 25832.064 | K25: =SUM(P25+S25+V25) -> 10 | L25: 0.9 | M25: 0.79 | P25: 5 | Q25: 4.62 | R25: 1.62 | S25: 5 | T25: 2.08 | U25: 2.75 | V25: 0 | W25: 0 | X25: 19643.13 | Y25: 13346.57 | Z25: 0 | AA25: 0 | AB25: 14 | AC25: 15 | AD25: 19 | AE25: 0 | AF25: 0 | AG25: 0 | AH25: 0 | AI25: 0 | AJ25: 0 | AK25: 0 | AL25: 0 | AM25: 0 | AN25: 0 | AO25: 0 | AP25: 0 | AQ25: 0 | AR25: 0 | AS25: 0 | AT25: 47 | AU25: 0 | AV25: 45 | AW25: 38 | AX25: 39 | AY25: 0 | AZ25: 0 | BA25: 0 | BB25: 0 | BC25: 0 | BD25: 21 | BE25: 0 | BF25: 20 | BG25: 18 | BH25: 66 | BI25: 0 | BJ25: 0 | BK25: 0 | BL25: 0 | BM25: 0
A26: 65100 | B26: SKWINKLES SANDIA C/CHILE RELLENOS /12 | C26: 24 | D26: 162 | E26: EFFEM MEXICO INC. Y COMPAÑÍAS EN N.C DE CV | F26: 807 | G26: MATRE MEXICO S DE RL DE CV | H26: 80.9362 | I26: 1942.4688 | J26: =K26*I26 -> 15539.75 | K26: =SUM(P26+S26+V26) -> 8 | L26: 2.4 | M26: 0 | P26: 5 | Q26: 3.98 | R26: 2.42 | S26: 3 | T26: 1.96 | U26: 6.33 | V26: 0 | W26: 0 | X26: 16187.24 | Y26: 16996.6 | Z26: 24 | AA26: 0 | AB26: 0 | AC26: 67 | AD26: 0 | AE26: 0 | AF26: 0 | AG26: 0 | AH26: 0 | AI26: 0 | AJ26: 0 | AK26: 0 | AL26: 0 | AM26: 0 | AN26: 0 | AO26: 0 | AP26: 0 | AQ26: 0 | AR26: 0 | AS26: 0 | AT26: 51 | AU26: 0 | AV26: 16 | AW26: 57 | AX26: 58 | AY26: 0 | AZ26: 0 | BA26: 0 | BB26: 0 | BC26: 0 | BD26: 47 | BE26: 0 | BF26: 0 | BG26: 0 | BH26: 152 | BI26: 0 | BJ26: 0 | BK26: 0 | BL26: 0 | BM26: 0
A27: 6015 | B27: CHOC SNICKERS SNACK 21.5GR /11 | C27: 18 | D27: 162 | E27: EFFEM MEXICO INC. Y COMPAÑÍAS EN N.C DE CV | F27: 558 | G27: CHOCOLATES | H27: 96.61 | I27: 1738.98 | J27: =K27*I27 -> 19128.78 | K27: =SUM(P27+S27+V27) -> 11 | L27: 1.08 | M27: 0 | P27: 4 | Q27: 7.94 | R27: 4.11 | S27: 5 | T27: 0.22 | U27: 0.11 | V27: 2 | W27: 0 | X27: 16085.56 | Y27: 7342.36 | Z27: 0 | AA27: 0 | AB27: 9 | AC27: 21 | AD27: 0 | AE27: 0 | AF27: 0 | AG27: 0 | AH27: 0 | AI27: 0 | AJ27: 0 | AK27: 0 | AL27: 0 | AM27: 0 | AN27: 0 | AO27: 0 | AP27: 0 | AQ27: 0 | AR27: 0 | AS27: 0 | AT27: 51 | AU27: 0 | AV27: 55 | AW27: 74 | AX27: 74 | AY27: 0 | AZ27: 0 | BA27: 0 | BB27: 0 | BC27: 0 | BD27: 4 | BE27: 0 | BF27: 0 | BG27: 0 | BH27: 2 | BI27: 0 | BJ27: 0 | BK27: 0 | BL27: 0 | BM27: 0
A28: 6021 | B28: CH HUBBA BUBBA GRAPE / 6 | C28: 24 | D28: 162 | E28: EFFEM MEXICO INC. Y COMPAÑÍAS EN N.C DE CV | F28: 974 | G28: CHICLES | H28: 107.6336 | I28: 2583.2064 | J28: =K28*I28 -> 33581.683 | K28: =SUM(P28+S28+V28) -> 13 | L28: 1.08 | M28: -0.17 | P28: 5 | Q28: 3.42 | R28: 0.08 | S28: 5 | T28: 1.6 | U28: 0.17 | V28: 3 | W28: 0 | X28: 15768.32 | Y28: 215.27 | Z28: 11 | AA28: 0 | AB28: 10 | AC28: 10 | AD28: -4 | AE28: 0 | AF28: 0 | AG28: 0 | AH28: 0 | AI28: 0 | AJ28: 0 | AK28: 0 | AL28: 0 | AM28: 0 | AN28: 0 | AO28: 0 | AP28: 0 | AQ28: 0 | AR28: 0 | AS28: 0 | AT28: 22 | AU28: 0 | AV28: 44 | AW28: 32 | AX28: 2 | AY28: 0 | AZ28: 0 | BA28: 0 | BB28: 0 | BC28: 0 | BD28: 18 | BE28: 0 | BF28: 10 | BG28: 21 | BH28: 4 | BI28: 0 | BJ28: 0 | BK28: 0 | BL28: 0 | BM28: 0
A29: 96183 | B29: EXH SKWINKLES CHUNKS MANGO 270GR/ 6 | C29: 20 | D29: 162 | E29: EFFEM MEXICO INC. Y COMPAÑÍAS EN N.C DE CV | F29: 807 | G29: MATRE MEXICO S DE RL DE CV | H29: 73.9487 | I29: 1478.974 | J29: =K29*I29 -> 19226.662 | K29: =SUM(P29+S29+V29) -> 13 | L29: 1.98 | M29: 0.55 | N29: 10 | P29: 3 | Q29: 7.15 | R29: 1.9 | S29: 8 | T29: 0.5 | U29: 0.55 | V29: 2 | W29: 0 | X29: 14235.12 | Y29: 4436.92 | Z29: 15 | AA29: 0 | AB29: 14 | AC29: 21 | AD29: 11 | AE29: 0 | AF29: 0 | AG29: 0 | AH29: 0 | AI29: 0 | AJ29: 0 | AK29: 0 | AL29: 0 | AM29: 0 | AN29: 0 | AO29: 0 | AP29: 0 | AQ29: 0 | AR29: 0 | AS29: 0 | AT29: 39 | AU29: 0 | AV29: 82 | AW29: 44 | AX29: 38 | AY29: 0 | AZ29: 0 | BA29: 0 | BB29: 0 | BC29: 0 | BD29: 9 | BE29: 0 | BF29: 1 | BG29: 0 | BH29: 11 | BI29: 0 | BJ29: 0 | BK29: 0 | BL29: 0 | BM29: 0
A30: 6093 | B30: CHOC SNICKERS ALMOND 260G / 6 | C30: 12 | D30: 162 | E30: EFFEM MEXICO INC. Y COMPAÑÍAS EN N.C DE CV | F30: 558 | G30: CHOCOLATES | H30: 84.1675 | I30: 1010.01 | J30: =K30*I30 -> 13130.13 | K30: =SUM(P30+S30+V30) -> 13 | L30: 4.12 | M30: 0.5 | P30: 5 | Q30: 7.08 | R30: 4.75 | S30: 5 | T30: 2 | U30: 0 | V30: 3 | W30: 0 | X30: 13340.55 | Y30: 5302.55 | Z30: 6 | AA30: 0 | AB30: 26 | AC30: 35 | AD30: 6 | AE30: 0 | AF30: 0 | AG30: 0 | AH30: 0 | AI30: 0 | AJ30: 0 | AK30: 0 | AL30: 0 | AM30: 0 | AN30: 0 | AO30: 0 | AP30: 0 | AQ30: 0 | AR30: 0 | AS30: 0 | AT30: 21 | AU30: 0 | AV30: 43 | AW30: 42 | AX30: 57 | AY30: 0 | AZ30: 0 | BA30: 0 | BB30: 0 | BC30: 0 | BD30: 0 | BE30: 0 | BF30: 24 | BG30: 0 | BH30: 0 | BI30: 0 | BJ30: 0 | BK30: 0 | BL30: 0 | BM30: 0
A31: 97317 | B31: CAJA SNICKERS MINIS 81GR / MARS | C31: 20 | D31: 162 | E31: EFFEM MEXICO INC. Y COMPAÑÍAS EN N.C DE CV | F31: 162 | G31: EFFEM MEXICO INC. Y COMPAÑÍA S EN N.C DE CV | H31: 33.9863 | I31: 679.726 | J31: =K31*I31 -> 6797.26 | K31: =SUM(P31+S31+V31) -> 10 | L31: 6.3 | M31: 3.7 | P31: 4 | Q31: 10.85 | R31: 2.15 | S31: 6 | T31: 1.3 | U31: 7.35 | V31: 0 | W31: 0 | X31: 12540.94 | Y31: 8972.38 | Z31: 126 | AA31: 0 | AB31: 0 | AC31: 0 | AD31: 74 | AE31: 0 | AF31: 0 | AG31: 0 | AH31: 0 | AI31: 0 | AJ31: 0 | AK31: 0 | AL31: 0 | AM31: 0 | AN31: 0 | AO31: 0 | AP31: 0 | AQ31: 0 | AR31: 0 | AS31: 0 | AT31: 217 | AU31: 0 | AV31: 0 | AW31: 0 | AX31: 43 | AY31: 0 | AZ31: 0 | BA31: 0 | BB31: 0 | BC31: 0 | BD31: 26 | BE31: 0 | BF31: 0 | BG31: 0 | BH31: 147 | BI31: 0 | BJ31: 0 | BK31: 0 | BL31: 0 | BM31: 0
A32: 65103 | B32: BOMVASO LUCAS LIMON /10 LUCAS | C32: 24 | D32: 162 | E32: EFFEM MEXICO INC. Y COMPAÑÍAS EN N.C DE CV | F32: 807 | G32: MATRE MEXICO S DE RL DE CV | H32: 61.1678 | I32: 1468.0272 | J32: =K32*I32 -> 14680.272 | K32: =SUM(P32+S32+V32) -> 10 | L32: 1.35 | M32: 0 | P32: 3 | Q32: 5.15 | R32: 0 | S32: 5 | T32: 1.9 | U32: 0 | V32: 2 | W32: 0 | X32: 12325.31 | Y32: 0 | Z32: 0 | AA32: 0 | AB32: 20 | AC32: 25 | AD32: 0 | AE32: 0 | AF32: 0 | AG32: 0 | AH32: 0 | AI32: 0 | AJ32: 0 | AK32: 0 | AL32: 0 | AM32: 0 | AN32: 0 | AO32: 0 | AP32: 0 | AQ32: 0 | AR32: 0 | AS32: 0 | AT32: 0 | AU32: 0 | AV32: 97 | AW32: 53 | AX32: 0 | AY32: 0 | AZ32: 0 | BA32: 0 | BB32: 0 | BC32: 0 | BD32: 0 | BE32: 0 | BF32: 28 | BG32: 35 | BH32: 0 | BI32: 0 | BJ32: 0 | BK32: 0 | BL32: 0 | BM32: 0
A33: 65126 | B33: SKWINKLES PIÑA/TAM RELLENO /12 | C33: 24 | D33: 162 | E33: EFFEM MEXICO INC. Y COMPAÑÍAS EN N.C DE CV | F33: 807 | G33: MATRE MEXICO S DE RL DE CV | H33: 80.9362 | I33: 1942.4688 | J33: =K33*I33 -> 0 | K33: =SUM(P33+S33+V33) -> 0 | L33: 3.52 | M33: 6.04 | P33: 0 | Q33: 2.52 | R33: 2.71 | S33: 0 | T33: 0.29 | U33: 3 | V33: 0 | W33: 0 | X33: 12302.3 | Y33: 22824.01 | Z33: 70 | AA33: 0 | AB33: 9 | AC33: 11 | AD33: 145 | AE33: 0 | AF33: 0 | AG33: 0 | AH33: 0 | AI33: 0 | AJ33: 0 | AK33: 0 | AL33: 0 | AM33: 0 | AN33: 0 | AO33: 0 | AP33: 0 | AQ33: 0 | AR33: 0 | AS33: 0 | AT33: 36 | AU33: 0 | AV33: 0 | AW33: 49 | AX33: 65 | AY33: 0 | AZ33: 0 | BA33: 0 | BB33: 0 | BC33: 0 | BD33: 7 | BE33: 0 | BF33: 0 | BG33: 0 | BH33: 72 | BI33: 0 | BJ33: 0 | BK33: 0 | BL33: 0 | BM33: 0
A34: 88031 | B34: CH WRIGLEY S DOUBLEMINT /20 | C34: 40 | D34: 162 | E34: EFFEM MEXICO INC. Y COMPAÑÍAS EN N.C DE CV | F34: 974 | G34: CHICLES | H34: 123.2556 | I34: 4930.224 | J34: =K34*I34 -> 24651.12 | K34: =SUM(P34+S34+V34) -> 5 | L34: 0.75 | M34: 0.12 | P34: 3 | Q34: 1 | R34: 1 | S34: 1 | T34: 0.62 | U34: 0.32 | V34: 1 | W34: 0 | X34: 11709.28 | Y34: 7148.82 | Z34: 30 | AA34: 0 | AB34: 0 | AC34: 0 | AD34: 5 | AE34: 0 | AF34: 0 | AG34: 0 | AH34: 0 | AI34: 0 | AJ34: 0 | AK34: 0 | AL34: 0 | AM34: 0 | AN34: 0 | AO34: 0 | AP34: 0 | AQ34: 0 | AR34: 0 | AS34: 0 | AT34: 40 | AU34: 0 | AV34: 0 | AW34: 0 | AX34: 40 | AY34: 0 | AZ34: 0 | BA34: 0 | BB34: 0 | BC34: 0 | BD34: 25 | BE34: 0 | BF34: 0 | BG34: 0 | BH34: 13 | BI34: 0 | BJ34: 0 | BK34: 0 | BL34: 0 | BM34: 0
A35: 65045 | B35: CHOC CONEJO MINI (120 GR) / 12 TURIN | C35: 18 | D35: 162 | E35: EFFEM MEXICO INC. Y COMPAÑÍAS EN N.C DE CV | F35: 123 | G35: CHOCOLATES TURIN S.A. DE C.V. | H35: 60.8763 | I35: 1095.7734 | J35: =K35*I35 -> 13149.281 | K35: =SUM(P35+S35+V35) -> 12 | L35: 2.97 | M35: 0 | P35: 3 | Q35: 6.25 | R35: 0.11 | S35: 7 | T35: 1.42 | U35: 0.06 | V35: 2 | W35: 0 | X35: 11657.81 | Y35: 182.63 | Z35: 0 | AA35: 0 | AB35: 18 | AC35: 71 | AD35: 0 | AE35: 0 | AF35: 0 | AG35: 0 | AH35: 0 | AI35: 0 | AJ35: 0 | AK35: 0 | AL35: 0 | AM35: 0 | AN35: 0 | AO35: 0 | AP35: 0 | AQ35: 0 | AR35: 0 | AS35: 0 | AT35: 27 | AU35: 0 | AV35: 51 | AW35: 69 | AX35: 2 | AY35: 0 | AZ35: 0 | BA35: 0 | BB35: 0 | BC35: 0 | BD35: 9 | BE35: 0 | BF35: 15 | BG35: 3 | BH35: 1 | BI35: 0 | BJ35: 0 | BK35: 0 | BL35: 0 | BM35: 0
A36: 65140 | B36: SKWINKLES MANGO CHAMOY ENCHILADO /12 | C36: 24 | D36: 162 | E36: EFFEM MEXICO INC. Y COMPAÑÍAS EN N.C DE CV | F36: 807 | G36: MATRE MEXICO S DE RL DE CV | H36: 69.9875 | I36: 1679.7 | J36: =K36*I36 -> 0 | K36: =SUM(P36+S36+V36) -> 0 | L36: 2.5 | M36: 0.04 | P36: 0 | Q36: 3.75 | R36: 12.62 | S36: 0 | T36: 0.67 | U36: 3.83 | V36: 0 | W36: 0 | X36: 11617.92 | Y36: 27715.05 | Z36: 23 | AA36: 0 | AB36: 34 | AC36: 6 | AD36: 1 | AE36: 0 | AF36: 0 | AG36: 0 | AH36: 0 | AI36: 0 | AJ36: 0 | AK36: 0 | AL36: 0 | AM36: 0 | AN36: 0 | AO36: 0 | AP36: 0 | AQ36: 0 | AR36: 0 | AS36: 0 | AT36: 37 | AU36: 0 | AV36: 25 | AW36: 56 | AX36: 303 | AY36: 0 | AZ36: 0 | BA36: 0 | BB36: 0 | BC36: 0 | BD36: 16 | BE36: 0 | BF36: 0 | BG36: 0 | BH36: 92 | BI36: 0 | BJ36: 0 | BK36: 0 | BL36: 0 | BM36: 0
A37: 2048 | B37: CH HUBBA BUBBA FRESA / 6 MARS | C37: 24 | D37: 162 | E37: EFFEM MEXICO INC. Y COMPAÑÍAS EN N.C DE CV | F37: 974 | G37: CHICLES | H37: 107.6336 | I37: 2583.2064 | J37: =K37*I37 -> 20665.651 | K37: =SUM(P37+S37+V37) -> 8 | L37: 0.33 | M37: 0 | P37: 3 | Q37: 3.29 | R37: 1.17 | S37: 3 | T37: 0.71 | U37: 0.5 | V37: 2 | W37: 0 | X37: 11193.89 | Y37: 4305.34 | Z37: 0 | AA37: 0 | AB37: 8 | AC37: 0 | AD37: 0 | AE37: 0 | AF37: 0 | AG37: 0 | AH37: 0 | AI37: 0 | AJ37: 0 | AK37: 0 | AL37: 0 | AM37: 0 | AN37: 0 | AO37: 0 | AP37: 0 | AQ37: 0 | AR37: 0 | AS37: 0 | AT37: 29 | AU37: 0 | AV37: 36 | AW37: 28 | AX37: 28 | AY37: 0 | AZ37: 0 | BA37: 0 | BB37: 0 | BC37: 0 | BD37: 17 | BE37: 0 | BF37: 0 | BG37: 0 | BH37: 12 | BI37: 0 | BJ37: 0 | BK37: 0 | BL37: 0 | BM37: 0
A38: 65890 | B38: MUECAS LUCAS TAMARINDO EXH /10 | C38: 24 | D38: 162 | E38: EFFEM MEXICO INC. Y COMPAÑÍAS EN N.C DE CV | F38: 807 | G38: MATRE MEXICO S DE RL DE CV | H38: 63.79 | I38: 1530.96 | J38: =K38*I38 -> 0 | K38: =SUM(P38+S38+V38) -> 0 | L38: 1.4 | M38: 3.46 | P38: 0 | Q38: 3.81 | R38: 6.54 | S38: 0 | T38: 1.79 | U38: 0.29 | V38: 0 | W38: 0 | X38: 10716.72 | Y38: 15756.13 | Z38: 33 | AA38: 0 | AB38: 0 | AC38: 1 | AD38: 83 | AE38: 0 | AF38: 0 | AG38: 0 | AH38: 0 | AI38: 0 | AJ38: 0 | AK38: 0 | AL38: 0 | AM38: 0 | AN38: 0 | AO38: 0 | AP38: 0 | AQ38: 0 | AR38: 0 | AS38: 0 | AT38: 73 | AU38: 0 | AV38: 11 | AW38: 15 | AX38: 157 | AY38: 0 | AZ38: 0 | BA38: 0 | BB38: 0 | BC38: 0 | BD38: 43 | BE38: 0 | BF38: 0 | BG38: 0 | BH38: 7 | BI38: 0 | BJ38: 0 | BK38: 0 | BL38: 0 | BM38: 0
A39: 97315 | B39: CORAZON M&M & SKITTLES 100GR / MARS | C39: 14 | D39: 162 | E39: EFFEM MEXICO INC. Y COMPAÑÍAS EN N.C DE CV | F39: 162 | G39: EFFEM MEXICO INC. Y COMPAÑÍA S EN N.C DE CV | H39: 56.568 | I39: 791.952 | J39: =K39*I39 -> 7919.52 | K39: =SUM(P39+S39+V39) -> 10 | L39: 1.64 | M39: 4.36 | P39: 0 | Q39: 7.93 | R39: 0.07 | S39: 10 | T39: 2.71 | U39: 3.29 | V39: 0 | W39: 0 | X39: 9729.7 | Y39: 6109.34 | Z39: 23 | AA39: 0 | AB39: 0 | AC39: 0 | AD39: 61 | AE39: 0 | AF39: 0 | AG39: 0 | AH39: 0 | AI39: 0 | AJ39: 0 | AK39: 0 | AL39: 0 | AM39: 0 | AN39: 0 | AO39: 0 | AP39: 0 | AQ39: 0 | AR39: 0 | AS39: 0 | AT39: 111 | AU39: 0 | AV39: 0 | AW39: 0 | AX39: 1 | AY39: 0 | AZ39: 0 | BA39: 0 | BB39: 0 | BC39: 0 | BD39: 38 | BE39: 0 | BF39: 0 | BG39: 0 | BH39: 46 | BI39: 0 | BJ39: 0 | BK39: 0 | BL39: 0 | BM39: 0
A40: 91046 | B40: CHOC JOSE CUERVO TUBO 180GR 2786 | C40: 6 | D40: 162 | E40: EFFEM MEXICO INC. Y COMPAÑÍAS EN N.C DE CV | F40: 123 | G40: CHOCOLATES TURIN S.A. DE C.V. | H40: 119.37 | I40: 716.22 | J40: =K40*I40 -> 9310.86 | K40: =SUM(P40+S40+V40) -> 13 | L40: 2.42 | M40: 0 | P40: 5 | Q40: 10.33 | R40: 5 | S40: 8 | T40: 0.25 | U40: 1.5 | V40: 0 | W40: 0 | X40: 9310.86 | Y40: 4655.43 | Z40: 0 | AA40: 0 | AB40: 6 | AC40: 17 | AD40: 0 | AE40: 0 | AF40: 0 | AG40: 0 | AH40: 0 | AI40: 0 | AJ40: 0 | AK40: 0 | AL40: 0 | AM40: 0 | AN40: 0 | AO40: 0 | AP40: 0 | AQ40: 0 | AR40: 0 | AS40: 0 | AT40: 12 | AU40: 0 | AV40: 32 | AW40: 36 | AX40: 30 | AY40: 0 | AZ40: 0 | BA40: 0 | BB40: 0 | BC40: 0 | BD40: 1 | BE40: 0 | BF40: 0 | BG40: 1 | BH40: 9 | BI40: 0 | BJ40: 0 | BK40: 0 | BL40: 0 | BM40: 0
...

Sheet 280126
J1: =SUM(J3:J212) -> 1038832.3 | K1: =SUM(K3:K212) -> 601 | O1: =SUM(O3:O212) -> 208 | T1: =SUM(T3:T212) -> 296 | W1: =SUM(W3:W212) -> 97 | X1: =Z1/Y1 -> 0.98250317 | Y1: =SUM(Y3:Y212) -> 2446402 | Z1: =SUM(Z3:Z212) -> 2403597.7
A2: Articulo | B2: Nombre | C2: UXC | D2: Subfamilia | E2: SN | F2: Categoria | G2: CN | H2: CostoCIVA | I2: CostoXCaja | J2: $Pedido | K2: SumaPedido | M2: 10VentasG | N2: 10ExistenciaG | O2: PedidoLPD | P2: 30VentasG | Q2: 30ExistenciasG | T2: PedMorelia | U2: 50VentasG | V2: 50ExistenciaG | W2: PedidoZam | X2: ExCEDIS | Y2: ValorVentaG | Z2: ValorExistenciaG | AA2: 10Actual15 | AB2: 10Actual30R | AC2: 10Anterior15 | AD2: 10Anterior30R | AE2: 10ExistenciaWC | AF2: 40Actual15 | AG2: 40Actual30R | AH2: 40Anterior15 | AI2: 40Anterior30R | AJ2: 40ExistenciaWC | AK2: 42Actual15 | AL2: 42Actual30R | AM2: 42Anterior15 | AN2: 42Anterior30R | AO2: 42ExistenciaWC | AP2: 44Actual15 | AQ2: 44Actual30R | AR2: 44Anterior15 | AS2: 44Anterior30R | AT2: 44ExistenciaWC | AU2: 30Actual15 | AV2: 30Actual30R | AW2: 30Anterior15 | AX2: 30Anterior30R | AY2: 30ExistenciaWC | AZ2: 32Actual15 | BA2: 32Actual30R | BB2: 32Anterior15 | BC2: 32Anterior30R | BD2: 32ExistenciaWC | BE2: 50Actual15 | BF2: 50Actual30R | BG2: 50Anterior15 | BH2: 50Anterior30R | BI2: 50ExistenciaWC | BJ2: 54Actual15 | BK2: 54Actual30R | BL2: 54Anterior15 | BM2: 54Anterior30R | BN2: 54ExistenciaWC
A3: 65124 | B3: SKWINKLES SALSAGHETI SANDIA/12 | C3: 20 | D3: 162 | E3: EFFEM MEXICO INC. Y COMPAÑÍAS EN N.C DE CV | F3: 807 | G3: MATRE MEXICO S DE RL DE CV | H3: 80.936 | I3: 1618.72 | J3: =I3*K3 -> 97123.2 | K3: =SUM(O3+T3+W3) -> 60 | M3: 51.1 | N3: 41.05 | O3: 20 | P3: 73.95 | Q3: 65.1 | R3: =P3/30*8 -> 19.72 | S3: =Q3-R3 -> 45.38 | T3: 20 | U3: 33.6 | V3: 14.25 | W3: 20 | X3: 0 | Y3: 256809.93 | Z3: 194893.89 | AA3: 328 | AB3: 269 | AC3: 413 | AD3: 293 | AE3: 821 | AF3: 0 | AG3: 0 | AH3: 0 | AI3: 0 | AJ3: 0 | AK3: 0 | AL3: 0 | AM3: 0 | AN3: 0 | AO3: 0 | AP3: 0 | AQ3: 0 | AR3: 0 | AS3: 0 | AT3: 0 | AU3: 430 | AV3: 445 | AW3: 437 | AX3: 476 | AY3: 1252 | AZ3: 33 | BA3: 59 | BB3: 53 | BC3: 72 | BD3: 50 | BE3: 322 | BF3: 327 | BG3: 40 | BH3: 293 | BI3: 285 | BJ3: 0 | BK3: 0 | BL3: 0 | BM3: 0 | BN3: 0
A4: 6001 | B4: CHOC SNICKERS /6 | C4: 32 | D4: 162 | E4: EFFEM MEXICO INC. Y COMPAÑÍAS EN N.C DE CV | F4: 558 | G4: CHOCOLATES | H4: 84.1675 | I4: 2693.36 | J4: =I4*K4 -> 107734.4 | K4: =SUM(O4+T4+W4) -> 40 | M4: 17.02 | N4: 18.06 | O4: 10 | P4: 29.12 | Q4: 22.34 | R4: =P4/30*8 -> 7.7653333 | S4: =Q4-R4 -> 14.574667 | T4: 20 | U4: 15.92 | V4: 10.06 | W4: 10 | X4: 0 | Y4: 167156.66 | Z4: 135930.51 | AA4: 172 | AB4: 113 | AC4: 215 | AD4: 202 | AE4: 578 | AF4: 0 | AG4: 0 | AH4: 0 | AI4: 0 | AJ4: 0 | AK4: 0 | AL4: 0 | AM4: 0 | AN4: 0 | AO4: 0 | AP4: 0 | AQ4: 0 | AR4: 0 | AS4: 0 | AT4: 0 | AU4: 141 | AV4: 169 | AW4: 347 | AX4: 296 | AY4: 615 | AZ4: 60 | BA4: 40 | BB4: 84 | BC4: 95 | BD4: 100 | BE4: 152 | BF4: 172 | BG4: 148 | BH4: 247 | BI4: 322 | BJ4: 0 | BK4: 0 | BL4: 0 | BM4: 0 | BN4: 0
A5: 65133 | B5: PANZON LUCAS SANDIA CHAMOY /10 | C5: 24 | D5: 162 | E5: EFFEM MEXICO INC. Y COMPAÑÍAS EN N.C DE CV | F5: 807 | G5: MATRE MEXICO S DE RL DE CV | H5: 76.07 | I5: 1825.68 | J5: =I5*K5 -> 91284 | K5: =SUM(O5+T5+W5) -> 50 | M5: 28.56 | N5: 13.83 | O5: 20 | P5: 39.19 | Q5: 28.29 | R5: =P5/30*8 -> 10.450667 | S5: =Q5-R5 -> 17.839333 | T5: 20 | U5: 20.1 | V5: 15.29 | W5: 10 | X5: 0 | Y5: 160393.6 | Z5: 104824.46 | AA5: 215 | AB5: 175 | AC5: 268 | AD5: 230 | AE5: 332 | AF5: 0 | AG5: 0 | AH5: 0 | AI5: 0 | AJ5: 0 | AK5: 0 | AL5: 0 | AM5: 0 | AN5: 0 | AO5: 0 | AP5: 0 | AQ5: 0 | AR5: 0 | AS5: 0 | AT5: 0 | AU5: 275 | AV5: 175 | AW5: 317 | AX5: 318 | AY5: 606 | AZ5: 28 | BA5: 22 | BB5: 43 | BC5: 40 | BD5: 73 | BE5: 178 | BF5: 185 | BG5: 67 | BH5: 290 | BI5: 367 | BJ5: 0 | BK5: 0 | BL5: 0 | BM5: 0 | BN5: 0
A6: 88124 | B6: CH ORBIT 4 S MENTA / 40 | C6: 24 | D6: 162 | E6: EFFEM MEXICO INC. Y COMPAÑÍAS EN N.C DE CV | F6: 974 | G6: CHICLES | H6: 76.9276 | I6: 1846.2624 | J6: =I6*K6 -> 110775.74 | K6: =SUM(O6+T6+W6) -> 60 | M6: 44.69 | N6: 13.96 | O6: 30 | P6: 36.35 | Q6: 32.08 | R6: =P6/30*8 -> 9.6933333 | S6: =Q6-R6 -> 22.386667 | T6: 30 | U6: 5.79 | V6: 7.25 | W6: 0 | X6: 0 | Y6: 160317.12 | Z6: 98390.4 | AA6: 335 | AB6: 258 | AC6: 429 | AD6: 359 | AE6: 335 | AF6: 0 | AG6: 0 | AH6: 0 | AI6: 0 | AJ6: 0 | AK6: 0 | AL6: 0 | AM6: 0 | AN6: 0 | AO6: 0 | AP6: 0 | AQ6: 0 | AR6: 0 | AS6: 0 | AT6: 0 | AU6: 207 | AV6: 169 | AW6: 236 | AX6: 226 | AY6: 673 | AZ6: 66 | BA6: 59 | BB6: 85 | BC6: 103 | BD6: 97 | BE6: 40 | BF6: 30 | BG6: 43 | BH6: 82 | BI6: 174 | BJ6: 0 | BK6: 0 | BL6: 0 | BM6: 0 | BN6: 0
A7: 6002 | B7: CHOC MILKY WAY /6 | C7: 32 | D7: 162 | E7: EFFEM MEXICO INC. Y COMPAÑÍAS EN N.C DE CV | F7: 558 | G7: CHOCOLATES | H7: 84.1675 | I7: 2693.36 | J7: =I7*K7 -> 107734.4 | K7: =SUM(O7+T7+W7) -> 40 | M7: 12.56 | N7: 2.47 | O7: 10 | P7: 26 | Q7: 20.06 | R7: =P7/30*8 -> 6.9333333 | S7: =Q7-R7 -> 13.126667 | T7: 20 | U7: 7.88 | V7: 6.53 | W7: 10 | X7: 0 | Y7: 125072.9 | Z7: 78275.78 | AA7: 129 | AB7: 79 | AC7: 160 | AD7: 147 | AE7: 79 | AF7: 0 | AG7: 0 | AH7: 0 | AI7: 0 | AJ7: 0 | AK7: 0 | AL7: 0 | AM7: 0 | AN7: 0 | AO7: 0 | AP7: 0 | AQ7: 0 | AR7: 0 | AS7: 0 | AT7: 0 | AU7: 125 | AV7: 97 | AW7: 372 | AX7: 259 | AY7: 552 | AZ7: 56 | BA7: 28 | BB7: 57 | BC7: 60 | BD7: 90 | BE7: 107 | BF7: 121 | BG7: 78 | BH7: 13 | BI7: 209 | BJ7: 0 | BK7: 0 | BL7: 0 | BM7: 0 | BN7: 0
A8: 65109 | B8: GUSANO LUCAS CHAMOY EXH /10 | C8: 30 | D8: 162 | E8: EFFEM MEXICO INC. Y COMPAÑÍAS EN N.C DE CV | F8: 807 | G8: MATRE MEXICO S DE RL DE CV | H8: 65.2744 | I8: 1958.232 | J8: =I8*K8 -> 48955.8 | K8: =SUM(O8+T8+W8) -> 25 | M8: 16.15 | N8: 16.67 | O8: 0 | P8: 25.25 | Q8: 24.47 | R8: =P8/30*8 -> 6.7333333 | S8: =Q8-R8 -> 17.736667 | T8: 20 | U8: 18.3 | V8: 12.1 | W8: 5 | X8: 0 | Y8: 116906.45 | Z8: 104243.22 | AA8: 209 | AB8: 175 | AC8: 44 | AD8: 288 | AE8: 500 | AF8: 0 | AG8: 0 | AH8: 0 | AI8: 0 | AJ8: 0 | AK8: 0 | AL8: 0 | AM8: 0 | AN8: 0 | AO8: 0 | AP8: 0 | AQ8: 0 | AR8: 0 | AS8: 0 | AT8: 0 | AU8: 217 | AV8: 162 | AW8: 265 | AX8: 225 | AY8: 610 | AZ8: 14 | BA8: 33 | BB8: 34 | BC8: 35 | BD8: 124 | BE8: 179 | BF8: 155 | BG8: 207 | BH8: 171 | BI8: 363 | BJ8: 0 | BK8: 0 | BL8: 0 | BM8: 0 | BN8: 0
A9: 88102 | B9: CH ORBIT 4 S HIERBABUENA / 40 | C9: 24 | D9: 162 | E9: EFFEM MEXICO INC. Y COMPAÑÍAS EN N.C DE CV | F9: 974 | G9: CHICLES | H9: 76.9276 | I9: 1846.2624 | J9: =I9*K9 -> 46156.56 | K9: =SUM(O9+T9+W9) -> 25 | M9: 22.15 | N9: 18.71 | O9: 5 | P9: 27.6 | Q9: 22.12 | R9: =P9/30*8 -> 7.36 | S9: =Q9-R9 -> 14.76 | T9: 20 | U9: 4.48 | V9: 4.62 | W9: 0 | X9: 0 | Y9: 100121.27 | Z9: 83928.01 | AA9: 254 | AB9: 193 | AC9: 37 | AD9: 288 | AE9: 449 | AF9: 0 | AG9: 0 | AH9: 0 | AI9: 0 | AJ9: 0 | AK9: 0 | AL9: 0 | AM9: 0 | AN9: 0 | AO9: 0 | AP9: 0 | AQ9: 0 | AR9: 0 | AS9: 0 | AT9: 0 | AU9: 149 | AV9: 117 | AW9: 210 | AX9: 158 | AY9: 465 | AZ9: 34 | BA9: 35 | BB9: 79 | BC9: 71 | BD9: 66 | BE9: 35 | BF9: 26 | BG9: 35 | BH9: 49 | BI9: 111 | BJ9: 0 | BK9: 0 | BL9: 0 | BM9: 0 | BN9: 0
A10: 88135 | B10: CH ORBIT 4 S POLAR MINT 4 S / 40 | C10: 24 | D10: 162 | E10: EFFEM MEXICO INC. Y COMPAÑÍAS EN N.C DE CV | F10: 974 | G10: CHICLES | H10: 76.9276 | I10: 1846.2624 | J10: =I10*K10 -> 36925.248 | K10: =SUM(O10+T10+W10) -> 20 | M10: 18.25 | N10: 20.88 | O10: 0 | P10: 24.42 | Q10: 26 | R10: =P10/30*8 -> 6.512 | S10: =Q10-R10 -> 19.488 | T10: 20 | U10: 4.29 | V10: 7.04 | W10: 0 | X10: 0 | Y10: 86697.41 | Z10: 99544.31 | AA10: 141 | AB10: 101 | AC10: 150 | AD10: 193 | AE10: 501 | AF10: 0 | AG10: 0 | AH10: 0 | AI10: 0 | AJ10: 0 | AK10: 0 | AL10: 0 | AM10: 0 | AN10: 0 | AO10: 0 | AP10: 0 | AQ10: 0 | AR10: 0 | AS10: 0 | AT10: 0 | AU10: 153 | AV10: 108 | AW10: 147 | AX10: 141 | AY10: 516 | AZ10: 36 | BA10: 25 | BB10: 83 | BC10: 60 | BD10: 108 | BE10: 23 | BF10: 17 | BG10: 38 | BH10: 67 | BI10: 169 | BJ10: 0 | BK10: 0 | BL10: 0 | BM10: 0 | BN10: 0
A11: 65112 | B11: MUECAS LUCAS CHAMOY EXH /10 | C11: 24 | D11: 162 | E11: EFFEM MEXICO INC. Y COMPAÑÍAS EN N.C DE CV | F11: 807 | G11: MATRE MEXICO S DE RL DE CV | H11: 63.79 | I11: 1530.96 | J11: =I11*K11 -> 22964.4 | K11: =SUM(O11+T11+W11) -> 15 | M11: 14.48 | N11: 15.54 | O11: 0 | P11: 27.9 | Q11: 24.67 | R11: =P11/30*8 -> 7.44 | S11: =Q11-R11 -> 17.23 | T11: 15 | U11: 8.44 | V11: 7.42 | W11: 0 | X11: 0 | Y11: 77791.9 | Z11: 72911.97 | AA11: 106 | AB11: 71 | AC11: 121 | AD11: 170 | AE11: 373 | AF11: 0 | AG11: 0 | AH11: 0 | AI11: 0 | AJ11: 0 | AK11: 0 | AL11: 0 | AM11: 0 | AN11: 0 | AO11: 0 | AP11: 0 | AQ11: 0 | AR11: 0 | AS11: 0 | AT11: 0 | AU11: 283 | AV11: 121 | AW11: 129 | AX11: 233 | AY11: 519 | AZ11: 23 | BA11: 11 | BB11: 35 | BC11: 34 | BD11: 73 | BE11: 71 | BF11: 73 | BG11: 94 | BH11: 2 | BI11: 178 | BJ11: 0 | BK11: 0 | BL11: 0 | BM11: 0 | BN11: 0
A12: 88060 | B12: SKITTLES ORIGINAL /10 | C12: 24 | D12: 162 | E12: EFFEM MEXICO INC. Y COMPAÑÍAS EN N.C DE CV | F12: 807 | G12: MATRE MEXICO S DE RL DE CV | H12: 61.51 | I12: 1476.24 | J12: =I12*K12 -> 48715.92 | K12: =SUM(O12+T12+W12) -> 33 | M12: 12.52 | N12: -0.88 | O12: 20 | P12: 30.21 | Q12: 29.88 | R12: =P12/30*8 -> 8.056 | S12: =Q12-R12 -> 21.824 | T12: 10 | U12: 8.52 | V12: 6.08 | W12: 3 | X12: 0 | Y12: 75657.3 | Z12: 51791.42 | AA12: 107 | AB12: 95 | AC12: 80 | AD12: 132 | AE12: -21 | AF12: 0 | AG12: 0 | AH12: 0 | AI12: 0 | AJ12: 0 | AK12: 0 | AL12: 0 | AM12: 0 | AN12: 0 | AO12: 0 | AP12: 0 | AQ12: 0 | AR12: 0 | AS12: 0 | AT12: 0 | AU12: 116 | AV12: 118 | AW12: 326 | AX12: 231 | AY12: 622 | AZ12: 29 | BA12: 29 | BB12: 47 | BC12: 36 | BD12: 95 | BE12: 81 | BF12: 77 | BG12: 40 | BH12: 90 | BI12: 146 | BJ12: 0 | BK12: 0 | BL12: 0 | BM12: 0 | BN12: 0
A13: 88158 | B13: CH ORBIT 4 S FRESA / 40 | C13: 24 | D13: 162 | E13: EFFEM MEXICO INC. Y COMPAÑÍAS EN N.C DE CV | F13: 974 | G13: CHICLES | H13: 76.9276 | I13: 1846.2624 | J13: =I13*K13 -> 18462.624 | K13: =SUM(O13+T13+W13) -> 10 | M13: 14.15 | N13: 25.38 | O13: 0 | P13: 21.35 | Q13: 18.75 | R13: =P13/30*8 -> 5.6933333 | S13: =Q13-R13 -> 13.056667 | T13: 10 | U13: 3.73 | V13: 8.42 | W13: 0 | X13: 0 | Y13: 72427.34 | Z13: 97005.7 | AA13: 116 | AB13: 87 | AC13: 115 | AD13: 130 | AE13: 609 | AF13: 0 | AG13: 0 | AH13: 0 | AI13: 0 | AJ13: 0 | AK13: 0 | AL13: 0 | AM13: 0 | AN13: 0 | AO13: 0 | AP13: 0 | AQ13: 0 | AR13: 0 | AS13: 0 | AT13: 0 | AU13: 134 | AV13: 90 | AW13: 158 | AX13: 117 | AY13: 359 | AZ13: 34 | BA13: 26 | BB13: 46 | BC13: 48 | BD13: 91 | BE13: 34 | BF13: 13 | BG13: 26 | BH13: 46 | BI13: 202 | BJ13: 0 | BK13: 0 | BL13: 0 | BM13: 0 | BN13: 0
A14: 65117 | B14: MUECAS LUCAS CEREZA EXH /10 | C14: 24 | D14: 162 | E14: EFFEM MEXICO INC. Y COMPAÑÍAS EN N.C DE CV | F14: 807 | G14: MATRE MEXICO S DE RL DE CV | H14: 63.79 | I14: 1530.96 | J14: =I14*K14 -> 45928.8 | K14: =SUM(O14+T14+W14) -> 30 | M14: 11.73 | N14: -3.04 | O14: 20 | P14: 16.44 | Q14: 21.25 | R14: =P14/30*8 -> 4.384 | S14: =Q14-R14 -> 16.866 | T14: 0 | U14: 10.21 | V14: 2 | W14: 10 | X14: 0 | Y14: 58750.59 | Z14: 30938.15 | AA14: 72 | AB14: 67 | AC14: 145 | AD14: 62 | AE14: -73 | AF14: 0 | AG14: 0 | AH14: 0 | AI14: 0 | AJ14: 0 | AK14: 0 | AL14: 0 | AM14: 0 | AN14: 0 | AO14: 0 | AP14: 0 | AQ14: 0 | AR14: 0 | AS14: 0 | AT14: 0 | AU14: 77 | AV14: 91 | AW14: 144 | AX14: 147 | AY14: 497 | AZ14: 16 | BA14: 25 | BB14: 18 | BC14: 16 | BD14: 13 | BE14: 71 | BF14: 0 | BG14: 112 | BH14: 124 | BI14: 48 | BJ14: 0 | BK14: 0 | BL14: 0 | BM14: 0 | BN14: 0
... A38: 65103 | B38: BOMVASO LUCAS LIMON /10 LUCAS | C38: 24 | D38: 162 | E38: EFFEM MEXICO INC. Y COMPAÑÍAS EN N.C DE CV | F38: 807 | G38: MATRE MEXICO S DE RL DE CV | H38: 61.1678 | I38: 1468.0272 | J38: =I38*K38 -> 13212.245 | K38: =SUM(O38+T38+W38) -> 9 | M38: 1.12 | N38: 0 | O38: 2 | P38: 5.23 | Q38: 0 | R38: =P38/30*8 -> 1.3946667 | S38: =Q38-R38 -> -1.3946667 | T38: 5 | U38: 2.25 | V38: 0 | W38: 2 | X38: 0 | Y38: 12631.15 | Z38: 0 | AA38: 0 | AB38: 0 | AC38: 13 | AD38: 28 | AE38: 0 | AF38: 0 | AG38: 0 | AH38: 0 | AI38: 0 | AJ38: 0 | AK38: 0 | AL38: 0 | AM38: 0 | AN38: 0 | AO38: 0 | AP38: 0 | AQ38: 0 | AR38: 0 | AS38: 0 | AT38: 0 | AU38: 0 | AV38: 0 | AW38: 81 | AX38: 65 | AY38: 0 | AZ38: 0 | BA38: 0 | BB38: 6 | BC38: 12 | BD38: 0 | BE38: 0 | BF38: 0 | BG38: 41 | BH38: 26 | BI38: 0 | BJ38: 0 | BK38: 0 | BL38: 0 | BM38: 0 | BN38: 0
A39: 6093 | B39: CHOC SNICKERS ALMOND 260G / 6 | C39: 12 | D39: 162 | E39: EFFEM MEXICO INC. Y COMPAÑÍAS EN N.C DE CV | F39: 558 | G39: CHOCOLATES | H39: 84.1675 | I39: 1010.01 | J39: =I39*K39 -> 5050.05 | K39: =SUM(O39+T39+W39) -> 5 | M39: 3.83 | N39: -1.17 | O39: =M39-N39 -> 5 | P39: 8.21 | Q39: 8.58 | R39: =P39/30*8 -> 2.1893333 | S39: =Q39-R39 -> 6.3906667 | T39: 0 | U39: 0 | V39: 0 | W39: =U39-V39 -> 0 | X39: 0 | Y39: 12162.2 | Z39: 7490.91 | AA39: 7 | AB39: 5 | AC39: 24 | AD39: 25 | AE39: -14 | AF39: 0 | AG39: 0 | AH39: 0 | AI39: 0 | AJ39: 0 | AK39: 0 | AL39: 0 | AM39: 0 | AN39: 0 | AO39: 0 | AP39: 0 | AQ39: 0 | AR39: 0 | AS39: 0 | AT39: 0 | AU39: 19 | AV39: 16 | AW39: 39 | AX39: 54 | AY39: 103 | AZ39: 0 | BA39: 0 | BB39: 0 | BC39: 11 | BD39: 0 | BE39: 0 | BF39: 0 | BG39: 0 | BH39: 0 | BI39: 0 | BJ39: 0 | BK39: 0 | BL39: 0 | BM39: 0 | BN39: 0
A40: 65045 | B40: CHOC CONEJO MINI (120 GR) / 12 TURIN | C40: 18 | D40: 162 | E40: EFFEM MEXICO INC. Y COMPAÑÍAS EN N.C DE CV | F40: 123 | G40: CHOCOLATES TURIN S.A. DE C.V. | H40: 60.8763 | I40: 1095.7734 | J40: =I40*K40 -> 3287.3202 | K40: =SUM(O40+T40+W40) -> 3 | M40: 3.03 | N40: 0 | O40: 3 | P40: 6.67 | Q40: 8.5 | R40: =P40/30*8 -> 1.7786667 | S40: =Q40-R40 -> 6.7213333 | T40: 0 | U40: 0.94 | V40: 0 | W40: 0 | X40: 0 | Y40: 11657.81 | Z40: 9314.07 | AA40: 0 | AB40: 0 | AC40: 28 | AD40: 53 | AE40: 0 | AF40: 0 | AG40: 0 | AH40: 0 | AI40: 0 | AJ40: 0 | AK40: 0 | AL40: 0 | AM40: 0 | AN40: 0 | AO40: 0 | AP40: 0 | AQ40: 0 | AR40: 0 | AS40: 0 | AT40: 0 | AU40: 8 | AV40: 21 | AW40: 68 | AX40: 49 | AY40: 126 | AZ40: 0 | BA40: 2 | BB40: 4 | BC40: 8 | BD40: 27 | BE40: 3 | BF40: 7 | BG40: 7 | BH40: 7 | BI40: 0 | BJ40: 0 | BK40: 0 | BL40: 0 | BM40: 0 | BN40: 0
A41: 91046 | B41: CHOC JOSE CUERVO TUBO 180GR 2786 | C41: 6 | D41: 162 | E41: EFFEM MEXICO INC. Y COMPAÑÍAS EN N.C DE CV | F41: 123 | G41: CHOCOLATES TURIN S.A. DE C.V. | H41: 119.37 | I41: 716.22 | J41: =I41*K41 -> 2148.66 | K41: =SUM(O41+T41+W41) -> 3 | M41: 2.92 | N41: -2 | O41: 3 | P41: 12.5 | Q41: 10.83 | R41: =P41/30*8 -> 3.3333333 | S41: =Q41-R41 -> 7.4966667 | T41: 0 | U41: 0.5 | V41: 1.33 | W41: 0 | X41: 0 | Y41: 11399.84 | Z41: 7281.57 | AA41: 0 | AB41: 0 | AC41: 15 | AD41: 5 | AE41: -12 | AF41: 0 | AG41: 0 | AH41: 0 | AI41: 0 | AJ41: 0 | AK41: 0 | AL41: 0 | AM41: 0 | AN41: 0 | AO41: 0 | AP41: 0 | AQ41: 0 | AR41: 0 | AS41: 0 | AT41: 0 | AU41: 21 | AV41: 4 | AW41: 42 | AX41: 0 | AY41: 65 | AZ41: 1 | BA41: 3 | BB41: 2 | BC41: 11 | BD41: 0 | BE41: 1 | BF41: 1 | BG41: 1 | BH41: 1 | BI41: 8 | BJ41: 0 | BK41: 0 | BL41: 0 | BM41: 0 | BN41: 0
A42: 6022 | B42: CH HUBBA BUBBA TRIPLE TREAT | C42: 24 | D42: 162 | E42: EFFEM MEXICO INC. Y COMPAÑÍAS EN N.C DE CV | F42: 974 | G42: CHICLES | H42: 107.6336 | I42: 2583.2064 | J42: =I42*K42 -> 10332.826 | K42: =SUM(O42+T42+W42) -> 4 | M42: 0.54 | N42: 0 | O42: 1 | P42: 3.83 | Q42: 0.42 | R42: =P42/30*8 -> 1.0213333 | S42: =Q42-R42 -> -0.60133333 | T42: 3 | U42: 0 | V42: 0 | W42: =U42-V42 -> 0 | X42: 0 | Y42: 11301.53 | Z42: 1076.34 | AA42: 0 | AB42: 0 | AC42: 11 | AD42: 4 | AE42: 0 | AF42: 0 | AG42: 0 | AH42: 0 | AI42: 0 | AJ42: 0 | AK42: 0 | AL42: 0 | AM42: 0 | AN42: 0 | AO42: 0 | AP42: 0 | AQ42: 0 | AR42: 0 | AS42: 0 | AT42: 0 | AU42: 37 | AV42: 28 | AW42: 27 | AX42: 13 | AY42: 4 | AZ42: 2 | BA42: 7 | BB42: 1 | BC42: 2 | BD42: 6 | BE42: 0 | BF42: 0 | BG42: 0 | BH42: 0 | BI42: 0 | BJ42: 0 | BK42: 0 | BL42: 0 | BM42: 0 | BN42: 0
A43: 91013 | B43: CHOC BAILEYS BLS 120GR TURIN 3055 | C43: 12 | D43: 162 | E43: EFFEM MEXICO INC. Y COMPAÑÍAS EN N.C DE CV | F43: 123 | G43: CHOCOLATES TURIN S.A. DE C.V. | H43: 101.8831 | I43: 1222.5972 | J43: =I43*K43 -> 3667.7916 | K43: =SUM(O43+T43+W43) -> 3 | M43: 3.08 | N43: -0.25 | O43: 3 | P43: 5.67 | Q43: 7 | R43: =P43/30*8 -> 1.512 | S43: =Q43-R43 -> 5.488 | T43: 0 | U43: 0.25 | V43: 2 | W43: 0 | X43: 0 | Y43: 11003.37 | Z43: 10697.73 | AA43: 3 | AB43: 0 | AC43: 27 | AD43: 14 | AE43: -3 | AF43: 0 | AG43: 0 | AH43: 0 | AI43: 0 | AJ43: 0 | AK43: 0 | AL43: 0 | AM43: 0 | AN43: 0 | AO43: 0 | AP43: 0 | AQ43: 0 | AR43: 0 | AS43: 0 | AT43: 0 | AU43: 16 | AV43: 19 | AW43: 26 | AX43: 16 | AY43: 65 | AZ43: 1 | BA43: 0 | BB43: 6 | BC43: 3 | BD43: 19 | BE43: 0 | BF43: 1 | BG43: 0 | BH43: 5 | BI43: 24 | BJ43: 0 | BK43: 0 | BL43: 0 | BM43: 0 | BN43: 0
A44: 91067 | B44: CHOC TEQUILA TUBO 1800 180GR | C44: 6 | D44: 162 | E44: EFFEM MEXICO INC. Y COMPAÑÍAS EN N.C DE CV | F44: 123 | G44: CHOCOLATES TURIN S.A. DE C.V. | H44: 119.3709 | I44: 716.2254 | J44: =I44*K44 -> 10027.156 | K44: =SUM(O44+T44+W44) -> 14 | M44: 2.17 | N44: -2 | O44: 2 | P44: 11.33 | Q44: 2.83 | R44: =P44/30*8 -> 3.0213333 | S44: =Q44-R44 -> -0.19133333 | T44: 10 | U44: 1.83 | V44: 0.17 | W44: 2 | X44: 0 | Y44: 10982.12 | Z44: 716.23 | AA44: 0 | AB44: 0 | AC44: 3 | AD44: 20 | AE44: -12 | AF44: 0 | AG44: 0 | AH44: 0 | AI44: 0 | AJ44: 0 | AK44: 0 | AL44: 0 | AM44: 0 | AN44: 0 | AO44: 0 | AP44: 0 | AQ44: 0 | AR44: 0 | AS44: 0 | AT44: 0 | AU44: 34 | AV44: 7 | AW44: 17 | AX44: 16 | AY44: 7 | AZ44: 1 | BA44: 1 | BB44: 3 | BC44: 2 | BD44: 10 | BE44: 2 | BF44: 3 | BG44: 7 | BH44: 1 | BI44: 1 | BJ44: 0 | BK44: 0 | BL44: 0 | BM44: 0 | BN44: 0
A45: 91047 | B45: CHOC CARAJILLO TUBO 180GR TURIN | C45: 6 | D45: 162 | E45: EFFEM MEXICO INC. Y COMPAÑÍAS EN N.C DE CV | F45: 123 | G45: CHOCOLATES TURIN S.A. DE C.V. | H45: 119.37 | I45: 716.22 | J45: =I45*K45 -> 3581.1 | K45: =SUM(O45+T45+W45) -> 5 | M45: 3.92 | N45: -0.67 | O45: 5 | P45: 10.42 | Q45: 10.17 | R45: =P45/30*8 -> 2.7786667 | S45: =Q45-R45 -> 7.3913333 | T45: 0 | U45: 0.42 | V45: 1.33 | W45: 0 | X45: 0 | Y45: 10564.24 | Z45: 7759.05 | AA45: 0 | AB45: 0 | AC45: 15 | AD45: 17 | AE45: -4 | AF45: 0 | AG45: 0 | AH45: 0 | AI45: 0 | AJ45: 0 | AK45: 0 | AL45: 0 | AM45: 0 | AN45: 0 | AO45: 0 | AP45: 0 | AQ45: 0 | AR45: 0 | AS45: 0 | AT45: 0 | AU45: 16 | AV45: 2 | AW45: 37 | AX45: 10 | AY45: 54 | AZ45: 0 | BA45: 0 | BB45: 3 | BC45: 1 | BD45: 7 | BE45: 1 | BF45: 0 | BG45: 1 | BH45: 1 | BI45: 8 | BJ45: 0 | BK45: 0 | BL45: 0 | BM45: 0 | BN45: 0
A46: 6036 | B46: M&M MINIS TUBO 180GR/6 | C46: 24 | D46: 162 | E46: EFFEM MEXICO INC. Y COMPAÑÍAS EN N.C DE CV | F46: 558 | G46: CHOCOLATES | H46: 103.33 | I46: 2479.92 | J46: =I46*K46 -> 0 | K46: =SUM(O46+T46+W46) -> 0 | M46: 1.4 | N46: 1 | O46: 0 | P46: 2.5 | Q46: 4 | R46: =P46/30*8 -> 0.66666667 | S46: =Q46-R46 -> 3.3333333 | T46: 0 | U46: 0.04 | V46: 0 | W46: 0 | X46: 0 | Y46: 9764.68 | Z46: 12399.6 | AA46: 12 | AB46: 0 | AC46: 7 | AD46: 29 | AE46: 24 | AF46: 0 | AG46: 0 | AH46: 0 | AI46: 0 | AJ46: 0 | AK46: 0 | AL46: 0 | AM46: 0 | AN46: 0 | AO46: 0 | AP46: 0 | AQ46: 0 | AR46: 0 | AS46: 0 | AT46: 0 | AU46: 1 | AV46: 3 | AW46: 16 | AX46: 67 | AY46: 71 | AZ46: 3 | BA46: 0 | BB46: 3 | BC46: 4 | BD46: 25 | BE46: 1 | BF46: 0 | BG46: 0 | BH46: 0 | BI46: 0 | BJ46: 0 | BK46: 0 | BL46: 0 | BM46: 0 | BN46: 0
A47: 97315 | B47: CORAZON M&M & SKITTLES 100GR / MARS | C47: 14 | D47: 162 | E47: EFFEM MEXICO INC. Y COMPAÑÍAS EN N.C DE CV | F47: 162 | G47: EFFEM MEXICO INC. Y COMPAÑÍA S EN N.C DE CV | H47: 56.568 | I47: 791.952 | J47: =I47*K47 -> 0 | K47: =SUM(O47+T47+W47) -> 0 | M47: 2.39 | N47: 1.07 | O47: 0 | P47: 4.71 | Q47: 0.07 | R47: =P47/30*8 -> 1.256 | S47: =Q47-R47 -> -1.186 | T47: 0 | U47: 5.11 | V47: -0.07 | W47: 0 | X47: 0 | Y47: 9673.13 | Z47: 848.52 | AA47: 26 | AB47: 15 | AC47: 0 | AD47: 0 | AE47: 15 | AF47: 0 | AG47: 0 | AH47: 0 | AI47: 0 | AJ47: 0 | AK47: 0 | AL47: 0 | AM47: 0 | AN47: 0 | AO47: 0 | AP47: 0 | AQ47: 0 | AR47: 0 | AS47: 0 | AT47: 0 | AU47: 21 | AV47: 90 | AW47: 0 | AX47: 0 | AY47: 1 | AZ47: 0 | BA47: 0 | BB47: 0 | BC47: 0 | BD47: 0 | BE47: 58 | BF47: 27 | BG47: 0 | BH47: 0 | BI47: -1 | BJ47: 0 | BK47: 0 | BL47: 0 | BM47: 0 | BN47: 0
A48: 97319 | B48: REGALITO M&M & SKITTLES 39GR / MARS | C48: 15 | D48: 162 | E48: EFFEM MEXICO INC. Y COMPAÑÍAS EN N.C DE CV | F48: 162 | G48: EFFEM MEXICO INC. Y COMPAÑÍA S EN N.C DE CV | H48: 24.6343 | I48: 369.5145 | J48: =I48*K48 -> 0 | K48: =SUM(O48+T48+W48) -> 0 | M48: 6.83 | N48: 0.13 | O48: 0 | P48: 9.4 | Q48: -0.53 | R48: =P48/30*8 -> 2.5066667 | S48: =Q48-R48 -> -3.0366667 | T48: 0 | U48: 8.03 | V48: 0.87 | W48: 0 | X48: 0 | Y48: 8966.89 | Z48: 172.44 | AA48: 87 | AB48: 31 | AC48: 0 | AD48: 0 | AE48: 2 | AF48: 0 | AG48: 0 | AH48: 0 | AI48: 0 | AJ48: 0 | AK48: 0 | AL48: 0 | AM48: 0 | AN48: 0 | AO48: 0 | AP48: 0 | AQ48: 0 | AR48: 0 | AS48: 0 | AT48: 0 | AU48: 55 | AV48: 164 | AW48: 0 | AX48: 0 | AY48: -9 | AZ48: 0 | BA48: 8 | BB48: 0 | BC48: 0 | BD48: 1 | BE48: 98 | BF48: 45 | BG48: 0 | BH48: 0 | BI48: 13 | BJ48: 0 | BK48: 0 | BL48: 0 | BM48: 0 | BN48: 0
A49: 6170 | B49: CHOC TUBO JOHNIE WALKER 180GR / 1 TURIN | C49: 6 | D49: 162 | E49: EFFEM MEXICO INC. Y COMPAÑÍAS EN N.C DE CV | F49: 123 | G49: CHOCOLATES TURIN S.A. DE C.V. | H49: 119.3709 | I49: 716.2254 | J49: =I49*K49 -> 1432.4508 | K49: =SUM(O49+T49+W49) -> 2 | M49: 4.83 | N49: 0 | O49: 2 | P49: 7.17 | Q49: 7.67 | R49: =P49/30*8 -> 1.912 | S49: =Q49-R49 -> 5.758 | T49: 0 | U49: 0.17 | V49: 0.33 | W49: 0 | X49: 0 | Y49: 8714.08 | Z49: 5729.8 | AA49: 1 | AB49: 3 | AC49: 18 | AD49: 17 | AE49: 0 | AF49: 0 | AG49: 0 | AH49: 0 | AI49: 0 | AJ49: 0 | AK49: 0 | AL49: 0 | AM49: 0 | AN49: 0 | AO49: 0 | AP49: 0 | AQ49: 0 | AR49: 0 | AS49: 0 | AT49: 0 | AU49: 10 | AV49: 6 | AW49: 24 | AX49: 7 | AY49: 38 | AZ49: 0 | BA49: 1 | BB49: 1 | BC49: 2 | BD49: 8 | BE49: 0 | BF49: 1 | BG49: 0 | BH49: 1 | BI49: 2 | BJ49: 0 | BK49: 0 | BL49: 0 | BM49: 0 | BN49: 0
A50: 65153 | B50: EXH SKWINKLES CHUNKS SANDIA 270GR/ 6 | C50: 20 | D50: 162 | E50: EFFEM MEXICO INC. Y COMPAÑÍAS EN N.C DE CV | F50: 807 | G50: MATRE MEXICO S DE RL DE CV | H50: 73.9487 | I50: 1478.974 | J50: =I50*K50 -> 0 | K50: =SUM(O50+T50+W50) -> 0 | M50: 1.05 | N50: 3.7 | O50: 0 | P50: 4.58 | Q50: 5 | R50: =P50/30*8 -> 1.2213333 | S50: =Q50-R50 -> 3.7786667 | T50: 0 | U50: 0 | V50: 0 | W50: =U50-V50 -> 0 | X50: 0 | Y50: 8319.23 | Z50: 12867.07 | AA50: 6 | AB50: 6 | AC50: 4 | AD50: 16 | AE50: 74 | AF50: 0 | AG50: 0 | AH50: 0 | AI50: 0 | AJ50: 0 | AK50: 0 | AL50: 0 | AM50: 0 | AN50: 0 | AO50: 0 | AP50: 0 | AQ50: 0 | AR50: 0 | AS50: 0 | AT50: 0 | AU50: 0 | AV50: 0 | AW50: 55 | AX50: 48 | AY50: 100 | AZ50: 0 | BA50: 6 | BB50: 6 | BC50: 7 | BD50: 0 | BE50: 0 | BF50: 0 | BG50: 0 | BH50: 0 | BI50: 0 | BJ50: 0 | BK50: 0 | BL50: 0 | BM50: 0 | BN50: 0
A51: 6045 | B51: LUCAS GOMITAS SANDIA 240GR/ 6 MARS | C51: 12 | D51: 162 | E51: EFFEM MEXICO INC. Y COMPAÑÍAS EN N.C DE CV | F51: 807 | G51: MATRE MEXICO S DE RL DE CV | H51: 73.9791 | I51: 887.7492 | J51: =I51*K51 -> 0 | K51: =SUM(O51+T51+W51) -> 0 | M51: 2.12 | N51: 2.42 | O51: 0 | P51: 6.96 | Q51: 6.33 | R51: =P51/30*8 -> 1.856 | S51: =Q51-R51 -> 4.474 | T51: 0 | U51: 0 | V51: 0 | W51: =U51-V51 -> 0 | X51: 0 | Y51: 8063.72 | Z51: 7767.81 | AA51: 5 | AB51: 2 | AC51: 17 | AD51: 5 | AE51: 29 | AF51: 0 | AG51: 0 | AH51: 0 | AI51: 0 | AJ51: 0 | AK51: 0 | AL51: 0 | AM51: 0 | AN51: 0 | AO51: 0 | AP51: 0 | AQ51: 0 | AR51: 0 | AS51: 0 | AT51: 0 | AU51: 14 | AV51: 16 | AW51: 46 | AX51: 24 | AY51: 75 | AZ51: 1 | BA51: 2 | BB51: 1 | BC51: 1 | BD51: 1 | BE51: 0 | BF51: 0 | BG51: 0 | BH51: 0 | BI51: 0 | BJ51: 0 | BK51: 0 | BL51: 0 | BM51: 0 | BN51: 0
A52: 6012 | B52: CHOC MILKY WAY SNACK 242 GR / 11 | C52: 18 | D52: 162 | E52: EFFEM MEXICO INC. Y COMPAÑÍAS EN N.C DE CV | F52: 558 | G52: CHOCOLATES | H52: 96.61 | I52: 1738.98 | J52: =I52*K52 -> 3477.96 | K52: =SUM(O52+T52+W52) -> 2 | M52: 0.89 | N52: -0.33 | O52: 2 | P52: 3.28 | Q52: 5.06 | R52: =P52/30*8 -> 0.87466667 | S52: =Q52-R52 -> 4.1853333 | T52: 0 | U52: 0.33 | V52: 0 | W52: 0 | X52: 0 | Y52: 7825.41 | Z52: 8211.85 | AA52: 6 | AB52: 0 | AC52: 10 | AD52: 0 | AE52: -6 | AF52: 0 | AG52: 0 | AH52: 0 | AI52: 0 | AJ52: 0 | AK52: 0 | AL52: 0 | AM52: 0 | AN52: 0 | AO52: 0 | AP52: 0 | AQ52: 0 | AR52: 0 | AS52: 0 | AT52: 0 | AU52: 31 | AV52: 32 | AW52: 0 | AX52: 0 | AY52: 45 | AZ52: 2 | BA52: 6 | BB52: 7 | BC52: 0 | BD52: 46 | BE52: 3 | BF52: 6 | BG52: 0 | BH52: 0 | BI52: 0 | BJ52: 0 | BK52: 0 | BL52: 0 | BM52: 0 | BN52: 0
A53: 91045 | B53: CHOC CEREZA TUBO 180GR TURIN | C53: 6 | D53: 162 | E53: EFFEM MEXICO INC. Y COMPAÑÍAS EN N.C DE CV | F53: 123 | G53: CHOCOLATES TURIN S.A. DE C.V. | H53: 119.37 | I53: 716.22 | J53: =I53*K53 -> 5729.76 | K53: =SUM(O53+T53+W53) -> 8 | M53: 4.08 | N53: -1.17 | O53: 3 | P53: 5.67 | Q53: 0.5 | R53: =P53/30*8 -> 1.512 | S53: =Q53-R53 -> -1.012 | T53: 5 | U53: 0.58 | V53: 0 | W53: 0 | X53: 0 | Y53: 7400.94 | Z53: -477.48 | AA53: 1 | AB53: 0 | AC53: 19 | AD53: 9 | AE53: -7 | AF53: 0 | AG53: 0 | AH53: 0 | AI53: 0 | AJ53: 0 | AK53: 0 | AL53: 0 | AM53: 0 | AN53: 0 | AO53: 0 | AP53: 0 | AQ53: 0 | AR53: 0 | AS53: 0 | AT53: 0 | AU53: 24 | AV53: 6 | AW53: 0 | AX53: 0 | AY53: 0 | AZ53: 4 | BA53: 2 | BB53: 2 | BC53: 0 | BD53: 3 | BE53: 0 | BF53: 0 | BG53: 2 | BH53: 3 | BI53: 0 | BJ53: 0 | BK53: 0 | BL53: 0 | BM53: 0 | BN53: 0
A54: 6171 | B54: CHOC BAILEYS AVELL TUBO 180GR / 1 TURIN | C54: 6 | D54: 162 | E54: EFFEM MEXICO INC. Y COMPAÑÍAS EN N.C DE CV | F54: 123 | G54: CHOCOLATES TURIN S.A. DE C.V. | H54: 119.37 | I54: 716.22 | J54: =I54*K54 -> 2148.66 | K54: =SUM(O54+T54+W54) -> 3 | M54: 1.58 | N54: -1 | O54: 2 | P54: 7.42 | Q54: 6.5 | R54: =P54/30*8 -> 1.9786667 | S54: =Q54-R54 -> 4.5213333 | T54: 0 | U54: 1.25 | V54: 0 | W54: 1 | X54: 0 | Y54: 7341.26 | Z54: 3939.21 | AA54: 0 | AB54: 0 | AC54: 1 | AD54: 17 | AE54: -6 | AF54: 0 | AG54: 0 | AH54: 0 | AI54: 0 | AJ54: 0 | AK54: 0 | AL54: 0 | AM54: 0 | AN54: 0 | AO54: 0 | AP54: 0 | AQ54: 0 | AR54: 0 | AS54: 0 | AT54: 0 | AU54: 2 | AV54: 3 | AW54: 25 | AX54: 27 | AY54: 31 | AZ54: 0 | BA54: 3 | BB54: 1 | BC54: 0 | BD54: 8 | BE54: 6 | BF54: 0 | BG54: 0 | BH54: 3 | BI54: 0 | BJ54: 0 | BK54: 0 | BL54: 0 | BM54: 0 | BN54: 0
A55: 91118 | B55: CHOC BAILEYS 80GR BLS TURIN | C55: 12 | D55: 162 | E55: EFFEM MEXICO INC. Y COMPAÑÍAS EN N.C DE CV | F55: 123 | G55: CHOCOLATES TURIN S.A. DE C.V. | H55: 59.0009 | I55: 708.0108 | J55: =I55*K55 -> 1416.0216 | K55: =SUM(O55+T55+W55) -> 2 | M55: 5.75 | N55: 3.83 | O55: 2 | P55: 4.58 | Q55: 4.83 | R55: =P55/30*8 -> 1.2213333 | S55: =Q55-R55 -> 3.6086667 | T55: 0 | U55: 0 | V55: 0 | W55: =U55-V55 -> 0 | X55: 0 | Y55: 7316.11 | Z55: 6136.09 | AA55: 2 | AB55: 0 | AC55: 50 | AD55: 34 | AE55: 46 | AF55: 0 | AG55: 0 | AH55: 0 | AI55: 0 | AJ55: 0 | AK55: 0 | AL55: 0 | AM55: 0 | AN55: 0 | AO55: 0 | AP55: 0 | AQ55: 0 | AR55: 0 | AS55: 0 | AT55: 0 | AU55: 1 | AV55: 0 | AW55: 38 | AX55: 22 | AY55: 59 | AZ55: 1 | BA55: 8 | BB55: 0 | BC55: 0 | BD55: -1 | BE55: 0 | BF55: 0 | BG55: 0 | BH55: 0 | BI55: 0 | BJ55: 0 | BK55: 0 | BL55: 0 | BM55: 0 | BN55: 0
A56: 6077 | B56: CHOC CONEJO 200gr/ 10 TURIN | C56: 12 | D56: 162 | E56: EFFEM MEXICO INC. Y COMPAÑÍAS EN N.C DE CV | F56: 123 | G56: CHOCOLATES TURIN S.A. DE C.V. | H56: 99.3739 | I56: 1192.4868 | J56: =I56*K56 -> 5962.434 | K56: =SUM(O56+T56+W56) -> 5 | M56: 1.67 | N56: 1.42 | O56: 0 | P56: 4 | Q56: 0.17 | R56: =P56/30*8 -> 1.0666667 | S56: =Q56-R56 -> -0.89666667 | T56: 5 | U56: 0.38 | V56: 0 | W56: 0 | X56: 0 | Y56: 7204.61 | Z56: 1888.1 | AA56: 10 | AB56: 12 | AC56: 3 | AD56: 2 | AE56: 17 | AF56: 0 | AG56: 0 | AH56: 0 | AI56: 0 | AJ56: 0 | AK56: 0 | AL56: 0 | AM56: 0 | AN56: 0 | AO56: 0 | AP56: 0 | AQ56: 0 | AR56: 0 | AS56: 0 | AT56: 0 | AU56: 16 | AV56: 16 | AW56: 3 | AX56: 34 | AY56: -5 | AZ56: 3 | BA56: 2 | BB56: 0 | BC56: 0 | BD56: 7 | BE56: 0 | BF56: 0 | BG56: 3 | BH56: 3 | BI56: 0 | BJ56: 0 | BK56: 0 | BL56: 0 | BM56: 0 | BN56: 0
A57: 6087 | B57: VIT CHOC CONEJO 600GR/30 TURIN | C57: 4 | D57: 162 | E57: EFFEM MEXICO INC. Y COMPAÑÍAS EN N.C DE CV | F57: 123 | G57: CHOCOLATES TURIN S.A. DE C.V. | H57: 255.4675 | I57: 1021.87 | J57: =I57*K57 -> 0 | K57: =SUM(O57+T57+W57) -> 0 | M57: 2.25 | N57: 1.5 | O57: 0 | P57: 2 | Q57: 8 | R57: =P57/30*8 -> 0.53333333 | S57: =Q57-R57 -> 7.4666667 | T57: 0 | U57: 2 | V57: 0 | W57: 0 | X57: 0 | Y57: 6386.69 | Z57: 9707.76 | AA57: 1 | AB57: 1 | AC57: 5 | AD57: 5 | AE57: 6 | AF57: 0 | AG57: 0 | AH57: 0 | AI57: 0 | AJ57: 0 | AK57: 0 | AL57: 0 | AM57: 0 | AN57: 0 | AO57: 0 | AP57: 0 | AQ57: 0 | AR57: 0 | AS57: 0 | AT57: 0 | AU57: 0 | AV57: 1 | AW57: 3 | AX57: 0 | AY57: 20 | AZ57: 0 | BA57: 1 | BB57: 4 | BC57: 0 | BD57: 12 | BE57: 6 | BF57: 1 | BG57: 0 | BH57: 3 | BI57: 0 | BJ57: 0 | BK57: 0 | BL57: 0 | BM57: 0 | BN57: 0
