Workbook

Sheet 230126
K1: =SUM(K18:K55) -> 639228.9 | L1: =SUM(L18:L55) -> 670 | M1: =SUM(M18:M55) -> 356.15 | N1: =SUM(N18:N55) -> 369.63 | P1: =SUM(P18:P55) -> 0 | Q1: =SUM(Q18:Q55) -> 502.08 | R1: =SUM(R18:R55) -> 484.43 | S1: =SUM(S18:S55) -> 315 | X1: =Z1/Y1 -> 0.83409698 | Y1: =SUM(Y3:Y91) -> 998643.08 | Z1: =SUM(Z3:Z91) -> 832965.18
A2: Articulo | B2: Nombre | C2: PROMO | D2: UXC | E2: Subfamilia | F2: SN | G2: Categoria | H2: CN | I2: CostoCIVA | J2: CostoXCaja | K2: $Pedido | L2: SumaPedido | M2: 10VentasG | N2: 10ExistenciaG | O2: PedidoLPD | Q2: 30VentasG | R2: 30ExistenciasG | S2: PedMorelia | U2: 50VentasG | V2: 50ExistenciaG | W2: PedidoZam | X2: ExCEDIS | Y2: ValorVentaG | Z2: ValorExistenciaG | AA2: 10Actual15 | AB2: 10Actual30R | AC2: 10Anterior15 | AD2: 10Anterior30R | AE2: 10ExistenciaWC | AF2: 40Actual15 | AG2: 40Actual30R | AH2: 40Anterior15 | AI2: 40Anterior30R | AJ2: 40ExistenciaWC | AK2: 42Actual15 | AL2: 42Actual30R | AM2: 42Anterior15 | AN2: 42Anterior30R | AO2: 42ExistenciaWC | AP2: 44Actual15 | AQ2: 44Actual30R | AR2: 44Anterior15 | AS2: 44Anterior30R | AT2: 44ExistenciaWC | AU2: 30Actual15 | AV2: 30Actual30R | AW2: 30Anterior15 | AX2: 30Anterior30R | AY2: 30ExistenciaWC | AZ2: 32Actual15 | BA2: 32Actual30R | BB2: 32Anterior15 | BC2: 32Anterior30R | BD2: 32ExistenciaWC | BE2: 50Actual15 | BF2: 50Actual30R | BG2: 50Anterior15 | BH2: 50Anterior30R | BI2: 50ExistenciaWC | BJ2: 54Actual15 | BK2: 54Actual30R | BL2: 54Anterior15 | BM2: 54Anterior30R | BN2: 54ExistenciaWC
A3: 47047 | B3: 47047 | D3: 15 | E3: 677 | F3: TRESMONTES LUCHETTI (NUTRESA) | G3: 999 | H3: PRODUCTOS A ELIMINAR | I3: 20.9477 | J3: 314.2155 | K3: =L3*J3 -> #REF! | L3: =SUM(O3+S3+W3) -> #REF! | M3: 0 | N3: 0 | O3: =MAX(0,(TRUNC((M3*0.75)-N3))) -> 0 | Q3: 0 | R3: 0 | S3: =Q3-#REF! -> #REF! | U3: 0 | V3: 0 | W3: =MAX(0,(TRUNC((U3*0.75)-V3))) -> 0 | X3: 0 | Y3: 0 | Z3: 0 | AA3: 0 | AB3: 0 | AC3: 0 | AD3: 0 | AE3: 0 | AF3: 0 | AG3: 0 | AH3: 0 | AI3: 0 | AJ3: 0 | AK3: 0 | AL3: 0 | AM3: 0 | AN3: 0 | AO3: 0 | AP3: 0 | AQ3: 0 | AR3: 0 | AS3: 0 | AT3: 0 | AU3: 0 | AV3: 0 | AW3: 0 | AX3: 0 | AY3: 0 | AZ3: 0 | BA3: 0 | BB3: 0 | BC3: 0 | BD3: 0 | BE3: 0 | BF3: 0 | BG3: 0 | BH3: 0 | BI3: 0 | BJ3: 0 | BK3: 0 | BL3: 0 | BM3: 0 | BN3: 0
A4: 47006 | B4: * DESC NUCITA SUPER 4 /12 NUTRESA | D4: 24 | E4: 677 | F4: TRESMONTES LUCHETTI (NUTRESA) | G4: 998 | H4: PRODUCTOS CON BAJA ROTACION | I4: 20.6351 | J4: 495.2424 | K4: =L4*J4 -> #REF! | L4: =SUM(O4+S4+W4) -> #REF! | M4: 0 | N4: 0 | O4: =MAX(0,(TRUNC((M4*0.75)-N4))) -> 0 | Q4: 0 | R4: 0 | S4: =Q4-#REF! -> #REF! | U4: 0 | V4: 0 | W4: =MAX(0,(TRUNC((U4*0.75)-V4))) -> 0 | X4: 0 | Y4: 0 | Z4: 0 | AA4: 0 | AB4: 0 | AC4: 0 | AD4: 0 | AE4: 0 | AF4: 0 | AG4: 0 | AH4: 0 | AI4: 0 | AJ4: 0 | AK4: 0 | AL4: 0 | AM4: 0 | AN4: 0 | AO4: 0 | AP4: 0 | AQ4: 0 | AR4: 0 | AS4: 0 | AT4: 0 | AU4: 0 | AV4: 0 | AW4: 0 | AX4: 0 | AY4: 0 | AZ4: 0 | BA4: 0 | BB4: 0 | BC4: 0 | BD4: 0 | BE4: 0 | BF4: 0 | BG4: 0 | BH4: 0 | BI4: 0 | BJ4: 0 | BK4: 0 | BL4: 0 | BM4: 0 | BN4: 0
A5: 47022 | B5: * DESC VIT MONEDA ORO CHOC NUTRESA /120 | D5: 10 | E5: 677 | F5: TRESMONTES LUCHETTI (NUTRESA) | G5: 998 | H5: PRODUCTOS CON BAJA ROTACION | I5: 127.43 | J5: 1274.3 | K5: =L5*J5 -> #REF! | L5: =SUM(O5+S5+W5) -> #REF! | M5: 0 | N5: 0 | O5: =MAX(0,(TRUNC((M5*0.75)-N5))) -> 0 | Q5: 0 | R5: 0 | S5: =Q5-#REF! -> #REF! | U5: 0 | V5: 0 | W5: =MAX(0,(TRUNC((U5*0.75)-V5))) -> 0 | X5: 0 | Y5: 0 | Z5: 0 | AA5: 0 | AB5: 0 | AC5: 0 | AD5: 0 | AE5: 0 | AF5: 0 | AG5: 0 | AH5: 0 | AI5: 0 | AJ5: 0 | AK5: 0 | AL5: 0 | AM5: 0 | AN5: 0 | AO5: 0 | AP5: 0 | AQ5: 0 | AR5: 0 | AS5: 0 | AT5: 0 | AU5: 0 | AV5: 0 | AW5: 0 | AX5: 0 | AY5: 0 | AZ5: 0 | BA5: 0 | BB5: 0 | BC5: 0 | BD5: 0 | BE5: 0 | BF5: 0 | BG5: 0 | BH5: 0 | BI5: 0 | BJ5: 0 | BK5: 0 | BL5: 0 | BM5: 0 | BN5: 0
A6: 8041 | B6: * DESCONTINUADO | D6: 72 | E6: 677 | F6: TRESMONTES LUCHETTI (NUTRESA) | G6: 999 | H6: PRODUCTOS A ELIMINAR | I6: 6.5368 | J6: 470.6496 | K6: =L6*J6 -> #REF! | L6: =SUM(O6+S6+W6) -> #REF! | M6: 0 | N6: 0 | O6: =MAX(0,(TRUNC((M6*0.75)-N6))) -> 0 | Q6: 0 | R6: 0 | S6: =Q6-#REF! -> #REF! | U6: 0 | V6: 0 | W6: =MAX(0,(TRUNC((U6*0.75)-V6))) -> 0 | X6: 0 | Y6: 0 | Z6: 0 | AA6: 0 | AB6: 0 | AC6: 0 | AD6: 0 | AE6: 0 | AF6: 0 | AG6: 0 | AH6: 0 | AI6: 0 | AJ6: 0 | AK6: 0 | AL6: 0 | AM6: 0 | AN6: 0 | AO6: 0 | AP6: 0 | AQ6: 0 | AR6: 0 | AS6: 0 | AT6: 0 | AU6: 0 | AV6: 0 | AW6: 0 | AX6: 0 | AY6: 0 | AZ6: 0 | BA6: 0 | BB6: 0 | BC6: 0 | BD6: 0 | BE6: 0 | BF6: 0 | BG6: 0 | BH6: 0 | BI6: 0 | BJ6: 0 | BK6: 0 | BL6: 0 | BM6: 0 | BN6: 0
A7: 8042 | B7: * DESCONTINUADO | D7: 72 | E7: 677 | F7: TRESMONTES LUCHETTI (NUTRESA) | G7: 999 | H7: PRODUCTOS A ELIMINAR | I7: 6.5368 | J7: 470.6496 | K7: =L7*J7 -> #REF! | L7: =SUM(O7+S7+W7) -> #REF! | M7: 0 | N7: 0 | O7: =MAX(0,(TRUNC((M7*0.75)-N7))) -> 0 | Q7: 0 | R7: 0 | S7: =Q7-#REF! -> #REF! | U7: 0 | V7: 0 | W7: =MAX(0,(TRUNC((U7*0.75)-V7))) -> 0 | X7: 0 | Y7: 0 | Z7: 0 | AA7: 0 | AB7: 0 | AC7: 0 | AD7: 0 | AE7: 0 | AF7: 0 | AG7: 0 | AH7: 0 | AI7: 0 | AJ7: 0 | AK7: 0 | AL7: 0 | AM7: 0 | AN7: 0 | AO7: 0 | AP7: 0 | AQ7: 0 | AR7: 0 | AS7: 0 | AT7: 0 | AU7: 0 | AV7: 0 | AW7: 0 | AX7: 0 | AY7: 0 | AZ7: 0 | BA7: 0 | BB7: 0 | BC7: 0 | BD7: 0 | BE7: 0 | BF7: 0 | BG7: 0 | BH7: 0 | BI7: 0 | BJ7: 0 | BK7: 0 | BL7: 0 | BM7: 0 | BN7: 0
A8: 9099 | B8: * DESCONTINUADO | D8: 24 | E8: 677 | F8: TRESMONTES LUCHETTI (NUTRESA) | G8: 999 | H8: PRODUCTOS A ELIMINAR | I8: 15.6492 | J8: 375.5808 | K8: =L8*J8 -> #REF! | L8: =SUM(O8+S8+W8) -> #REF! | M8: 0 | N8: 0 | O8: =MAX(0,(TRUNC((M8*0.75)-N8))) -> 0 | Q8: 0 | R8: 0 | S8: =Q8-#REF! -> #REF! | U8: 0 | V8: 0 | W8: =MAX(0,(TRUNC((U8*0.75)-V8))) -> 0 | X8: 0 | Y8: 0 | Z8: 0 | AA8: 0 | AB8: 0 | AC8: 0 | AD8: 0 | AE8: 0 | AF8: 0 | AG8: 0 | AH8: 0 | AI8: 0 | AJ8: 0 | AK8: 0 | AL8: 0 | AM8: 0 | AN8: 0 | AO8: 0 | AP8: 0 | AQ8: 0 | AR8: 0 | AS8: 0 | AT8: 0 | AU8: 0 | AV8: 0 | AW8: 0 | AX8: 0 | AY8: 0 | AZ8: 0 | BA8: 0 | BB8: 0 | BC8: 0 | BD8: 0 | BE8: 0 | BF8: 0 | BG8: 0 | BH8: 0 | BI8: 0 | BJ8: 0 | BK8: 0 | BL8: 0 | BM8: 0 | BN8: 0
A9: 47017 | B9: ** | D9: 6 | E9: 677 | F9: TRESMONTES LUCHETTI (NUTRESA) | G9: 999 | H9: PRODUCTOS A ELIMINAR | I9: 51.17 | J9: 307.02 | K9: =L9*J9 -> #REF! | L9: =SUM(O9+S9+W9) -> #REF! | M9: 0 | N9: 0 | O9: =MAX(0,(TRUNC((M9*0.75)-N9))) -> 0 | Q9: 0 | R9: 0 | S9: =Q9-#REF! -> #REF! | U9: 0 | V9: 0 | W9: =MAX(0,(TRUNC((U9*0.75)-V9))) -> 0 | X9: 0 | Y9: 0 | Z9: 0 | AA9: 0 | AB9: 0 | AC9: 0 | AD9: 0 | AE9: 0 | AF9: 0 | AG9: 0 | AH9: 0 | AI9: 0 | AJ9: 0 | AK9: 0 | AL9: 0 | AM9: 0 | AN9: 0 | AO9: 0 | AP9: 0 | AQ9: 0 | AR9: 0 | AS9: 0 | AT9: 0 | AU9: 0 | AV9: 0 | AW9: 0 | AX9: 0 | AY9: 0 | AZ9: 0 | BA9: 0 | BB9: 0 | BC9: 0 | BD9: 0 | BE9: 0 | BF9: 0 | BG9: 0 | BH9: 0 | BI9: 0 | BJ9: 0 | BK9: 0 | BL9: 0 | BM9: 0 | BN9: 0
A10: 47021 | B10: ** | D10: 10 | E10: 677 | F10: TRESMONTES LUCHETTI (NUTRESA) | G10: 999 | H10: PRODUCTOS A ELIMINAR | I10: 34.3188 | J10: 343.188 | K10: =L10*J10 -> #REF! | L10: =SUM(O10+S10+W10) -> #REF! | M10: 0 | N10: 0 | O10: =MAX(0,(TRUNC((M10*0.75)-N10))) -> 0 | Q10: 0 | R10: 0 | S10: =Q10-#REF! -> #REF! | U10: 0 | V10: 0 | W10: =MAX(0,(TRUNC((U10*0.75)-V10))) -> 0 | X10: 0 | Y10: 0 | Z10: 0 | AA10: 0 | AB10: 0 | AC10: 0 | AD10: 0 | AE10: 0 | AF10: 0 | AG10: 0 | AH10: 0 | AI10: 0 | AJ10: 0 | AK10: 0 | AL10: 0 | AM10: 0 | AN10: 0 | AO10: 0 | AP10: 0 | AQ10: 0 | AR10: 0 | AS10: 0 | AT10: 0 | AU10: 0 | AV10: 0 | AW10: 0 | AX10: 0 | AY10: 0 | AZ10: 0 | BA10: 0 | BB10: 0 | BC10: 0 | BD10: 0 | BE10: 0 | BF10: 0 | BG10: 0 | BH10: 0 | BI10: 0 | BJ10: 0 | BK10: 0 | BL10: 0 | BM10: 0 | BN10: 0
A11: 47028 | B11: ** | D11: 24 | E11: 677 | F11: TRESMONTES LUCHETTI (NUTRESA) | G11: 999 | H11: PRODUCTOS A ELIMINAR | I11: 37.9 | J11: 909.6 | K11: =L11*J11 -> #REF! | L11: =SUM(O11+S11+W11) -> #REF! | M11: 0 | N11: 0 | O11: =MAX(0,(TRUNC((M11*0.75)-N11))) -> 0 | Q11: 0 | R11: 0 | S11: =Q11-#REF! -> #REF! | U11: 0 | V11: 0 | W11: =MAX(0,(TRUNC((U11*0.75)-V11))) -> 0 | X11: 0 | Y11: 0 | Z11: 0 | AA11: 0 | AB11: 0 | AC11: 0 | AD11: 0 | AE11: 0 | AF11: 0 | AG11: 0 | AH11: 0 | AI11: 0 | AJ11: 0 | AK11: 0 | AL11: 0 | AM11: 0 | AN11: 0 | AO11: 0 | AP11: 0 | AQ11: 0 | AR11: 0 | AS11: 0 | AT11: 0 | AU11: 0 | AV11: 0 | AW11: 0 | AX11: 0 | AY11: 0 | AZ11: 0 | BA11: 0 | BB11: 0 | BC11: 0 | BD11: 0 | BE11: 0 | BF11: 0 | BG11: 0 | BH11: 0 | BI11: 0 | BJ11: 0 | BK11: 0 | BL11: 0 | BM11: 0 | BN11: 0
A12: 47032 | B12: ** | D12: 12 | E12: 677 | F12: TRESMONTES LUCHETTI (NUTRESA) | G12: 999 | H12: PRODUCTOS A ELIMINAR | I12: 22.49 | J12: 269.88 | K12: =L12*J12 -> #REF! | L12: =SUM(O12+S12+W12) -> #REF! | M12: 0 | N12: 0 | O12: =MAX(0,(TRUNC((M12*0.75)-N12))) -> 0 | Q12: 0 | R12: 0 | S12: =Q12-#REF! -> #REF! | U12: 0 | V12: 0 | W12: =MAX(0,(TRUNC((U12*0.75)-V12))) -> 0 | X12: 0 | Y12: 0 | Z12: 0 | AA12: 0 | AB12: 0 | AC12: 0 | AD12: 0 | AE12: 0 | AF12: 0 | AG12: 0 | AH12: 0 | AI12: 0 | AJ12: 0 | AK12: 0 | AL12: 0 | AM12: 0 | AN12: 0 | AO12: 0 | AP12: 0 | AQ12: 0 | AR12: 0 | AS12: 0 | AT12: 0 | AU12: 0 | AV12: 0 | AW12: 0 | AX12: 0 | AY12: 0 | AZ12: 0 | BA12: 0 | BB12: 0 | BC12: 0 | BD12: 0 | BE12: 0 | BF12: 0 | BG12: 0 | BH12: 0 | BI12: 0 | BJ12: 0 | BK12: 0 | BL12: 0 | BM12: 0 | BN12: 0
A13: 47034 | B13: ** | D13: 12 | E13: 677 | F13: TRESMONTES LUCHETTI (NUTRESA) | G13: 999 | H13: PRODUCTOS A ELIMINAR | I13: 25.0387 | J13: 300.4644 | K13: =L13*J13 -> #REF! | L13: =SUM(O13+S13+W13) -> #REF! | M13: 0 | N13: 0 | O13: =MAX(0,(TRUNC((M13*0.75)-N13))) -> 0 | Q13: 0 | R13: 0 | S13: =Q13-#REF! -> #REF! | U13: 0 | V13: 0 | W13: =MAX(0,(TRUNC((U13*0.75)-V13))) -> 0 | X13: 0 | Y13: 0 | Z13: 0 | AA13: 0 | AB13: 0 | AC13: 0 | AD13: 0 | AE13: 0 | AF13: 0 | AG13: 0 | AH13: 0 | AI13: 0 | AJ13: 0 | AK13: 0 | AL13: 0 | AM13: 0 | AN13: 0 | AO13: 0 | AP13: 0 | AQ13: 0 | AR13: 0 | AS13: 0 | AT13: 0 | AU13: 0 | AV13: 0 | AW13: 0 | AX13: 0 | AY13: 0 | AZ13: 0 | BA13: 0 | BB13: 0 | BC13: 0 | BD13: 0 | BE13: 0 | BF13: 0 | BG13: 0 | BH13: 0 | BI13: 0 | BJ13: 0 | BK13: 0 | BL13: 0 | BM13: 0 | BN13: 0
A14: 47037 | B14: ** | D14: 24 | E14: 677 | F14: TRESMONTES LUCHETTI (NUTRESA) | G14: 999 | H14: PRODUCTOS A ELIMINAR | I14: 20.0881 | J14: 482.1144 | K14: =L14*J14 -> #REF! | L14: =SUM(O14+S14+W14) -> #REF! | M14: 0 | N14: 0 | O14: =MAX(0,(TRUNC((M14*0.75)-N14))) -> 0 | Q14: 0 | R14: 0 | S14: =Q14-#REF! -> #REF! | U14: 0 | V14: 0 | W14: =MAX(0,(TRUNC((U14*0.75)-V14))) -> 0 | X14: 0 | Y14: 0 | Z14: 0 | AA14: 0 | AB14: 0 | AC14: 0 | AD14: 0 | AE14: 0 | AF14: 0 | AG14: 0 | AH14: 0 | AI14: 0 | AJ14: 0 | AK14: 0 | AL14: 0 | AM14: 0 | AN14: 0 | AO14: 0 | AP14: 0 | AQ14: 0 | AR14: 0 | AS14: 0 | AT14: 0 | AU14: 0 | AV14: 0 | AW14: 0 | AX14: 0 | AY14: 0 | AZ14: 0 | BA14: 0 | BB14: 0 | BC14: 0 | BD14: 0 | BE14: 0 | BF14: 0 | BG14: 0 | BH14: 0 | BI14: 0 | BJ14: 0 | BK14: 0 | BL14: 0 | BM14: 0 | BN14: 0
A15: 47044 | B15: ** | D15: 12 | E15: 677 | F15: TRESMONTES LUCHETTI (NUTRESA) | G15: 999 | H15: PRODUCTOS A ELIMINAR | I15: 18.04 | J15: 216.48 | K15: =L15*J15 -> #REF! | L15: =SUM(O15+S15+W15) -> #REF! | M15: 0 | N15: 0 | O15: =MAX(0,(TRUNC((M15*0.75)-N15))) -> 0 | Q15: 0 | R15: 0 | S15: =Q15-#REF! -> #REF! | U15: 0 | V15: 0 | W15: =MAX(0,(TRUNC((U15*0.75)-V15))) -> 0 | X15: 0 | Y15: 0 | Z15: 0 | AA15: 0 | AB15: 0 | AC15: 0 | AD15: 0 | AE15: 0 | AF15: 0 | AG15: 0 | AH15: 0 | AI15: 0 | AJ15: 0 | AK15: 0 | AL15: 0 | AM15: 0 | AN15: 0 | AO15: 0 | AP15: 0 | AQ15: 0 | AR15: 0 | AS15: 0 | AT15: 0 | AU15: 0 | AV15: 0 | AW15: 0 | AX15: 0 | AY15: 0 | AZ15: 0 | BA15: 0 | BB15: 0 | BC15: 0 | BD15: 0 | BE15: 0 | BF15: 0 | BG15: 0 | BH15: 0 | BI15: 0 | BJ15: 0 | BK15: 0 | BL15: 0 | BM15: 0 | BN15: 0
... A17: 47125 | B17: ** | D17: 15 | E17: 677 | F17: TRESMONTES LUCHETTI (NUTRESA) | G17: 999 | H17: PRODUCTOS A ELIMINAR | I17: 37.9 | J17: 568.5 | K17: =L17*J17 -> #REF! | L17: =SUM(O17+S17+W17) -> #REF! | M17: 0 | N17: 0 | O17: =MAX(0,(TRUNC((M17*0.75)-N17))) -> 0 | Q17: 0 | R17: 0 | S17: =Q17-#REF! -> #REF! | U17: 0 | V17: 0 | W17: =MAX(0,(TRUNC((U17*0.75)-V17))) -> 0 | X17: 0 | Y17: 0 | Z17: 0 | AA17: 0 | AB17: 0 | AC17: 0 | AD17: 0 | AE17: 0 | AF17: 0 | AG17: 0 | AH17: 0 | AI17: 0 | AJ17: 0 | AK17: 0 | AL17: 0 | AM17: 0 | AN17: 0 | AO17: 0 | AP17: 0 | AQ17: 0 | AR17: 0 | AS17: 0 | AT17: 0 | AU17: 0 | AV17: 0 | AW17: 0 | AX17: 0 | AY17: 0 | AZ17: 0 | BA17: 0 | BB17: 0 | BC17: 0 | BD17: 0 | BE17: 0 | BF17: 0 | BG17: 0 | BH17: 0 | BI17: 0 | BJ17: 0 | BK17: 0 | BL17: 0 | BM17: 0 | BN17: 0
A18: 47005 | B18: NUCITA TRISABOR 224GR /16 NUTRESA | C18: 2/20 | D18: 24 | E18: 677 | F18: TRESMONTES LUCHETTI (NUTRESA) | G18: 61 | H18: NUTRESA SA DE CV | I18: 22.3159 | J18: 535.5816 | K18: =L18*J18 -> 0 | L18: =SUM(O18+W18+S18) -> 0 | M18: 63.67 | N18: 71.96 | O18: =MAX(0,(TRUNC((M18*0.75)-N18))) -> 0 | Q18: 98.98 | R18: 143.71 | S18: 0 | U18: 99.04 | V18: 46.96 | W18: 0 | X18: 40 ma | Y18: 140155.01 | Z18: 140657.12 | AA18: 254 | AB18: 147 | AC18: 952 | AD18: 497 | AE18: 1727 | AF18: 0 | AG18: 0 | AH18: 0 | AI18: 0 | AJ18: 0 | AK18: 0 | AL18: 0 | AM18: 0 | AN18: 0 | AO18: 0 | AP18: 0 | AQ18: 0 | AR18: 0 | AS18: 0 | AT18: 0 | AU18: 614 | AV18: 305 | AW18: 1272 | AX18: 674 | AY18: 3449 | AZ18: 0 | BA18: 0 | BB18: 0 | BC18: 0 | BD18: 0 | BE18: 701 | BF18: 182 | BG18: 1160 | BH18: 850 | BI18: 1127 | BJ18: 0 | BK18: 0 | BL18: 0 | BM18: 0 | BN18: 0
A19: 47001 | B19: CHOC CREMINO BICOLOR /24 NUTRESA | C19: 1/20 | D19: 16 | E19: 677 | F19: TRESMONTES LUCHETTI (NUTRESA) | G19: 61 | H19: NUTRESA SA DE CV | I19: 56.5902 | J19: 905.4432 | K19: =L19*J19 -> 144870.91 | L19: =SUM(O19+W19+S19) -> 160 | M19: 45.12 | N19: 4.44 | O19: 60 | Q19: 58.19 | R19: 20 | S19: 60 | U19: 47.5 | V19: 6.88 | W19: 40 | X19: 0 | Y19: 136552.15 | Z19: 28351.69 | AA19: 213 | AB19: 67 | AC19: 291 | AD19: 369 | AE19: 71 | AF19: 0 | AG19: 0 | AH19: 0 | AI19: 0 | AJ19: 0 | AK19: 0 | AL19: 0 | AM19: 0 | AN19: 0 | AO19: 0 | AP19: 0 | AQ19: 0 | AR19: 0 | AS19: 0 | AT19: 0 | AU19: 369 | AV19: 107 | AW19: 362 | AX19: 293 | AY19: 320 | AZ19: 0 | BA19: 0 | BB19: 0 | BC19: 0 | BD19: 0 | BE19: 140 | BF19: 154 | BG19: 372 | BH19: 342 | BI19: 110 | BJ19: 0 | BK19: 0 | BL19: 0 | BM19: 0 | BN19: 0
A20: 47012 | B20: CHOC MONEDA EXH /48 NUTRESA 1432 | C20: 1/25 | D20: 18 | E20: 677 | F20: TRESMONTES LUCHETTI (NUTRESA) | G20: 61 | H20: NUTRESA SA DE CV | I20: 58.8379 | J20: 1059.0822 | K20: =L20*J20 -> 52954.11 | L20: =SUM(O20+W20+S20) -> 50 | M20: 15.86 | N20: 17.44 | O20: =MAX(0,(TRUNC((M20*0.75)-N20))) -> 0 | Q20: 41.25 | R20: 7.78 | S20: 50 | U20: 32.33 | V20: 26.89 | W20: =MAX(0,(TRUNC((U20*0.75)-V20))) -> 0 | X20: 0 | Y20: 94729.02 | Z20: 55189.95 | AA20: 91 | AB20: 87 | AC20: 63 | AD20: 176 | AE20: 314 | AF20: 0 | AG20: 0 | AH20: 0 | AI20: 0 | AJ20: 0 | AK20: 0 | AL20: 0 | AM20: 0 | AN20: 0 | AO20: 0 | AP20: 0 | AQ20: 0 | AR20: 0 | AS20: 0 | AT20: 0 | AU20: 278 | AV20: 125 | AW20: 308 | AX20: 188 | AY20: 140 | AZ20: 0 | BA20: 0 | BB20: 0 | BC20: 0 | BD20: 0 | BE20: 265 | BF20: 66 | BG20: 219 | BH20: 130 | BI20: 484 | BJ20: 0 | BK20: 0 | BL20: 0 | BM20: 0 | BN20: 0
A21: 47023 | B21: EXH CHOC CREMINO BICOLORE NUTRESA /50 | D21: 8 | E21: 677 | F21: TRESMONTES LUCHETTI (NUTRESA) | G21: 61 | H21: NUTRESA SA DE CV | I21: 105.55 | J21: 844.4 | K21: =L21*J21 -> 84440 | L21: =SUM(O21+W21+S21) -> 100 | M21: 33.19 | N21: 13.5 | O21: 20 | Q21: 35.12 | R21: 7.38 | S21: 50 | U21: 22.38 | V21: 4.88 | W21: 30 | X21: 0 | Y21: 76576.52 | Z21: 21743.3 | AA21: 101 | AB21: 23 | AC21: 127 | AD21: 52 | AE21: 108 | AF21: 0 | AG21: 0 | AH21: 0 | AI21: 0 | AJ21: 0 | AK21: 0 | AL21: 0 | AM21: 0 | AN21: 0 | AO21: 0 | AP21: 0 | AQ21: 0 | AR21: 0 | AS21: 0 | AT21: 0 | AU21: 106 | AV21: 19 | AW21: 120 | AX21: 91 | AY21: 59 | AZ21: 0 | BA21: 0 | BB21: 0 | BC21: 0 | BD21: 0 | BE21: 78 | BF21: 59 | BG21: 62 | BH21: 19 | BI21: 39 | BJ21: 0 | BK21: 0 | BL21: 0 | BM21: 0 | BN21: 0
A22: 47010 | B22: CHOC MUIBON AVELLANAS /15 NUTRESA 9055 | C22: 46296 | D22: 24 | E22: 677 | F22: TRESMONTES LUCHETTI (NUTRESA) | G22: 61 | H22: NUTRESA SA DE CV | I22: 48.56 | J22: 1165.44 | K22: =L22*J22 -> 58272 | L22: =SUM(O22+W22+S22) -> 50 | M22: 14.6 | N22: 2.79 | O22: 20 | Q22: 22.04 | R22: 7.62 | S22: 20 | U22: 24.75 | V22: 12.08 | W22: 10 | X22: 0 | Y22: 71553.16 | Z22: 26222.4 | AA22: 67 | AB22: 59 | AC22: 127 | AD22: 254 | AE22: 67 | AF22: 0 | AG22: 0 | AH22: 0 | AI22: 0 | AJ22: 0 | AK22: 0 | AL22: 0 | AM22: 0 | AN22: 0 | AO22: 0 | AP22: 0 | AQ22: 0 | AR22: 0 | AS22: 0 | AT22: 0 | AU22: 187 | AV22: 74 | AW22: 143 | AX22: 324 | AY22: 183 | AZ22: 0 | BA22: 0 | BB22: 0 | BC22: 0 | BD22: 0 | BE22: 153 | BF22: 98 | BG22: 253 | BH22: 278 | BI22: 290 | BJ22: 0 | BK22: 0 | BL22: 0 | BM22: 0 | BN22: 0
A23: 47046 | B23: NUCITA PATITAS (152G) / 8 NUTRESA | C23: 1/20 | D23: 24 | E23: 677 | F23: TRESMONTES LUCHETTI (NUTRESA) | G23: 61 | H23: NUTRESA SA DE CV | I23: 39.11 | J23: 938.64 | K23: =L23*J23 -> 18772.8 | L23: =SUM(O23+W23+S23) -> 20 | M23: 12.83 | N23: 45.96 | O23: =MAX(0,(TRUNC((M23*0.75)-N23))) -> 0 | Q23: 30.85 | R23: 6.88 | S23: 20 | T23: 10ZAM | U23: 22.21 | V23: 49.12 | W23: =MAX(0,(TRUNC((U23*0.75)-V23))) -> 0 | X23: 0 | Y23: 61852.46 | Z23: 95702.17 | AA23: 86 | AB23: 38 | AC23: 139 | AD23: 128 | AE23: 1103 | AF23: 0 | AG23: 0 | AH23: 0 | AI23: 0 | AJ23: 0 | AK23: 0 | AL23: 0 | AM23: 0 | AN23: 0 | AO23: 0 | AP23: 0 | AQ23: 0 | AR23: 0 | AS23: 0 | AT23: 0 | AU23: 319 | AV23: 77 | AW23: 286 | AX23: 194 | AY23: 165 | AZ23: 0 | BA23: 0 | BB23: 0 | BC23: 0 | BD23: 0 | BE23: 133 | BF23: 62 | BG23: 270 | BH23: 198 | BI23: 1179 | BJ23: 0 | BK23: 0 | BL23: 0 | BM23: 0 | BN23: 0
A24: 47038 | B24: CREMINO STICK 140GR/ 20 NUTRESA | D24: 28 | E24: 677 | F24: TRESMONTES LUCHETTI (NUTRESA) | G24: 61 | H24: NUTRESA SA DE CV | I24: 26.59 | J24: 744.52 | K24: =L24*J24 -> 29780.8 | L24: =SUM(O24+W24+S24) -> 40 | M24: 16.34 | N24: 0.04 | O24: 20 | Q24: 23.54 | R24: 29.54 | S24: 0 | U24: 23.89 | V24: 6.54 | W24: 20 | X24: 0 | Y24: 47476.44 | Z24: 26882.49 | AA24: 93 | AB24: 83 | AC24: 248 | AD24: 150 | AE24: 1 | AF24: 0 | AG24: 0 | AH24: 0 | AI24: 0 | AJ24: 0 | AK24: 0 | AL24: 0 | AM24: 0 | AN24: 0 | AO24: 0 | AP24: 0 | AQ24: 0 | AR24: 0 | AS24: 0 | AT24: 0 | AU24: 138 | AV24: 52 | AW24: 357 | AX24: 276 | AY24: 827 | AZ24: 0 | BA24: 0 | BB24: 0 | BC24: 0 | BD24: 0 | BE24: 239 | BF24: 8 | BG24: 277 | BH24: 298 | BI24: 183 | BJ24: 0 | BK24: 0 | BL24: 0 | BM24: 0 | BN24: 0
A25: 47039 | B25: NUCITA TRISABOR CONFITES NUTRESA/12 5868 | D25: 24 | E25: 677 | F25: TRESMONTES LUCHETTI (NUTRESA) | G25: 61 | H25: NUTRESA SA DE CV | I25: 52.259 | J25: 1254.216 | K25: =L25*J25 -> 25084.32 | L25: =SUM(O25+W25+S25) -> 20 | M25: 8.44 | N25: 1 | O25: 10 | Q25: 17.9 | R25: 12.12 | S25: 10 | U25: 9.98 | V25: 7.83 | W25: =MAX(0,(TRUNC((U25*0.75)-V25))) -> 0 | X25: 0 | Y25: 45543.72 | Z25: 26286.28 | AA25: 72 | AB25: 0 | AC25: 94 | AD25: 73 | AE25: 24 | AF25: 0 | AG25: 0 | AH25: 0 | AI25: 0 | AJ25: 0 | AK25: 0 | AL25: 0 | AM25: 0 | AN25: 0 | AO25: 0 | AP25: 0 | AQ25: 0 | AR25: 0 | AS25: 0 | AT25: 0 | AU25: 126 | AV25: 35 | AW25: 217 | AX25: 138 | AY25: 291 | AZ25: 0 | BA25: 0 | BB25: 0 | BC25: 0 | BD25: 0 | BE25: 97 | BF25: 20 | BG25: 85 | BH25: 95 | BI25: 188 | BJ25: 0 | BK25: 0 | BL25: 0 | BM25: 0 | BN25: 0
A26: 47000 | B26: CHOC CREMINO BLANCO /24 NUTRESA 2256 | C26: 1/20 | D26: 16 | E26: 677 | F26: TRESMONTES LUCHETTI (NUTRESA) | G26: 61 | H26: NUTRESA SA DE CV | I26: 56.59 | J26: 905.44 | K26: =L26*J26 -> 0 | L26: =SUM(O26+W26+S26) -> 0 | M26: 12.75 | N26: 8.38 | O26: 0 | P26: 5ZAM | Q26: 23.38 | R26: 38.44 | S26: 0 | U26: 12 | V26: 21.62 | W26: =MAX(0,(TRUNC((U26*0.75)-V26))) -> 0 | X26: 0 | Y26: 43574.3 | Z26: 61966.05 | AA26: 70 | AB26: 17 | AC26: 83 | AD26: 85 | AE26: 134 | AF26: 0 | AG26: 0 | AH26: 0 | AI26: 0 | AJ26: 0 | AK26: 0 | AL26: 0 | AM26: 0 | AN26: 0 | AO26: 0 | AP26: 0 | AQ26: 0 | AR26: 0 | AS26: 0 | AT26: 0 | AU26: 147 | AV26: 38 | AW26: 133 | AX26: 150 | AY26: 615 | AZ26: 0 | BA26: 0 | BB26: 0 | BC26: 0 | BD26: 0 | BE26: 62 | BF26: 49 | BG26: 83 | BH26: 45 | BI26: 346 | BJ26: 0 | BK26: 0 | BL26: 0 | BM26: 0 | BN26: 0
A27: 10703 | B27: VIT CHOC MONEDA 708g /120 NUTRESA | D27: 12 | E27: 677 | F27: TRESMONTES LUCHETTI (NUTRESA) | G27: 542 | H27: DISPONIBLE | I27: 125.581 | J27: 1506.972 | K27: =L27*J27 -> 52744.02 | L27: =SUM(O27+W27+S27) -> 35 | M27: 4.62 | N27: -0.25 | O27: 10 | Q27: 5.92 | R27: 0 | S27: 15 | U27: 11.08 | V27: 3.25 | W27: 10 | X27: 0 | Y27: 32588.27 | Z27: 4520.92 | AA27: 12 | AB27: 15 | AC27: 34 | AD27: 4 | AE27: -3 | AF27: 0 | AG27: 0 | AH27: 0 | AI27: 0 | AJ27: 0 | AK27: 0 | AL27: 0 | AM27: 0 | AN27: 0 | AO27: 0 | AP27: 0 | AQ27: 0 | AR27: 0 | AS27: 0 | AT27: 0 | AU27: 13 | AV27: 9 | AW27: 40 | AX27: 27 | AY27: 0 | AZ27: 0 | BA27: 0 | BB27: 0 | BC27: 0 | BD27: 0 | BE27: 40 | BF27: 23 | BG27: 54 | BH27: 55 | BI27: 39 | BJ27: 0 | BK27: 0 | BL27: 0 | BM27: 0 | BN27: 0
A28: 47004 | B28: NUCITA FRESA Y CHOCOLATE 224GR /16 NUTRESA | C28: 2/20 | D28: 24 | E28: 677 | F28: TRESMONTES LUCHETTI (NUTRESA) | G28: 61 | H28: NUTRESA SA DE CV | I28: 22.3159 | J28: 535.5816 | K28: =L28*J28 -> 0 | L28: =SUM(O28+W28+S28) -> 0 | M28: 15.02 | N28: 22.88 | O28: =MAX(0,(TRUNC((M28*0.75)-N28))) -> 0 | Q28: 22.33 | R28: 41.42 | S28: 0 | U28: 23.35 | V28: 79.96 | W28: =MAX(0,(TRUNC((U28*0.75)-V28))) -> 0 | X28: 0 | Y28: 32514.27 | Z28: 77257.65 | AA28: 104 | AB28: 70 | AC28: 93 | AD28: 257 | AE28: 549 | AF28: 0 | AG28: 0 | AH28: 0 | AI28: 0 | AJ28: 0 | AK28: 0 | AL28: 0 | AM28: 0 | AN28: 0 | AO28: 0 | AP28: 0 | AQ28: 0 | AR28: 0 | AS28: 0 | AT28: 0 | AU28: 220 | AV28: 69 | AW28: 232 | AX28: 99 | AY28: 994 | AZ28: 0 | BA28: 0 | BB28: 0 | BC28: 0 | BD28: 0 | BE28: 64 | BF28: 32 | BG28: 377 | BH28: 207 | BI28: 1919 | BJ28: 0 | BK28: 0 | BL28: 0 | BM28: 0 | BN28: 0
A29: 47024 | B29: CHOC BALONCITOS NUTRESA /200 | D29: 12 | E29: 677 | F29: TRESMONTES LUCHETTI (NUTRESA) | G29: 61 | H29: NUTRESA SA DE CV | I29: 135.39 | J29: 1624.68 | K29: =L29*J29 -> 40617 | L29: =SUM(O29+W29+S29) -> 25 | M29: 7.42 | N29: -0.08 | O29: 10 | Q29: 6.67 | R29: 4.67 | S29: 5 | U29: 4.88 | V29: 0 | W29: 10 | X29: 0 | Y29: 30801.22 | Z29: 7446.45 | AA29: 19 | AB29: 29 | AC29: 54 | AD29: 3 | AE29: -1 | AF29: 0 | AG29: 0 | AH29: 0 | AI29: 0 | AJ29: 0 | AK29: 0 | AL29: 0 | AM29: 0 | AN29: 0 | AO29: 0 | AP29: 0 | AQ29: 0 | AR29: 0 | AS29: 0 | AT29: 0 | AU29: 33 | AV29: 6 | AW29: 33 | AX29: 22 | AY29: 56 | AZ29: 0 | BA29: 0 | BB29: 0 | BC29: 0 | BD29: 0 | BE29: 6 | BF29: 13 | BG29: 30 | BH29: 32 | BI29: 0 | BJ29: 0 | BK29: 0 | BL29: 0 | BM29: 0 | BN29: 0
A30: 47008 | B30: CHOC NUCITA BARRA /16 NUTRESA 1471 | D30: 24 | E30: 677 | F30: TRESMONTES LUCHETTI (NUTRESA) | G30: 61 | H30: NUTRESA SA DE CV | I30: 35.74 | J30: 857.76 | K30: =L30*J30 -> 42888 | L30: =SUM(O30+W30+S30) -> 50 | M30: 7.79 | N30: 0.5 | O30: 10 | Q30: 10.58 | R30: 0 | S30: 20 | U30: 16.5 | V30: 1.42 | W30: 20 | X30: 0 | Y30: 29914.38 | Z30: 1644.04 | AA30: 0 | AB30: 3 | AC30: 135 | AD30: 101 | AE30: 12 | AF30: 0 | AG30: 0 | AH30: 0 | AI30: 0 | AJ30: 0 | AK30: 0 | AL30: 0 | AM30: 0 | AN30: 0 | AO30: 0 | AP30: 0 | AQ30: 0 | AR30: 0 | AS30: 0 | AT30: 0 | AU30: 0 | AV30: 3 | AW30: 198 | AX30: 109 | AY30: 0 | AZ30: 0 | BA30: 0 | BB30: 0 | BC30: 0 | BD30: 0 | BE30: 88 | BF30: 89 | BG30: 169 | BH30: 189 | BI30: 34 | BJ30: 0 | BK30: 0 | BL30: 0 | BM30: 0 | BN30: 0
A31: 47003 | B31: NUCITA FRESA/VAINILLLA /16 NUTRESA | C31: 2/20 | D31: 24 | E31: 677 | F31: TRESMONTES LUCHETTI (NUTRESA) | G31: 61 | H31: NUTRESA SA DE CV | I31: 22.3159 | J31: 535.5816 | K31: =L31*J31 -> 0 | L31: =SUM(O31+W31+S31) -> 0 | M31: 19.75 | N31: 36.58 | O31: =MAX(0,(TRUNC((M31*0.75)-N31))) -> 0 | Q31: 16.98 | R31: 47.54 | S31: 0 | U31: 17.81 | V31: 54.04 | W31: =MAX(0,(TRUNC((U31*0.75)-V31))) -> 0 | X31: 0 | Y31: 29211.51 | Z31: 73999.52 | AA31: 63 | AB31: 38 | AC31: 348 | AD31: 88 | AE31: 878 | AF31: 0 | AG31: 0 | AH31: 0 | AI31: 0 | AJ31: 0 | AK31: 0 | AL31: 0 | AM31: 0 | AN31: 0 | AO31: 0 | AP31: 0 | AQ31: 0 | AR31: 0 | AS31: 0 | AT31: 0 | AU31: 74 | AV31: 33 | AW31: 218 | AX31: 198 | AY31: 1141 | AZ31: 0 | BA31: 0 | BB31: 0 | BC31: 0 | BD31: 0 | BE31: 99 | BF31: 46 | BG31: 250 | BH31: 111 | BI31: 1297 | BJ31: 0 | BK31: 0 | BL31: 0 | BM31: 0 | BN31: 0
A32: 47002 | B32: NUCITA VAINILLA Y CHOCOLATE 240GR /16 NUTRES 78 | C32: 2/20 | D32: 24 | E32: 677 | F32: TRESMONTES LUCHETTI (NUTRESA) | G32: 61 | H32: NUTRESA SA DE CV | I32: 22.3159 | J32: 535.5816 | K32: =L32*J32 -> 0 | L32: =SUM(O32+W32+S32) -> 0 | M32: 17.71 | N32: 39.58 | O32: =MAX(0,(TRUNC((M32*0.75)-N32))) -> 0 | Q32: 16.94 | R32: 50.88 | S32: 0 | U32: 9.54 | V32: 24 | W32: =MAX(0,(TRUNC((U32*0.75)-V32))) -> 0 | X32: 0 | Y32: 23666.01 | Z32: 61301.78 | AA32: 76 | AB32: 33 | AC32: 237 | AD32: 191 | AE32: 950 | AF32: 0 | AG32: 0 | AH32: 0 | AI32: 0 | AJ32: 0 | AK32: 0 | AL32: 0 | AM32: 0 | AN32: 0 | AO32: 0 | AP32: 0 | AQ32: 0 | AR32: 0 | AS32: 0 | AT32: 0 | AU32: 99 | AV32: 49 | AW32: 176 | AX32: 214 | AY32: 1221 | AZ32: 0 | BA32: 0 | BB32: 0 | BC32: 0 | BD32: 0 | BE32: 66 | BF32: 17 | BG32: 112 | BH32: 85 | BI32: 576 | BJ32: 0 | BK32: 0 | BL32: 0 | BM32: 0 | BN32: 0
A33: 47029 | B33: NUCITA TRIANG TRISABOR /12 NUTRESA 2694 | D33: 24 | E33: 677 | F33: TRESMONTES LUCHETTI (NUTRESA) | G33: 61 | H33: NUTRESA SA DE CV | I33: 41.26 | J33: 990.24 | K33: =L33*J33 -> 24756 | L33: =SUM(O33+W33+S33) -> 25 | M33: 5 | N33: -0.04 | O33: 5 | Q33: 7.75 | R33: 4.29 | S33: 10 | U33: 9.08 | V33: 2.67 | W33: 10 | X33: 0 | Y33: 21620.24 | Z33: 6849.16 | AA33: 16 | AB33: 7 | AC33: 57 | AD33: 87 | AE33: -1 | AF33: 0 | AG33: 0 | AH33: 0 | AI33: 0 | AJ33: 0 | AK33: 0 | AL33: 0 | AM33: 0 | AN33: 0 | AO33: 0 | AP33: 0 | AQ33: 0 | AR33: 0 | AS33: 0 | AT33: 0 | AU33: 75 | AV33: 36 | AW33: 56 | AX33: 74 | AY33: 103 | AZ33: 0 | BA33: 0 | BB33: 0 | BC33: 0 | BD33: 0 | BE33: 76 | BF33: 25 | BG33: 108 | BH33: 43 | BI33: 64 | BJ33: 0 | BK33: 0 | BL33: 0 | BM33: 0 | BN33: 0
A34: 47014 | B34: CHOC BALONES BLISTER/56 NUTRESA 1398 | C34: 1/25 | D34: 24 | E34: 677 | F34: TRESMONTES LUCHETTI (NUTRESA) | G34: 61 | H34: NUTRESA SA DE CV | I34: 43.3191 | J34: 1039.6584 | K34: =L34*J34 -> 5198.292 | L34: =SUM(O34+W34+S34) -> 5 | M34: 4.1 | N34: 1.62 | O34: 0 | P34: 1ZAM | Q34: 5.9 | R34: 4 | S34: 5 | T34: NO PEDIR 25 SOLO 5 CONFIRMAR POR QUE LUEGO MANDAN LOS 25 | U34: 2.1 | V34: 5.04 | W34: =MAX(0,(TRUNC((U34*0.75)-V34))) -> 0 | X34: 0 | Y34: 12584.2 | Z34: 11089.69 | AA34: 15 | AB34: 4 | AC34: 71 | AD34: 21 | AE34: 39 | AF34: 0 | AG34: 0 | AH34: 0 | AI34: 0 | AJ34: 0 | AK34: 0 | AL34: 0 | AM34: 0 | AN34: 0 | AO34: 0 | AP34: 0 | AQ34: 0 | AR34: 0 | AS34: 0 | AT34: 0 | AU34: 73 | AV34: 33 | AW34: 34 | AX34: 36 | AY34: 96 | AZ34: 0 | BA34: 0 | BB34: 0 | BC34: 0 | BD34: 0 | BE34: 10 | BF34: 9 | BG34: 17 | BH34: 38 | BI34: 121 | BJ34: 0 | BK34: 0 | BL34: 0 | BM34: 0 | BN34: 0
A35: 48091 | B35: ZUKO 8 S JAMAICA EXH | D35: 12 | E35: 677 | F35: TRESMONTES LUCHETTI (NUTRESA) | G35: 690 | H35: TRESMONTES LUCCHETTI (ZUKO) | I35: 29.5707 | J35: 354.8484 | K35: =L35*J35 -> 0 | L35: =SUM(O35+W35+S35) -> 0 | M35: 10.88 | N35: 12.17 | O35: =MAX(0,(TRUNC((M35*0.75)-N35))) -> 0 | Q35: 6.96 | R35: 5.92 | S35: 0 | T35: 5zam | U35: 7.33 | V35: 20.25 | W35: =MAX(0,(TRUNC((U35*0.75)-V35))) -> 0 | X35: 0 | Y35: 8930.35 | Z35: 13602.52 | AA35: 32 | AB35: 14 | AC35: 58 | AD35: 67 | AE35: 146 | AF35: 0 | AG35: 0 | AH35: 0 | AI35: 0 | AJ35: 0 | AK35: 0 | AL35: 0 | AM35: 0 | AN35: 0 | AO35: 0 | AP35: 0 | AQ35: 0 | AR35: 0 | AS35: 0 | AT35: 0 | AU35: 18 | AV35: 11 | AW35: 43 | AX35: 34 | AY35: 71 | AZ35: 0 | BA35: 0 | BB35: 0 | BC35: 0 | BD35: 0 | BE35: 17 | BF35: 12 | BG35: 13 | BH35: 104 | BI35: 243 | BJ35: 0 | BK35: 0 | BL35: 0 | BM35: 0 | BN35: 0
A36: 48084 | B36: ZUKO 8 S HORCHATA EXH | D36: 12 | E36: 677 | F36: TRESMONTES LUCHETTI (NUTRESA) | G36: 690 | H36: TRESMONTES LUCCHETTI (ZUKO) | I36: 29.5707 | J36: 354.8484 | K36: =L36*J36 -> 0 | L36: =SUM(O36+W36+S36) -> 0 | M36: 7.04 | N36: 10.83 | O36: =MAX(0,(TRUNC((M36*0.75)-N36))) -> 0 | Q36: 5.58 | R36: 5.17 | S36: 0 | T36: 3zam | U36: 5.79 | V36: 15.42 | W36: =MAX(0,(TRUNC((U36*0.75)-V36))) -> 0 | X36: 0 | Y36: 6535.12 | Z36: 11148.15 | AA36: 41 | AB36: 14 | AC36: 14 | AD36: 45 | AE36: 130 | AF36: 0 | AG36: 0 | AH36: 0 | AI36: 0 | AJ36: 0 | AK36: 0 | AL36: 0 | AM36: 0 | AN36: 0 | AO36: 0 | AP36: 0 | AQ36: 0 | AR36: 0 | AS36: 0 | AT36: 0 | AU36: 18 | AV36: 10 | AW36: 30 | AX36: 28 | AY36: 62 | AZ36: 0 | BA36: 0 | BB36: 0 | BC36: 0 | BD36: 0 | BE36: 22 | BF36: 9 | BG36: 10 | BH36: 66 | BI36: 185 | BJ36: 0 | BK36: 0 | BL36: 0 | BM36: 0 | BN36: 0
A37: 48085 | B37: ZUKO 8 S FRESA EXH | D37: 12 | E37: 677 | F37: TRESMONTES LUCHETTI (NUTRESA) | G37: 690 | H37: TRESMONTES LUCCHETTI (ZUKO) | I37: 29.5707 | J37: 354.8484 | K37: =L37*J37 -> 0 | L37: =SUM(O37+W37+S37) -> 0 | M37: 5.12 | N37: 3.5 | O37: =MAX(0,(TRUNC((M37*0.75)-N37))) -> 0 | Q37: 4.5 | R37: 3.33 | S37: 0 | U37: 4.83 | V37: 0.67 | W37: 0 | X37: 0 | Y37: 5130.52 | Z37: 2661.36 | AA37: 17 | AB37: 11 | AC37: 7 | AD37: 64 | AE37: 42 | AF37: 0 | AG37: 0 | AH37: 0 | AI37: 0 | AJ37: 0 | AK37: 0 | AL37: 0 | AM37: 0 | AN37: 0 | AO37: 0 | AP37: 0 | AQ37: 0 | AR37: 0 | AS37: 0 | AT37: 0 | AU37: 8 | AV37: 0 | AW37: 35 | AX37: 22 | AY37: 40 | AZ37: 0 | BA37: 0 | BB37: 0 | BC37: 0 | BD37: 0 | BE37: 10 | BF37: 6 | BG37: 12 | BH37: 66 | BI37: 8 | BJ37: 0 | BK37: 0 | BL37: 0 | BM37: 0 | BN37: 0
A38: 48081 | B38: ZUKO 8 S NARANJA EXH | D38: 12 | E38: 677 | F38: TRESMONTES LUCHETTI (NUTRESA) | G38: 690 | H38: TRESMONTES LUCCHETTI (ZUKO) | I38: 29.5707 | J38: 354.8484 | K38: =L38*J38 -> 0 | L38: =SUM(O38+W38+S38) -> 0 | M38: 4.46 | N38: 15.08 | O38: =MAX(0,(TRUNC((M38*0.75)-N38))) -> 0 | Q38: 3.25 | R38: 6.75 | S38: 0 | U38: 6.38 | V38: 18.17 | W38: =MAX(0,(TRUNC((U38*0.75)-V38))) -> 0 | X38: 0 | Y38: 4997.45 | Z38: 14193.94 | AA38: 18 | AB38: 9 | AC38: 6 | AD38: 50 | AE38: 181 | AF38: 0 | AG38: 0 | AH38: 0 | AI38: 0 | AJ38: 0 | AK38: 0 | AL38: 0 | AM38: 0 | AN38: 0 | AO38: 0 | AP38: 0 | AQ38: 0 | AR38: 0 | AS38: 0 | AT38: 0 | AU38: 5 | AV38: 4 | AW38: 23 | AX38: 18 | AY38: 81 | AZ38: 0 | BA38: 0 | BB38: 0 | BC38: 0 | BD38: 0 | BE38: 25 | BF38: 10 | BG38: 19 | BH38: 55 | BI38: 218 | BJ38: 0 | BK38: 0 | BL38: 0 | BM38: 0 | BN38: 0
A39: 47026 | B39: CHOC MUIBON ROLL C&C 315GR/ 15 NUTRESA | C39: 1/20 | D39: 12 | E39: 677 | F39: TRESMONTES LUCHETTI (NUTRESA) | G39: 999 | H39: PRODUCTOS A ELIMINAR | I39: 48.56 | J39: 582.72 | K39: =L39*J39 -> 34963.2 | L39: =SUM(O39+W39+S39) -> 60 | M39: 0 | N39: 0 | O39: 20 | Q39: 7.08 | R39: 3.5 | S39: 20 | U39: 0 | V39: 0 | W39: 20 | X39: 0 | Y39: 4127.6 | Z39: 2039.52 | AA39: 0 | AB39: 0 | AC39: 0 | AD39: 0 | AE39: 0 | AF39: 0 | AG39: 0 | AH39: 0 | AI39: 0 | AJ39: 0 | AK39: 0 | AL39: 0 | AM39: 0 | AN39: 0 | AO39: 0 | AP39: 0 | AQ39: 0 | AR39: 0 | AS39: 0 | AT39: 0 | AU39: 67 | AV39: 36 | AW39: 0 | AX39: 0 | AY39: 42 | AZ39: 0 | BA39: 0 | BB39: 0 | BC39: 0 | BD39: 0 | BE39: 0 | BF39: 0 | BG39: 0 | BH39: 0 | BI39: 0 | BJ39: 0 | BK39: 0 | BL39: 0 | BM39: 0 | BN39: 0
A40: 48067 | B40: ZUKO 8 S LIMON EXH | D40: 12 | E40: 677 | F40: TRESMONTES LUCHETTI (NUTRESA) | G40: 690 | H40: TRESMONTES LUCCHETTI (ZUKO) | I40: 29.5707 | J40: 354.8484 | K40: =L40*J40 -> 0 | L40: =SUM(O40+W40+S40) -> 0 | M40: 3.58 | N40: 8 | O40: =MAX(0,(TRUNC((M40*0.75)-N40))) -> 0 | Q40: 3.21 | R40: 7.25 | S40: 0 | U40: 4.58 | V40: 9.92 | W40: =MAX(0,(TRUNC((U40*0.75)-V40))) -> 0 | X40: 0 | Y40: 4036.4 | Z40: 8930.35 | AA40: 22 | AB40: 5 | AC40: 6 | AD40: 25 | AE40: 96 | AF40: 0 | AG40: 0 | AH40: 0 | AI40: 0 | AJ40: 0 | AK40: 0 | AL40: 0 | AM40: 0 | AN40: 0 | AO40: 0 | AP40: 0 | AQ40: 0 | AR40: 0 | AS40: 0 | AT40: 0 | AU40: 6 | AV40: 4 | AW40: 25 | AX40: 11 | AY40: 87 | AZ40: 0 | BA40: 0 | BB40: 0 | BC40: 0 | BD40: 0 | BE40: 5 | BF40: 4 | BG40: 24 | BH40: 48 | BI40: 119 | BJ40: 0 | BK40: 0 | BL40: 0 | BM40: 0 | BN40: 0
A41: 47036 | B41: CHOC RACING BLISTER NUTRESA /56 1476 | D41: 24 | E41: 677 | F41: TRESMONTES LUCHETTI (NUTRESA) | G41: 61 | H41: NUTRESA SA DE CV | I41: 38.6661 | J41: 927.9864 | K41: =L41*J41 -> 0 | L41: =SUM(O41+W41+S41) -> 0 | M41: 2.06 | N41: 0 | O41: 0 | Q41: 1.21 | R41: 0 | S41: 0 | U41: 0.65 | V41: 0 | W41: =MAX(0,(TRUNC((U41*0.75)-V41))) -> 0 | X41: 0 | Y41: 3634.61 | Z41: 0 | AA41: 0 | AB41: 0 | AC41: 35 | AD41: 29 | AE41: 0 | AF41: 0 | AG41: 0 | AH41: 0 | AI41: 0 | AJ41: 0 | AK41: 0 | AL41: 0 | AM41: 0 | AN41: 0 | AO41: 0 | AP41: 0 | AQ41: 0 | AR41: 0 | AS41: 0 | AT41: 0 | AU41: 0 | AV41: 0 | AW41: 19 | AX41: 20 | AY41: 0 | AZ41: 0 | BA41: 0 | BB41: 0 | BC41: 0 | BD41: 0 | BE41: 0 | BF41: 0 | BG41: 11 | BH41: 9 | BI41: 0 | BJ41: 0 | BK41: 0 | BL41: 0 | BM41: 0 | BN41: 0
...

Sheet 120226
J1: =SUM(J3:J91) -> 860364.99 | K1: =SUM(K3:K91) -> 992 | N1: =SUM(N3:N91) -> 326 | R1: =SUM(R3:R91) -> 420 | U1: =SUM(U3:U91) -> 285 | V1: =X1/W1 -> 0.41499017 | W1: =SUM(W3:W91) -> 914416.64 | X1: =SUM(X3:X91) -> 379473.92
A2: Articulo | B2: Nombre | C2: UXC | D2: Subfamilia | E2: SN | F2: Categoria | G2: CN | H2: CostoCIVA | I2: CostoXCaja | J2: $Pedido | K2: SumaPedido | L2: 10VentasG | M2: 10ExistenciaG | N2: PedidoLPD | P2: 30VentasG | Q2: 30ExistenciasG | R2: PedMorelia | S2: 50VentasG | T2: 50ExistenciaG | U2: PedidoZam | V2: ExCEDIS | W2: ValorVentaG | X2: ValorExistenciaG | Y2: 10Actual15 | Z2: 10Actual30R | AA2: 10Anterior15 | AB2: 10Anterior30R | AC2: 10ExistenciaWC | AD2: 40Actual15 | AE2: 40Actual30R | AF2: 40Anterior15 | AG2: 40Anterior30R | AH2: 40ExistenciaWC | AI2: 42Actual15 | AJ2: 42Actual30R | AK2: 42Anterior15 | AL2: 42Anterior30R | AM2: 42ExistenciaWC | AN2: 44Actual15 | AO2: 44Actual30R | AP2: 44Anterior15 | AQ2: 44Anterior30R | AR2: 44ExistenciaWC | AS2: 30Actual15 | AT2: 30Actual30R | AU2: 30Anterior15 | AV2: 30Anterior30R | AW2: 30ExistenciaWC | AX2: 32Actual15 | AY2: 32Actual30R | AZ2: 32Anterior15 | BA2: 32Anterior30R | BB2: 32ExistenciaWC | BC2: 50Actual15 | BD2: 50Actual30R | BE2: 50Anterior15 | BF2: 50Anterior30R | BG2: 50ExistenciaWC | BH2: 54Actual15 | BI2: 54Actual30R | BJ2: 54Anterior15 | BK2: 54Anterior30R | BL2: 54ExistenciaWC
A3: 47005 | B3: NUCITA TRISABOR 224GR /16 NUTRESA | C3: 24 | D3: 677 | E3: TRESMONTES LUCHETTI (NUTRESA) | F3: 61 | G3: NUTRESA SA DE CV | H3: 22.316 | I3: 535.584 | J3: =K3*I3 -> 99618.624 | K3: =SUM(N3+R3+U3) -> 186 | L3: 64.69 | M3: 4.29 | N3: 66 | O3: 15ma | P3: 121.94 | Q3: 50.88 | R3: 60 | S3: 78.44 | T3: 2.67 | U3: =MAX(0,(TRUNC((S3*0.8)-T3))) -> 60 | V3: 10ma | W3: 141963.23 | X3: 42221.87 | Y3: 1038 | Z3: 231 | AA3: 399 | AB3: 0 | AC3: 103 | AD3: 0 | AE3: 0 | AF3: 0 | AG3: 0 | AH3: 0 | AI3: 0 | AJ3: 0 | AK3: 0 | AL3: 0 | AM3: 0 | AN3: 0 | AO3: 0 | AP3: 0 | AQ3: 0 | AR3: 0 | AS3: 1614 | AT3: 543 | AU3: 810 | AV3: 462 | AW3: 1725 | AX3: 0 | AY3: 0 | AZ3: 0 | BA3: 0 | BB3: 0 | BC3: 748 | BD3: 593 | BE3: 652 | BF3: 372 | BG3: 64 | BH3: 0 | BI3: 0 | BJ3: 0 | BK3: 0 | BL3: 0
A4: 47001 | B4: CHOC CREMINO BICOLOR /24 NUTRESA | C4: 16 | D4: 677 | E4: TRESMONTES LUCHETTI (NUTRESA) | F4: 61 | G4: NUTRESA SA DE CV | H4: 56.5902 | I4: 905.4432 | J4: =K4*I4 -> 165696.11 | K4: =SUM(N4+R4+U4) -> 183 | L4: 37.81 | M4: 1.06 | N4: 63 | P4: 60.28 | Q4: -0.25 | R4: 80 | S4: 38.44 | T4: 0.12 | U4: 40 | V4: 0 | W4: 114566.86 | X4: 848.85 | Y4: 0 | Z4: 178 | AA4: 365 | AB4: 302 | AC4: 17 | AD4: 0 | AE4: 0 | AF4: 0 | AG4: 0 | AH4: 0 | AI4: 0 | AJ4: 0 | AK4: 0 | AL4: 0 | AM4: 0 | AN4: 0 | AO4: 0 | AP4: 0 | AQ4: 0 | AR4: 0 | AS4: 162 | AT4: 402 | AU4: 322 | AV4: 239 | AW4: -4 | AX4: 0 | AY4: 0 | AZ4: 0 | BA4: 0 | BB4: 0 | BC4: 56 | BD4: 138 | BE4: 398 | BF4: 184 | BG4: 2 | BH4: 0 | BI4: 0 | BJ4: 0 | BK4: 0 | BL4: 0
A5: 47010 | B5: CHOC MUIBON AVELLANAS /15 NUTRESA 9055 | C5: 24 | D5: 677 | E5: TRESMONTES LUCHETTI (NUTRESA) | F5: 61 | G5: NUTRESA SA DE CV | H5: 48.56 | I5: 1165.44 | J5: =K5*I5 -> 83911.68 | K5: =SUM(N5+R5+U5) -> 72 | L5: 15.1 | M5: 2.08 | N5: 22 | P5: 26.75 | Q5: 0 | R5: 30 | S5: 20.9 | T5: 1.25 | U5: 20 | V5: 0 | W5: 73131.36 | X5: 3884.8 | Y5: 3 | Z5: 72 | AA5: 268 | AB5: 111 | AC5: 50 | AD5: 0 | AE5: 0 | AF5: 0 | AG5: 0 | AH5: 0 | AI5: 0 | AJ5: 0 | AK5: 0 | AL5: 0 | AM5: 0 | AN5: 0 | AO5: 0 | AP5: 0 | AQ5: 0 | AR5: 0 | AS5: 113 | AT5: 195 | AU5: 313 | AV5: 237 | AW5: 0 | AX5: 0 | AY5: 0 | AZ5: 0 | BA5: 0 | BB5: 0 | BC5: 182 | BD5: 170 | BE5: 234 | BF5: 1 | BG5: 30 | BH5: 0 | BI5: 0 | BJ5: 0 | BK5: 0 | BL5: 0
A6: 47012 | B6: CHOC MONEDA EXH /48 NUTRESA 1432 | C6: 18 | D6: 677 | E6: TRESMONTES LUCHETTI (NUTRESA) | F6: 61 | G6: NUTRESA SA DE CV | H6: 58.8379 | I6: 1059.0822 | J6: =K6*I6 -> 84726.576 | K6: =SUM(N6+R6+U6) -> 80 | L6: 18.81 | M6: 5.72 | N6: 10 | P6: 22.39 | Q6: 0.06 | R6: 50 | S6: 24.44 | T6: 9.56 | U6: 20 | V6: 0 | W6: 69516.98 | X6: 16239.26 | Y6: 102 | Z6: 100 | AA6: 136 | AB6: 101 | AC6: 103 | AD6: 0 | AE6: 0 | AF6: 0 | AG6: 0 | AH6: 0 | AI6: 0 | AJ6: 0 | AK6: 0 | AL6: 0 | AM6: 0 | AN6: 0 | AO6: 0 | AP6: 0 | AQ6: 0 | AR6: 0 | AS6: 13 | AT6: 309 | AU6: 190 | AV6: 91 | AW6: 1 | AX6: 0 | AY6: 0 | AZ6: 0 | BA6: 0 | BB6: 0 | BC6: 197 | BD6: 222 | BE6: 86 | BF6: 92 | BG6: 172 | BH6: 0 | BI6: 0 | BJ6: 0 | BK6: 0 | BL6: 0
A7: 47046 | B7: NUCITA PATITAS (152G) / 8 NUTRESA | C7: 24 | D7: 677 | E7: TRESMONTES LUCHETTI (NUTRESA) | F7: 61 | G7: NUTRESA SA DE CV | H7: 39.11 | I7: 938.64 | J7: =K7*I7 -> 18772.8 | K7: =SUM(N7+R7+U7) -> 20 | L7: 13.71 | M7: 40.25 | N7: =MAX(0,(TRUNC((L7*0.8)-M7))) -> 0 | P7: 22.52 | Q7: 0.08 | R7: 20 | S7: 28.62 | T7: 31.21 | U7: =MAX(0,(TRUNC((S7*0.8)-T7))) -> 0 | V7: 0 | W7: 60874.72 | X7: 67151.87 | Y7: 84 | Z7: 119 | AA7: 144 | AB7: 83 | AC7: 966 | AD7: 0 | AE7: 0 | AF7: 0 | AG7: 0 | AH7: 0 | AI7: 0 | AJ7: 0 | AK7: 0 | AL7: 0 | AM7: 0 | AN7: 0 | AO7: 0 | AP7: 0 | AQ7: 0 | AR7: 0 | AS7: 121 | AT7: 270 | AU7: 198 | AV7: 173 | AW7: 2 | AX7: 0 | AY7: 0 | AZ7: 0 | BA7: 0 | BB7: 0 | BC7: 245 | BD7: 262 | BE7: 248 | BF7: 126 | BG7: 749 | BH7: 0 | BI7: 0 | BJ7: 0 | BK7: 0 | BL7: 0
A8: 47039 | B8: NUCITA TRISABOR CONFITES NUTRESA/12 5868 | C8: 24 | D8: 677 | E8: TRESMONTES LUCHETTI (NUTRESA) | F8: 61 | G8: NUTRESA SA DE CV | H8: 52.259 | I8: 1254.216 | J8: =K8*I8 -> 56439.72 | K8: =SUM(N8+R8+U8) -> 45 | L8: 4.77 | M8: 0.04 | N8: 10 | P8: 18.35 | Q8: 3.25 | R8: 15 | S8: 18.29 | T8: 0 | U8: 20 | V8: 0 | W8: 51945.45 | X8: 4128.46 | Y8: 8 | Z8: 47 | AA8: 83 | AB8: 0 | AC8: 1 | AD8: 0 | AE8: 0 | AF8: 0 | AG8: 0 | AH8: 0 | AI8: 0 | AJ8: 0 | AK8: 0 | AL8: 0 | AM8: 0 | AN8: 0 | AO8: 0 | AP8: 0 | AQ8: 0 | AR8: 0 | AS8: 123 | AT8: 112 | AU8: 207 | AV8: 109 | AW8: 78 | AX8: 0 | AY8: 0 | AZ8: 0 | BA8: 0 | BB8: 0 | BC8: 173 | BD8: 71 | BE8: 184 | BF8: 93 | BG8: 0 | BH8: 0 | BI8: 0 | BJ8: 0 | BK8: 0 | BL8: 0
A9: 47023 | B9: EXH CHOC CREMINO BICOLORE NUTRESA /50 | C9: 8 | D9: 677 | E9: TRESMONTES LUCHETTI (NUTRESA) | F9: 61 | G9: NUTRESA SA DE CV | H9: 105.55 | I9: 844.4 | J9: =K9*I9 -> 67552 | K9: =SUM(N9+R9+U9) -> 80 | L9: 17.94 | M9: 0.38 | N9: 20 | P9: 29.75 | Q9: 0.12 | R9: 40 | S9: 12.88 | T9: -5 | U9: 20 | V9: 0 | W9: 51138.98 | X9: -3799.8 | Y9: 58 | Z9: 107 | AA9: 32 | AB9: 0 | AC9: 3 | AD9: 0 | AE9: 0 | AF9: 0 | AG9: 0 | AH9: 0 | AI9: 0 | AJ9: 0 | AK9: 0 | AL9: 0 | AM9: 0 | AN9: 0 | AO9: 0 | AP9: 0 | AQ9: 0 | AR9: 0 | AS9: 23 | AT9: 120 | AU9: 89 | AV9: 132 | AW9: 1 | AX9: 0 | AY9: 0 | AZ9: 0 | BA9: 0 | BB9: 0 | BC9: 57 | BD9: 84 | BE9: 4 | BF9: 0 | BG9: -40 | BH9: 0 | BI9: 0 | BJ9: 0 | BK9: 0 | BL9: 0
A10: 47000 | B10: CHOC CREMINO BLANCO /24 NUTRESA 2256 | C10: 16 | D10: 677 | E10: TRESMONTES LUCHETTI (NUTRESA) | F10: 61 | G10: NUTRESA SA DE CV | H10: 56.59 | I10: 905.44 | J10: =K10*I10 -> 37123.04 | K10: =SUM(N10+R10+U10) -> 41 | L10: 15.91 | M10: -1.12 | N10: 21 | P10: 26.94 | Q10: 25.31 | R10: 20 | S10: 12.91 | T10: 15.88 | U10: =MAX(0,(TRUNC((S10*0.8)-T10))) -> 0 | V10: 0 | W10: 50478.28 | X10: 36274.19 | Y10: 111 | Z10: 66 | AA10: 87 | AB10: 47 | AC10: -18 | AD10: 0 | AE10: 0 | AF10: 0 | AG10: 0 | AH10: 0 | AI10: 0 | AJ10: 0 | AK10: 0 | AL10: 0 | AM10: 0 | AN10: 0 | AO10: 0 | AP10: 0 | AQ10: 0 | AR10: 0 | AS10: 123 | AT10: 152 | AU10: 165 | AV10: 134 | AW10: 405 | AX10: 0 | AY10: 0 | AZ10: 0 | BA10: 0 | BB10: 0 | BC10: 54 | BD10: 67 | BE10: 59 | BF10: 120 | BG10: 254 | BH10: 0 | BI10: 0 | BJ10: 0 | BK10: 0 | BL10: 0
A11: 47004 | B11: NUCITA FRESA Y CHOCOLATE 224GR /16 NUTRESA | C11: 24 | D11: 677 | E11: TRESMONTES LUCHETTI (NUTRESA) | F11: 61 | G11: NUTRESA SA DE CV | H11: 22.316 | I11: 535.584 | J11: =K11*I11 -> 0 | K11: =SUM(N11+R11+U11) -> 0 | L11: 20.69 | M11: 4.25 | N11: 0 | O11: 20zam | P11: 31.65 | Q11: 18.75 | R11: 0 | S11: 21.23 | T11: 68.67 | U11: =MAX(0,(TRUNC((S11*0.8)-T11))) -> 0 | V11: 0 | W11: 39398.9 | X11: 49095.2 | Y11: 204 | Z11: 129 | AA11: 228 | AB11: 0 | AC11: 102 | AD11: 0 | AE11: 0 | AF11: 0 | AG11: 0 | AH11: 0 | AI11: 0 | AJ11: 0 | AK11: 0 | AL11: 0 | AM11: 0 | AN11: 0 | AO11: 0 | AP11: 0 | AQ11: 0 | AR11: 0 | AS11: 438 | AT11: 244 | AU11: 116 | AV11: 167 | AW11: 450 | AX11: 0 | AY11: 0 | AZ11: 0 | BA11: 0 | BB11: 0 | BC11: 237 | BD11: 110 | BE11: 172 | BF11: 91 | BG11: 1648 | BH11: 0 | BI11: 0 | BJ11: 0 | BK11: 0 | BL11: 0
A12: 47002 | B12: NUCITA VAINILLA Y CHOCOLATE 240GR /16 NUTRES 78 | C12: 24 | D12: 677 | E12: TRESMONTES LUCHETTI (NUTRESA) | F12: 61 | G12: NUTRESA SA DE CV | H12: 22.316 | I12: 535.584 | J12: =K12*I12 -> 22494.528 | K12: =SUM(N12+R12+U12) -> 42 | L12: 22.73 | M12: 4.88 | N12: 22 | P12: 29.29 | Q12: 29.12 | R12: 0 | S12: 17.65 | T12: 8.75 | U12: 20 | V12: 0 | W12: 37312.35 | X12: 22896.22 | Y12: 334 | Z12: 95 | AA12: 164 | AB12: 0 | AC12: 117 | AD12: 0 | AE12: 0 | AF12: 0 | AG12: 0 | AH12: 0 | AI12: 0 | AJ12: 0 | AK12: 0 | AL12: 0 | AM12: 0 | AN12: 0 | AO12: 0 | AP12: 0 | AQ12: 0 | AR12: 0 | AS12: 394 | AT12: 115 | AU12: 217 | AV12: 69 | AW12: 699 | AX12: 0 | AY12: 0 | AZ12: 0 | BA12: 0 | BB12: 0 | BC12: 238 | BD12: 94 | BE12: 114 | BF12: 49 | BG12: 210 | BH12: 0 | BI12: 0 | BJ12: 0 | BK12: 0 | BL12: 0
A13: 47038 | B13: CREMINO STICK 140GR/ 20 NUTRESA | C13: 28 | D13: 677 | E13: TRESMONTES LUCHETTI (NUTRESA) | F13: 61 | G13: NUTRESA SA DE CV | H13: 26.59 | I13: 744.52 | J13: =K13*I13 -> 22335.6 | K13: =SUM(N13+R13+U13) -> 30 | L13: 5.38 | M13: 0.04 | N13: 10 | P13: 21.14 | Q13: 23.93 | R13: 0 | S13: 23.05 | T13: 1.29 | U13: 20 | V13: 0 | W13: 36906.92 | X13: 18799.13 | Y13: 0 | Z13: 0 | AA13: 116 | AB13: 69 | AC13: 1 | AD13: 0 | AE13: 0 | AF13: 0 | AG13: 0 | AH13: 0 | AI13: 0 | AJ13: 0 | AK13: 0 | AL13: 0 | AM13: 0 | AN13: 0 | AO13: 0 | AP13: 0 | AQ13: 0 | AR13: 0 | AS13: 131 | AT13: 118 | AU13: 322 | AV13: 160 | AW13: 670 | AX13: 0 | AY13: 0 | AZ13: 0 | BA13: 0 | BB13: 0 | BC13: 139 | BD13: 225 | BE13: 375 | BF13: 38 | BG13: 36 | BH13: 0 | BI13: 0 | BJ13: 0 | BK13: 0 | BL13: 0
A14: 47003 | B14: NUCITA FRESA/VAINILLLA /16 NUTRESA | C14: 24 | D14: 677 | E14: TRESMONTES LUCHETTI (NUTRESA) | F14: 61 | G14: NUTRESA SA DE CV | H14: 22.316 | I14: 535.584 | J14: =K14*I14 -> 11782.848 | K14: =SUM(N14+R14+U14) -> 22 | L14: 18.96 | M14: 4.38 | N14: 22 | O14: 10zam | P14: 33.75 | Q14: 23.25 | R14: 0 | S14: 15 | T14: 44.92 | U14: =MAX(0,(TRUNC((S14*0.8)-T14))) -> 0 | V14: 0 | W14: 36263.5 | X14: 38852.16 | Y14: 351 | Z14: 96 | AA14: 56 | AB14: 0 | AC14: 105 | AD14: 0 | AE14: 0 | AF14: 0 | AG14: 0 | AH14: 0 | AI14: 0 | AJ14: 0 | AK14: 0 | AL14: 0 | AM14: 0 | AN14: 0 | AO14: 0 | AP14: 0 | AQ14: 0 | AR14: 0 | AS14: 530 | AT14: 85 | AU14: 216 | AV14: 43 | AW14: 558 | AX14: 0 | AY14: 0 | AZ14: 0 | BA14: 0 | BB14: 0 | BC14: 171 | BD14: 134 | BE14: 92 | BF14: 60 | BG14: 1078 | BH14: 0 | BI14: 0 | BJ14: 0 | BK14: 0 | BL14: 0
A15: 10703 | B15: VIT CHOC MONEDA 708g /120 NUTRESA | C15: 12 | D15: 677 | E15: TRESMONTES LUCHETTI (NUTRESA) | F15: 542 | G15: DISPONIBLE | H15: 125.581 | I15: 1506.972 | J15: =K15*I15 -> 45209.16 | K15: =SUM(N15+R15+U15) -> 30 | L15: 0 | M15: -0.25 | N15: 10 | P15: 3.04 | Q15: 0 | R15: 10 | S15: 10.54 | T15: 0 | U15: 10 | V15: 0 | W15: 20469.7 | X15: -376.74 | Y15: 0 | Z15: 0 | AA15: 0 | AB15: 0 | AC15: -3 | AD15: 0 | AE15: 0 | AF15: 0 | AG15: 0 | AH15: 0 | AI15: 0 | AJ15: 0 | AK15: 0 | AL15: 0 | AM15: 0 | AN15: 0 | AO15: 0 | AP15: 0 | AQ15: 0 | AR15: 0 | AS15: 0 | AT15: 0 | AU15: 28 | AV15: 17 | AW15: 0 | AX15: 0 | AY15: 0 | AZ15: 0 | BA15: 0 | BB15: 0 | BC15: 26 | BD15: 43 | BE15: 60 | BF15: 38 | BG15: 0 | BH15: 0 | BI15: 0 | BJ15: 0 | BK15: 0 | BL15: 0
A16: 47008 | B16: CHOC NUCITA BARRA /16 NUTRESA 1471 | C16: 24 | D16: 677 | E16: TRESMONTES LUCHETTI (NUTRESA) | F16: 61 | G16: NUTRESA SA DE CV | H16: 35.74 | I16: 857.76 | J16: =K16*I16 -> 30021.6 | K16: =SUM(N16+R16+U16) -> 35 | L16: 2.85 | M16: 0.5 | N16: 5 | P16: 9.06 | Q16: 0 | R16: 20 | S16: 8.79 | T16: 0 | U16: 10 | V16: 0 | W16: 17762.78 | X16: 428.88 | Y16: 0 | Z16: 0 | AA16: 68 | AB16: 1 | AC16: 12 | AD16: 0 | AE16: 0 | AF16: 0 | AG16: 0 | AH16: 0 | AI16: 0 | AJ16: 0 | AK16: 0 | AL16: 0 | AM16: 0 | AN16: 0 | AO16: 0 | AP16: 0 | AQ16: 0 | AR16: 0 | AS16: 0 | AT16: 0 | AU16: 155 | AV16: 125 | AW16: 0 | AX16: 0 | AY16: 0 | AZ16: 0 | BA16: 0 | BB16: 0 | BC16: 18 | BD16: 94 | BE16: 119 | BF16: 54 | BG16: 0 | BH16: 0 | BI16: 0 | BJ16: 0 | BK16: 0 | BL16: 0
A17: 47029 | B17: NUCITA TRIANG TRISABOR /12 NUTRESA 2694 | C17: 24 | D17: 677 | E17: TRESMONTES LUCHETTI (NUTRESA) | F17: 61 | G17: NUTRESA SA DE CV | H17: 41.26 | I17: 990.24 | J17: =K17*I17 -> 19804.8 | K17: =SUM(N17+R17+U17) -> 20 | L17: 5.77 | M17: -0.04 | N17: 5 | P17: 6.77 | Q17: 0.92 | R17: 10 | S17: 5.04 | T17: 0.67 | U17: 5 | V17: 0 | W17: 17411.72 | X17: 1526.62 | Y17: 0 | Z17: 15 | AA17: 99 | AB17: 64 | AC17: -1 | AD17: 0 | AE17: 0 | AF17: 0 | AG17: 0 | AH17: 0 | AI17: 0 | AJ17: 0 | AK17: 0 | AL17: 0 | AM17: 0 | AN17: 0 | AO17: 0 | AP17: 0 | AQ17: 0 | AR17: 0 | AS17: 33 | AT17: 81 | AU17: 73 | AV17: 32 | AW17: 22 | AX17: 0 | AY17: 0 | AZ17: 0 | BA17: 0 | BB17: 0 | BC17: 45 | BD17: 51 | BE17: 37 | BF17: 27 | BG17: 16 | BH17: 0 | BI17: 0 | BJ17: 0 | BK17: 0 | BL17: 0
A18: 47024 | B18: CHOC BALONCITOS NUTRESA /200 | C18: 12 | D18: 677 | E18: TRESMONTES LUCHETTI (NUTRESA) | F18: 61 | G18: NUTRESA SA DE CV | H18: 135.39 | I18: 1624.68 | J18: =K18*I18 -> 24370.2 | K18: =SUM(N18+R18+U18) -> 15 | L18: 0.25 | M18: -0.08 | N18: 5 | P18: 5.88 | Q18: 1.92 | R18: 5 | S18: 4.33 | T18: 0 | U18: 5 | V18: 0 | W18: 16991.44 | X18: 2978.58 | Y18: 0 | Z18: 6 | AA18: 0 | AB18: 0 | AC18: -1 | AD18: 0 | AE18: 0 | AF18: 0 | AG18: 0 | AH18: 0 | AI18: 0 | AJ18: 0 | AK18: 0 | AL18: 0 | AM18: 0 | AN18: 0 | AO18: 0 | AP18: 0 | AQ18: 0 | AR18: 0 | AS18: 29 | AT18: 24 | AU18: 18 | AV18: 23 | AW18: 23 | AX18: 0 | AY18: 0 | AZ18: 0 | BA18: 0 | BB18: 0 | BC18: 0 | BD18: 4 | BE18: 37 | BF18: 26 | BG18: 0 | BH18: 0 | BI18: 0 | BJ18: 0 | BK18: 0 | BL18: 0
A19: 47014 | B19: CHOC BALONES BLISTER/56 NUTRESA 1398 | C19: 24 | D19: 677 | E19: TRESMONTES LUCHETTI (NUTRESA) | F19: 61 | G19: NUTRESA SA DE CV | H19: 43.3191 | I19: 1039.6584 | J19: =K19*I19 -> 10396.584 | K19: =SUM(N19+R19+U19) -> 10 | L19: 3 | M19: 0.08 | N19: 5 | P19: 4.9 | Q19: 2.5 | R19: 5 | S19: 3.5 | T19: 3.21 | U19: =MAX(0,(TRUNC((S19*0.8)-T19))) -> 0 | V19: 0 | W19: 11847.77 | X19: 6021.35 | Y19: 33 | Z19: 14 | AA19: 20 | AB19: 24 | AC19: 2 | AD19: 0 | AE19: 0 | AF19: 0 | AG19: 0 | AH19: 0 | AI19: 0 | AJ19: 0 | AK19: 0 | AL19: 0 | AM19: 0 | AN19: 0 | AO19: 0 | AP19: 0 | AQ19: 0 | AR19: 0 | AS19: 30 | AT19: 67 | AU19: 39 | AV19: 30 | AW19: 60 | AX19: 0 | AY19: 0 | AZ19: 0 | BA19: 0 | BB19: 0 | BC19: 29 | BD19: 23 | BE19: 40 | BF19: 7 | BG19: 77 | BH19: 0 | BI19: 0 | BJ19: 0 | BK19: 0 | BL19: 0
A20: 48084 | B20: ZUKO 8 S HORCHATA EXH | C20: 12 | D20: 677 | E20: TRESMONTES LUCHETTI (NUTRESA) | F20: 690 | G20: TRESMONTES LUCCHETTI (ZUKO) | H20: 29.5707 | I20: 354.8484 | J20: =K20*I20 -> 0 | K20: 0 | L20: 8.5 | M20: 4.83 | N20: =MAX(0,(TRUNC((L20*0.8)-M20))) -> 1 | P20: 4.67 | Q20: 3.58 | R20: 3 | S20: 10.5 | T20: 11.83 | U20: =MAX(0,(TRUNC((S20*0.8)-T20))) -> 0 | V20: 0 | W20: 8398.08 | X20: 7185.68 | Y20: 32 | Z20: 32 | AA20: 49 | AB20: 10 | AC20: 58 | AD20: 0 | AE20: 0 | AF20: 0 | AG20: 0 | AH20: 0 | AI20: 0 | AJ20: 0 | AK20: 0 | AL20: 0 | AM20: 0 | AN20: 0 | AO20: 0 | AP20: 0 | AQ20: 0 | AR20: 0 | AS20: 14 | AT20: 17 | AU20: 30 | AV20: 7 | AW20: 43 | AX20: 0 | AY20: 0 | AZ20: 0 | BA20: 0 | BB20: 0 | BC20: 33 | BD20: 21 | BE20: 69 | BF20: 27 | BG20: 142 | BH20: 0 | BI20: 0 | BJ20: 0 | BK20: 0 | BL20: 0
A21: 48091 | B21: ZUKO 8 S JAMAICA EXH | C21: 12 | D21: 677 | E21: TRESMONTES LUCHETTI (NUTRESA) | F21: 690 | G21: TRESMONTES LUCCHETTI (ZUKO) | H21: 29.5707 | I21: 354.8484 | J21: =K21*I21 -> 0 | K21: 0 | L21: 7.08 | M21: 8.42 | N21: =MAX(0,(TRUNC((L21*0.8)-M21))) -> 0 | P21: 5.25 | Q21: 3 | R21: 3 | S21: 10.42 | T21: 17.92 | U21: =MAX(0,(TRUNC((S21*0.8)-T21))) -> 0 | V21: 0 | W21: 8072.8 | X21: 10408.89 | Y21: 16 | Z21: 23 | AA21: 56 | AB21: 3 | AC21: 101 | AD21: 0 | AE21: 0 | AF21: 0 | AG21: 0 | AH21: 0 | AI21: 0 | AJ21: 0 | AK21: 0 | AL21: 0 | AM21: 0 | AN21: 0 | AO21: 0 | AP21: 0 | AQ21: 0 | AR21: 0 | AS21: 22 | AT21: 24 | AU21: 29 | AV21: 0 | AW21: 36 | AX21: 0 | AY21: 0 | AZ21: 0 | BA21: 0 | BB21: 0 | BC21: 20 | BD21: 20 | BE21: 95 | BF21: 0 | BG21: 215 | BH21: 0 | BI21: 0 | BJ21: 0 | BK21: 0 | BL21: 0
A22: 48081 | B22: ZUKO 8 S NARANJA EXH | C22: 12 | D22: 677 | E22: TRESMONTES LUCHETTI (NUTRESA) | F22: 690 | G22: TRESMONTES LUCCHETTI (ZUKO) | H22: 29.5707 | I22: 354.8484 | J22: =K22*I22 -> 0 | K22: 0 | L22: 4.62 | M22: 11.5 | N22: =MAX(0,(TRUNC((L22*0.8)-M22))) -> 0 | P22: 3.46 | Q22: 5.75 | R22: 0 | S22: 9.5 | T22: 15.92 | U22: =MAX(0,(TRUNC((S22*0.8)-T22))) -> 0 | V22: 0 | W22: 6239.42 | X22: 11769.14 | Y22: 16 | Z22: 15 | AA22: 32 | AB22: 0 | AC22: 138 | AD22: 0 | AE22: 0 | AF22: 0 | AG22: 0 | AH22: 0 | AI22: 0 | AJ22: 0 | AK22: 0 | AL22: 0 | AM22: 0 | AN22: 0 | AO22: 0 | AP22: 0 | AQ22: 0 | AR22: 0 | AS22: 10 | AT22: 7 | AU22: 20 | AV22: 16 | AW22: 69 | AX22: 0 | AY22: 0 | AZ22: 0 | BA22: 0 | BB22: 0 | BC22: 20 | BD22: 28 | BE22: 58 | BF22: 44 | BG22: 191 | BH22: 0 | BI22: 0 | BJ22: 0 | BK22: 0 | BL22: 0
A23: 48085 | B23: ZUKO 8 S FRESA EXH | C23: 12 | D23: 677 | E23: TRESMONTES LUCHETTI (NUTRESA) | F23: 690 | G23: TRESMONTES LUCCHETTI (ZUKO) | H23: 29.5707 | I23: 354.8484 | J23: =K23*I23 -> 0 | K23: 0 | L23: 5.21 | M23: 2.33 | N23: 3 | P23: 3.12 | Q23: 2.67 | R23: 3 | S23: 7.62 | T23: 0 | U23: 10 | V23: 0 | W23: 5662.79 | X23: 1774.24 | Y23: 12 | Z23: 11 | AA23: 45 | AB23: 0 | AC23: 28 | AD23: 0 | AE23: 0 | AF23: 0 | AG23: 0 | AH23: 0 | AI23: 0 | AJ23: 0 | AK23: 0 | AL23: 0 | AM23: 0 | AN23: 0 | AO23: 0 | AP23: 0 | AQ23: 0 | AR23: 0 | AS23: 5 | AT23: 7 | AU23: 19 | AV23: 20 | AW23: 32 | AX23: 0 | AY23: 0 | AZ23: 0 | BA23: 0 | BB23: 0 | BC23: 4 | BD23: 9 | BE23: 68 | BF23: 30 | BG23: 0 | BH23: 0 | BI23: 0 | BJ23: 0 | BK23: 0 | BL23: 0
A24: 48067 | B24: ZUKO 8 S LIMON EXH | C24: 12 | D24: 677 | E24: TRESMONTES LUCHETTI (NUTRESA) | F24: 690 | G24: TRESMONTES LUCCHETTI (ZUKO) | H24: 29.5707 | I24: 354.8484 | J24: =K24*I24 -> 0 | K24: 0 | L24: 5.38 | M24: 2.25 | N24: 0 | O24: 2ma | P24: 2.79 | Q24: 6.5 | R24: 0 | S24: 6.38 | T24: 7.92 | U24: =MAX(0,(TRUNC((S24*0.8)-T24))) -> 0 | V24: 0 | W24: 5160.09 | X24: 5914.14 | Y24: 19 | Z24: 17 | AA24: 27 | AB24: 20 | AC24: 27 | AD24: 0 | AE24: 0 | AF24: 0 | AG24: 0 | AH24: 0 | AI24: 0 | AJ24: 0 | AK24: 0 | AL24: 0 | AM24: 0 | AN24: 0 | AO24: 0 | AP24: 0 | AQ24: 0 | AR24: 0 | AS24: 6 | AT24: 5 | AU24: 16 | AV24: 18 | AW24: 78 | AX24: 0 | AY24: 0 | AZ24: 0 | BA24: 0 | BB24: 0 | BC24: 20 | BD24: 9 | BE24: 49 | BF24: 6 | BG24: 95 | BH24: 0 | BI24: 0 | BJ24: 0 | BK24: 0 | BL24: 0
A25: 48068 | B25: ZUKO 8 S TAMARINDO EXH | C25: 12 | D25: 677 | E25: TRESMONTES LUCHETTI (NUTRESA) | F25: 690 | G25: TRESMONTES LUCCHETTI (ZUKO) | H25: 29.5707 | I25: 354.8484 | J25: =K25*I25 -> 0 | K25: 0 | L25: 2.38 | M25: 0.58 | N25: 5 | P25: 2.96 | Q25: 2.08 | R25: 3 | S25: 3.71 | T25: 0 | U25: 5 | V25: 0 | W25: 3208.42 | X25: 946.26 | Y25: 9 | Z25: 3 | AA25: 18 | AB25: 0 | AC25: 7 | AD25: 0 | AE25: 0 | AF25: 0 | AG25: 0 | AH25: 0 | AI25: 0 | AJ25: 0 | AK25: 0 | AL25: 0 | AM25: 0 | AN25: 0 | AO25: 0 | AP25: 0 | AQ25: 0 | AR25: 0 | AS25: 6 | AT25: 5 | AU25: 19 | AV25: 16 | AW25: 25 | AX25: 0 | AY25: 0 | AZ25: 0 | BA25: 0 | BB25: 0 | BC25: 0 | BD25: 0 | BE25: 35 | BF25: 19 | BG25: 0 | BH25: 0 | BI25: 0 | BJ25: 0 | BK25: 0 | BL25: 0
A26: 48069 | B26: ZUKO 8 S MANGO EXH | C26: 12 | D26: 677 | E26: TRESMONTES LUCHETTI (NUTRESA) | F26: 690 | G26: TRESMONTES LUCCHETTI (ZUKO) | H26: 29.5707 | I26: 354.8484 | J26: =K26*I26 -> 0 | K26: 0 | L26: 2.33 | M26: 2.58 | N26: =MAX(0,(TRUNC((L26*0.8)-M26))) -> 0 | P26: 3.54 | Q26: 2.25 | R26: 0 | S26: 3.12 | T26: 7.42 | U26: =MAX(0,(TRUNC((S26*0.8)-T26))) -> 0 | V26: 0 | W26: 3193.64 | X26: 4346.89 | Y26: 10 | Z26: 8 | AA26: 14 | AB26: 0 | AC26: 31 | AD26: 0 | AE26: 0 | AF26: 0 | AG26: 0 | AH26: 0 | AI26: 0 | AJ26: 0 | AK26: 0 | AL26: 0 | AM26: 0 | AN26: 0 | AO26: 0 | AP26: 0 | AQ26: 0 | AR26: 0 | AS26: 4 | AT26: 8 | AU26: 28 | AV26: 13 | AW26: 27 | AX26: 0 | AY26: 0 | AZ26: 0 | BA26: 0 | BB26: 0 | BC26: 10 | BD26: 3 | BE26: 15 | BF26: 22 | BG26: 89 | BH26: 0 | BI26: 0 | BJ26: 0 | BK26: 0 | BL26: 0
A27: 48029 | B27: ZUKO 8 S UVA EXH | C27: 12 | D27: 677 | E27: TRESMONTES LUCHETTI (NUTRESA) | F27: 690 | G27: TRESMONTES LUCCHETTI (ZUKO) | H27: 29.5707 | I27: 354.8484 | J27: =K27*I27 -> 0 | K27: 0 | L27: 1.83 | M27: 4.67 | N27: =MAX(0,(TRUNC((L27*0.8)-M27))) -> 0 | P27: 2.21 | Q27: 3.33 | R27: 0 | S27: 4.25 | T27: 2.58 | U27: =MAX(0,(TRUNC((S27*0.8)-T27))) -> 0 | V27: 0 | W27: 2942.28 | X27: 3755.48 | Y27: 5 | Z27: 4 | AA27: 12 | AB27: 6 | AC27: 56 | AD27: 0 | AE27: 0 | AF27: 0 | AG27: 0 | AH27: 0 | AI27: 0 | AJ27: 0 | AK27: 0 | AL27: 0 | AM27: 0 | AN27: 0 | AO27: 0 | AP27: 0 | AQ27: 0 | AR27: 0 | AS27: 6 | AT27: 3 | AU27: 11 | AV27: 16 | AW27: 40 | AX27: 0 | AY27: 0 | AZ27: 0 | BA27: 0 | BB27: 0 | BC27: 14 | BD27: 5 | BE27: 21 | BF27: 27 | BG27: 31 | BH27: 0 | BI27: 0 | BJ27: 0 | BK27: 0 | BL27: 0
A28: 48082 | B28: ZUKO 8 S PIÑA EXH | C28: 12 | D28: 677 | E28: TRESMONTES LUCHETTI (NUTRESA) | F28: 690 | G28: TRESMONTES LUCCHETTI (ZUKO) | H28: 29.5707 | I28: 354.8484 | J28: =K28*I28 -> 0 | K28: 0 | L28: 4.17 | M28: -0.5 | N28: 0 | O28: 3zam | P28: 0.79 | Q28: 0 | R28: 3 | S28: 2.96 | T28: 8.33 | U28: =MAX(0,(TRUNC((S28*0.8)-T28))) -> 0 | V28: 0 | W28: 2809.22 | X28: 2779.65 | Y28: 25 | Z28: 20 | AA28: 15 | AB28: 0 | AC28: -6 | AD28: 0 | AE28: 0 | AF28: 0 | AG28: 0 | AH28: 0 | AI28: 0 | AJ28: 0 | AK28: 0 | AL28: 0 | AM28: 0 | AN28: 0 | AO28: 0 | AP28: 0 | AQ28: 0 | AR28: 0 | AS28: 0 | AT28: 0 | AU28: 9 | AV28: 1 | AW28: 0 | AX28: 0 | AY28: 0 | AZ28: 0 | BA28: 0 | BB28: 0 | BC28: 2 | BD28: 11 | BE28: 15 | BF28: 26 | BG28: 100 | BH28: 0 | BI28: 0 | BJ28: 0 | BK28: 0 | BL28: 0
A29: 48058 | B29: ZUKO 8 S MELON EXH | C29: 12 | D29: 677 | E29: TRESMONTES LUCHETTI (NUTRESA) | F29: 690 | G29: TRESMONTES LUCCHETTI (ZUKO) | H29: 29.5707 | I29: 354.8484 | J29: =K29*I29 -> 0 | K29: =SUM(N29+R29+U29) -> 0 | L29: 1.92 | M29: 4.25 | N29: =MAX(0,(TRUNC((L29*0.8)-M29))) -> 0 | P29: 2.33 | Q29: 3.25 | R29: 0 | S29: 3.29 | T29: 3.92 | U29: =MAX(0,(TRUNC((S29*0.8)-T29))) -> 0 | V29: 0 | W29: 2676.15 | X29: 4051.19 | Y29: 7 | Z29: 8 | AA29: 10 | AB29: 4 | AC29: 51 | AD29: 0 | AE29: 0 | AF29: 0 | AG29: 0 | AH29: 0 | AI29: 0 | AJ29: 0 | AK29: 0 | AL29: 0 | AM29: 0 | AN29: 0 | AO29: 0 | AP29: 0 | AQ29: 0 | AR29: 0 | AS29: 1 | AT29: 0 | AU29: 20 | AV29: 14 | AW29: 39 | AX29: 0 | AY29: 0 | AZ29: 0 | BA29: 0 | BB29: 0 | BC29: 10 | BD29: 3 | BE29: 26 | BF29: 4 | BG29: 47 | BH29: 0 | BI29: 0 | BJ29: 0 | BK29: 0 | BL29: 0
A30: 47036 | B30: CHOC RACING BLISTER NUTRESA /56 1476 | C30: 24 | D30: 677 | E30: TRESMONTES LUCHETTI (NUTRESA) | F30: 61 | G30: NUTRESA SA DE CV | H30: 38.6661 | I30: 927.9864 | J30: =K30*I30 -> 0 | K30: =SUM(N30+R30+U30) -> 0 | L30: 1.23 | M30: 0 | N30: =MAX(0,(TRUNC((L30*0.8)-M30))) -> 0 | P30: 1.02 | Q30: 0 | R30: 0 | S30: 0.54 | T30: 0 | U30: =MAX(0,(TRUNC((S30*0.8)-T30))) -> 0 | V30: 0 | W30: 2590.63 | X30: 0 | Y30: 0 | Z30: 0 | AA30: 28 | AB30: 3 | AC30: 0 | AD30: 0 | AE30: 0 | AF30: 0 | AG30: 0 | AH30: 0 | AI30: 0 | AJ30: 0 | AK30: 0 | AL30: 0 | AM30: 0 | AN30: 0 | AO30: 0 | AP30: 0 | AQ30: 0 | AR30: 0 | AS30: 0 | AT30: 0 | AU30: 21 | AV30: 7 | AW30: 0 | AX30: 0 | AY30: 0 | AZ30: 0 | BA30: 0 | BB30: 0 | BC30: 0 | BD30: 0 | BE30: 7 | BF30: 12 | BG30: 0 | BH30: 0 | BI30: 0 | BJ30: 0 | BK30: 0 | BL30: 0
A31: 48063 | B31: ZUKO 8 S PIÑA COLADA EXH | C31: 12 | D31: 677 | E31: TRESMONTES LUCHETTI (NUTRESA) | F31: 690 | G31: TRESMONTES LUCCHETTI (ZUKO) | H31: 29.5707 | I31: 354.8484 | J31: =K31*I31 -> 0 | K31: =SUM(N31+R31+U31) -> 0 | L31: 2.12 | M31: 2.58 | N31: =MAX(0,(TRUNC((L31*0.8)-M31))) -> 0 | P31: 0.54 | Q31: 3.67 | R31: 0 | S31: 3.75 | T31: 5.17 | U31: =MAX(0,(TRUNC((S31*0.8)-T31))) -> 0 | V31: 0 | W31: 2276.94 | X31: 4051.19 | Y31: 10 | Z31: 7 | AA31: 12 | AB31: 0 | AC31: 31 | AD31: 0 | AE31: 0 | AF31: 0 | AG31: 0 | AH31: 0 | AI31: 0 | AJ31: 0 | AK31: 0 | AL31: 0 | AM31: 0 | AN31: 0 | AO31: 0 | AP31: 0 | AQ31: 0 | AR31: 0 | AS31: 4 | AT31: 5 | AU31: 0 | AV31: 0 | AW31: 44 | AX31: 0 | AY31: 0 | AZ31: 0 | BA31: 0 | BB31: 0 | BC31: 11 | BD31: 4 | BE31: 19 | BF31: 26 | BG31: 62 | BH31: 0 | BI31: 0 | BJ31: 0 | BK31: 0 | BL31: 0
A32: 47026 | B32: CHOC MUIBON ROLL C&C 315GR/ 15 NUTRESA | C32: 12 | D32: 677 | E32: TRESMONTES LUCHETTI (NUTRESA) | F32: 999 | G32: PRODUCTOS A ELIMINAR | H32: 48.56 | I32: 582.72 | J32: =K32*I32 -> 23891.52 | K32: =SUM(N32+R32+U32) -> 41 | L32: 0 | M32: 0 | N32: 11 | P32: 3.54 | Q32: 0.92 | R32: 20 | S32: 0 | T32: 0 | U32: 10 | V32: 0 | W32: 2063.8 | X32: 534.16 | Y32: 0 | Z32: 0 | AA32: 0 | AB32: 0 | AC32: 0 | AD32: 0 | AE32: 0 | AF32: 0 | AG32: 0 | AH32: 0 | AI32: 0 | AJ32: 0 | AK32: 0 | AL32: 0 | AM32: 0 | AN32: 0 | AO32: 0 | AP32: 0 | AQ32: 0 | AR32: 0 | AS32: 13 | AT32: 59 | AU32: 0 | AV32: 0 | AW32: 11 | AX32: 0 | AY32: 0 | AZ32: 0 | BA32: 0 | BB32: 0 | BC32: 0 | BD32: 0 | BE32: 0 | BF32: 0 | BG32: 0 | BH32: 0 | BI32: 0 | BJ32: 0 | BK32: 0 | BL32: 0
A33: 47027 | B33: CHOC CREMINO FRUTOS ROJOS 408GR/ 24 NUTRESA | C33: 16 | D33: 677 | E33: TRESMONTES LUCHETTI (NUTRESA) | F33: 999 | G33: PRODUCTOS A ELIMINAR | H33: 56.59 | I33: 905.44 | J33: =K33*I33 -> 36217.6 | K33: =SUM(N33+R33+U33) -> 40 | L33: 2.09 | M33: 0 | N33: 10 | P33: 0 | Q33: 0 | R33: 20 | S33: 0 | T33: 0 | U33: 10 | V33: 0 | W33: 1895.76 | X33: 0 | Y33: 16 | Z33: 35 | AA33: 0 | AB33: 0 | AC33: 0 | AD33: 0 | AE33: 0 | AF33: 0 | AG33: 0 | AH33: 0 | AI33: 0 | AJ33: 0 | AK33: 0 | AL33: 0 | AM33: 0 | AN33: 0 | AO33: 0 | AP33: 0 | AQ33: 0 | AR33: 0 | AS33: 0 | AT33: 0 | AU33: 0 | AV33: 0 | AW33: 0 | AX33: 0 | AY33: 0 | AZ33: 0 | BA33: 0 | BB33: 0 | BC33: 0 | BD33: 0 | BE33: 0 | BF33: 0 | BG33: 0 | BH33: 0 | BI33: 0 | BJ33: 0 | BK33: 0 | BL33: 0
A34: 48080 | B34: ZUKO 8 S DURAZNO EXH | C34: 12 | D34: 677 | E34: TRESMONTES LUCHETTI (NUTRESA) | F34: 690 | G34: TRESMONTES LUCCHETTI (ZUKO) | H34: 29.5707 | I34: 354.8484 | J34: =K34*I34 -> 0 | K34: =SUM(N34+R34+U34) -> 0 | L34: 0 | M34: 0 | N34: =MAX(0,(TRUNC((L34*0.8)-M34))) -> 0 | P34: 1.75 | Q34: 0 | R34: 0 | S34: 2.83 | T34: 1.58 | U34: =MAX(0,(TRUNC((S34*0.8)-T34))) -> 0 | V34: 0 | W34: 1626.39 | X34: 561.84 | Y34: 0 | Z34: 0 | AA34: 0 | AB34: 0 | AC34: 0 | AD34: 0 | AE34: 0 | AF34: 0 | AG34: 0 | AH34: 0 | AI34: 0 | AJ34: 0 | AK34: 0 | AL34: 0 | AM34: 0 | AN34: 0 | AO34: 0 | AP34: 0 | AQ34: 0 | AR34: 0 | AS34: 0 | AT34: 0 | AU34: 10 | AV34: 22 | AW34: 0 | AX34: 0 | AY34: 0 | AZ34: 0 | BA34: 0 | BB34: 0 | BC34: 14 | BD34: 6 | BE34: 4 | BF34: 26 | BG34: 19 | BH34: 0 | BI34: 0 | BJ34: 0 | BK34: 0 | BL34: 0
A35: 47019 | B35: BOLSA CHOCO MIX 815 GR / 69 NUTRESA | C35: 8 | D35: 677 | E35: TRESMONTES LUCHETTI (NUTRESA) | F35: 61 | G35: NUTRESA SA DE CV | H35: 152.41 | I35: 1219.28 | J35: =K35*I35 -> 0 | K35: =SUM(N35+R35+U35) -> 0 | L35: 0.38 | M35: 3.5 | N35: =MAX(0,(TRUNC((L35*0.8)-M35))) -> 0 | P35: 0.81 | Q35: 1.5 | R35: 0 | S35: 0 | T35: 0.75 | U35: =MAX(0,(TRUNC((S35*0.8)-T35))) -> 0 | V35: 0 | W35: 1447.9 | X35: 7010.86 | Y35: 1 | Z35: 0 | AA35: 1 | AB35: 2 | AC35: 28 | AD35: 0 | AE35: 0 | AF35: 0 | AG35: 0 | AH35: 0 | AI35: 0 | AJ35: 0 | AK35: 0 | AL35: 0 | AM35: 0 | AN35: 0 | AO35: 0 | AP35: 0 | AQ35: 0 | AR35: 0 | AS35: 0 | AT35: 1 | AU35: 2 | AV35: 8 | AW35: 12 | AX35: 0 | AY35: 0 | AZ35: 0 | BA35: 0 | BB35: 0 | BC35: 0 | BD35: 0 | BE35: 0 | BF35: 0 | BG35: 6 | BH35: 0 | BI35: 0 | BJ35: 0 | BK35: 0 | BL35: 0
